Workbook

Sheet BALANCE SHEET 
A4: Powered by Clearbit
A5: NVIDIA Corp (NMS: NVDA)
A6: Standardized Annual Balance Sheet | B6: 2015 | C6: 2016 | D6: 2017 | E6: 2018 | F6: 2019 | G6: 2020 | H6: 2021 | I6: 2022 | J6: 2023 | K6: 2024
A7: Report Date | B7: 01/25/2015 | C7: 01/31/2016 | D7: 01/29/2017 | E7: 01/28/2018 | F7: 01/27/2019 | G7: 01/26/2020 | H7: 01/31/2021 | I7: 01/30/2022 | J7: 01/29/2023 | K7: 01/28/2024
A8: Currency | B8: USD | C8: USD | D8: USD | E8: USD | F8: USD | G8: USD | H8: USD | I8: USD | J8: USD | K8: USD
A9: Consolidated | B9: Yes | C9: Yes | D9: Yes | E9: Yes | F9: Yes | G9: Yes | H9: Yes | I9: Yes | J9: Yes | K9: Yes
A10: Scale | B10: Thousands | C10: Thousands | D10: Thousands | E10: Thousands | F10: Thousands | G10: Thousands | H10: Thousands | I10: Thousands | J10: Thousands | K10: Thousands
A11: Cash & Equivalents | B11: 496654 | C11: 596000 | D11: 1766000 | E11: 4002000 | F11: 782000 | G11: 10896000 | H11: 847000 | I11: 1990000 | J11: 3389000 | K11: 7280000
A12: Short Term Investments | B12: 4126685 | C12: 4441000 | D12: 5032000 | E12: 3106000 | F12: 6640000 | G12: 1000 | H12: 10714000 | I12: 19218000 | J12: 9907000 | K12: 18704000
A13: Cash & Equivs & ST Investments | B13: 4623339 | C13: 5037000 | D13: 6798000 | E13: 7108000 | F13: 7422000 | G13: 10897000 | H13: 11561000 | I13: 21208000 | J13: 13296000 | K13: 25984000
A14: Receivables (ST) | B14: 473637 | C14: 505000 | D14: 826000 | E14: 1265000 | F14: 1424000 | G14: 1657000 | H14: 2429000 | I14: 4650000 | J14: 3827000 | K14: 9999000
A15: Inventories | B15: 482893 | C15: 418000 | D15: 794000 | E15: 796000 | F15: 1575000 | G15: 979000 | H15: 1826000 | I15: 2605000 | J15: 5159000 | K15: 5282000
A16: Other Current Assets | B16: 70174 | C16: 93000 | D16: 118000 | E16: 86000 | F16: 136000 | G16: 157000 | H16: 239000 | I16: 366000 | J16: 791000 | K16: 3080000
A17: Total Current Assets | B17: 5713297 | C17: 6053000 | D17: 8536000 | E17: 9255000 | F17: 10557000 | G17: 13690000 | H17: 16055000 | I17: 28829000 | J17: 23073000 | K17: 44345000
A18: Gross Property Plant & Equip | B18: 1179257 | C18: 1100000 | D18: 1191000 | E18: 1737000 | F18: 2171000 | G18: 2685000 | H18: 3557000 | I18: 4681000 | J18: 6501000 | K18: 7423000
A19: Accumulated Depreciation | B19: 621975 | C19: 634000 | D19: 670000 | E19: 740000 | F19: 767000 | G19: 1011000 | H19: 1408000 | I19: 1903000 | J19: 2694000 | K19: 3509000
A20: Net Property Plant & Equip | B20: 557282 | C20: 466000 | D20: 521000 | E20: 997000 | F20: 1404000 | G20: 1674000 | H20: 2149000 | I20: 2778000 | J20: 3807000 | K20: 3914000
A21: Intangible Assets | B21: 839893 | C21: 784000 | D21: 722000 | E21: 670000 | F21: 663000 | G21: 667000 | H21: 6930000 | I21: 6688000 | J21: 6048000 | K21: 5542000
A22: Other Assets | B22: 90896 | C22: 67000 | D22: 62000 | E22: 319000 | F22: 668000 | G22: 736000 | H22: 2851000 | I22: 2248000 | J22: 1183000 | K22: 5846000
... A40: Total Liabilities & Equity | B40: 7201368 | C40: 7370000 | D40: 9841000 | E40: 11241000 | F40: 13292000 | G40: 17315000 | H40: 28791000 | I40: 44187000 | J40: 41182000 | K40: 65728000
A44: =

Sheet Percentage Balance sheet
A1: Standardized Annual Balance Sheet | B1: 2015 | C1: 2016 | D1: 2017 | E1: 2018 | F1: 2019 | G1: 2020 | H1: 2021 | I1: 2022 | J1: 2023 | K1: 2024
A2: Report Date | B2: 01/25/2015 | C2: 01/31/2016 | D2: 01/29/2017 | E2: 01/28/2018 | F2: 01/27/2019 | G2: 01/26/2020 | H2: 01/31/2021 | I2: 01/30/2022 | J2: 01/29/2023 | K2: 01/28/2024
A3: Currency | B3: USD | C3: USD | D3: USD | E3: USD | F3: USD | G3: USD | H3: USD | I3: USD | J3: USD | K3: USD
A4: Consolidated | B4: Yes | C4: Yes | D4: Yes | E4: Yes | F4: Yes | G4: Yes | H4: Yes | I4: Yes | J4: Yes | K4: Yes
A5: Scale | B5: Thousands | C5: Thousands | D5: Thousands | E5: Thousands | F5: Thousands | G5: Thousands | H5: Thousands | I5: Thousands | J5: Thousands | K5: Thousands
A6: Cash & Equivalents | B6: ='BALANCE SHEET '!B11/'BALANCE SHEET '!$B$23 -> 0.068966619 | C6: ='BALANCE SHEET '!C11/'BALANCE SHEET '!$C$23 -> 0.080868385 | D6: ='BALANCE SHEET '!D11/'BALANCE SHEET '!$D$23 -> 0.17945331 | E6: ='BALANCE SHEET '!E11/'BALANCE SHEET '!$E$23 -> 0.35601815 | F6: ='BALANCE SHEET '!F11/'BALANCE SHEET '!$F$23 -> 0.05883238 | G6: ='BALANCE SHEET '!G11/'BALANCE SHEET '!$G$23 -> 0.62928097 | H6: ='BALANCE SHEET '!H11/'BALANCE SHEET '!$H$23 -> 0.029418916 | I6: ='BALANCE SHEET '!I11/'BALANCE SHEET '!$I$23 -> 0.04503587 | J6: ='BALANCE SHEET '!J11/'BALANCE SHEET '!$J$23 -> 0.082293235 | K6: ='BALANCE SHEET '!K11/'BALANCE SHEET '!$K$23 -> 0.11075949
A7: Short Term Investments | B7: ='BALANCE SHEET '!B12/'BALANCE SHEET '!$B$23 -> 0.57304182 | C7: ='BALANCE SHEET '!C12/'BALANCE SHEET '!$C$23 -> 0.60257802 | D7: ='BALANCE SHEET '!D12/'BALANCE SHEET '!$D$23 -> 0.51133015 | E7: ='BALANCE SHEET '!E12/'BALANCE SHEET '!$E$23 -> 0.27630994 | F7: ='BALANCE SHEET '!F12/'BALANCE SHEET '!$F$23 -> 0.4995486 | G7: ='BALANCE SHEET '!G12/'BALANCE SHEET '!$G$23 -> 5.7753393e-05 | H7: ='BALANCE SHEET '!H12/'BALANCE SHEET '!$H$23 -> 0.37213018 | I7: ='BALANCE SHEET '!I12/'BALANCE SHEET '!$I$23 -> 0.4349243 | J7: ='BALANCE SHEET '!J12/'BALANCE SHEET '!$J$23 -> 0.24056627 | K7: ='BALANCE SHEET '!K12/'BALANCE SHEET '!$K$23 -> 0.2845667
A8: Cash & Equivs & ST Investments | B8: ='BALANCE SHEET '!B13/'BALANCE SHEET '!$B$23 -> 0.64200844 | C8: ='BALANCE SHEET '!C13/'BALANCE SHEET '!$C$23 -> 0.6834464 | D8: ='BALANCE SHEET '!D13/'BALANCE SHEET '!$D$23 -> 0.69078346 | E8: ='BALANCE SHEET '!E13/'BALANCE SHEET '!$E$23 -> 0.63232808 | F8: ='BALANCE SHEET '!F13/'BALANCE SHEET '!$F$23 -> 0.55838098 | G8: ='BALANCE SHEET '!G13/'BALANCE SHEET '!$G$23 -> 0.62933872 | H8: ='BALANCE SHEET '!H13/'BALANCE SHEET '!$H$23 -> 0.4015491 | I8: ='BALANCE SHEET '!I13/'BALANCE SHEET '!$I$23 -> 0.47996017 | J8: ='BALANCE SHEET '!J13/'BALANCE SHEET '!$J$23 -> 0.3228595 | K8: ='BALANCE SHEET '!K13/'BALANCE SHEET '!$K$23 -> 0.39532619
A9: Receivables (ST) | B9: ='BALANCE SHEET '!B14/'BALANCE SHEET '!$B$23 -> 0.06577042 | C9: ='BALANCE SHEET '!C14/'BALANCE SHEET '!$C$23 -> 0.068521031 | D9: ='BALANCE SHEET '!D14/'BALANCE SHEET '!$D$23 -> 0.083934559 | E9: ='BALANCE SHEET '!E14/'BALANCE SHEET '!$E$23 -> 0.11253447 | F9: ='BALANCE SHEET '!F14/'BALANCE SHEET '!$F$23 -> 0.10713211 | G9: ='BALANCE SHEET '!G14/'BALANCE SHEET '!$G$23 -> 0.095697372 | H9: ='BALANCE SHEET '!H14/'BALANCE SHEET '!$H$23 -> 0.084366642 | I9: ='BALANCE SHEET '!I14/'BALANCE SHEET '!$I$23 -> 0.10523457 | J9: ='BALANCE SHEET '!J14/'BALANCE SHEET '!$J$23 -> 0.09292895 | K9: ='BALANCE SHEET '!K14/'BALANCE SHEET '!$K$23 -> 0.15212695
A10: Inventories | B10: ='BALANCE SHEET '!B15/'BALANCE SHEET '!$B$23 -> 0.067055732 | C10: ='BALANCE SHEET '!C15/'BALANCE SHEET '!$C$23 -> 0.056716418 | D10: ='BALANCE SHEET '!D15/'BALANCE SHEET '!$D$23 -> 0.080682857 | E10: ='BALANCE SHEET '!E15/'BALANCE SHEET '!$E$23 -> 0.070812205 | F10: ='BALANCE SHEET '!F15/'BALANCE SHEET '!$F$23 -> 0.11849233 | G10: ='BALANCE SHEET '!G15/'BALANCE SHEET '!$G$23 -> 0.056540572 | H10: ='BALANCE SHEET '!H15/'BALANCE SHEET '!$H$23 -> 0.063422597 | I10: ='BALANCE SHEET '!I15/'BALANCE SHEET '!$I$23 -> 0.058953991 | J10: ='BALANCE SHEET '!J15/'BALANCE SHEET '!$J$23 -> 0.12527318 | K10: ='BALANCE SHEET '!K15/'BALANCE SHEET '!$K$23 -> 0.08036149
A11: Other Current Assets | B11: ='BALANCE SHEET '!B16/'BALANCE SHEET '!$B$23 -> 0.0097445374 | C11: ='BALANCE SHEET '!C16/'BALANCE SHEET '!$C$23 -> 0.012618725 | D11: ='BALANCE SHEET '!D16/'BALANCE SHEET '!$D$23 -> 0.011990651 | E11: ='BALANCE SHEET '!E16/'BALANCE SHEET '!$E$23 -> 0.0076505649 | F11: ='BALANCE SHEET '!F16/'BALANCE SHEET '!$F$23 -> 0.010231718 | G11: ='BALANCE SHEET '!G16/'BALANCE SHEET '!$G$23 -> 0.0090672827 | H11: ='BALANCE SHEET '!H16/'BALANCE SHEET '!$H$23 -> 0.0083012052 | I11: ='BALANCE SHEET '!I16/'BALANCE SHEET '!$I$23 -> 0.0082829792 | J11: ='BALANCE SHEET '!J16/'BALANCE SHEET '!$J$23 -> 0.019207421 | K11: ='BALANCE SHEET '!K16/'BALANCE SHEET '!$K$23 -> 0.046859786
A12: Total Current Assets | B12: ='BALANCE SHEET '!B17/'BALANCE SHEET '!$B$23 -> 0.79336273 | C12: ='BALANCE SHEET '!C17/'BALANCE SHEET '!$C$23 -> 0.82130258 | D12: ='BALANCE SHEET '!D17/'BALANCE SHEET '!$D$23 -> 0.86739153 | E12: ='BALANCE SHEET '!E17/'BALANCE SHEET '!$E$23 -> 0.82332533 | F12: ='BALANCE SHEET '!F17/'BALANCE SHEET '!$F$23 -> 0.79423714 | G12: ='BALANCE SHEET '!G17/'BALANCE SHEET '!$G$23 -> 0.79064395 | H12: ='BALANCE SHEET '!H17/'BALANCE SHEET '!$H$23 -> 0.55763954 | I12: ='BALANCE SHEET '!I17/'BALANCE SHEET '!$I$23 -> 0.65243171 | J12: ='BALANCE SHEET '!J17/'BALANCE SHEET '!$J$23 -> 0.56026905 | K12: ='BALANCE SHEET '!K17/'BALANCE SHEET '!$K$23 -> 0.67467442
A13: Gross Property Plant & Equip | B13: ='BALANCE SHEET '!B18/'BALANCE SHEET '!$B$23 -> 0.16375458 | C13: ='BALANCE SHEET '!C18/'BALANCE SHEET '!$C$23 -> 0.14925373 | D13: ='BALANCE SHEET '!D18/'BALANCE SHEET '!$D$23 -> 0.12102429 | E13: ='BALANCE SHEET '!E18/'BALANCE SHEET '!$E$23 -> 0.15452362 | F13: ='BALANCE SHEET '!F18/'BALANCE SHEET '!$F$23 -> 0.16333133 | G13: ='BALANCE SHEET '!G18/'BALANCE SHEET '!$G$23 -> 0.15506786 | H13: ='BALANCE SHEET '!H18/'BALANCE SHEET '!$H$23 -> 0.12354555 | I13: ='BALANCE SHEET '!I18/'BALANCE SHEET '!$I$23 -> 0.10593614 | J13: ='BALANCE SHEET '!J18/'BALANCE SHEET '!$J$23 -> 0.15786023 | K13: ='BALANCE SHEET '!K18/'BALANCE SHEET '!$K$23 -> 0.11293513
A14: Accumulated Depreciation | B14: ='BALANCE SHEET '!B19/'BALANCE SHEET '!$B$23 -> 0.086369007 | C14: ='BALANCE SHEET '!C19/'BALANCE SHEET '!$C$23 -> 0.086024423 | D14: ='BALANCE SHEET '!D19/'BALANCE SHEET '!$D$23 -> 0.068082512 | E14: ='BALANCE SHEET '!E19/'BALANCE SHEET '!$E$23 -> 0.065830442 | F14: ='BALANCE SHEET '!F19/'BALANCE SHEET '!$F$23 -> 0.057703882 | G14: ='BALANCE SHEET '!G19/'BALANCE SHEET '!$G$23 -> 0.05838868 | H14: ='BALANCE SHEET '!H19/'BALANCE SHEET '!$H$23 -> 0.048904171 | I14: ='BALANCE SHEET '!I19/'BALANCE SHEET '!$I$23 -> 0.043066965 | J14: ='BALANCE SHEET '!J19/'BALANCE SHEET '!$J$23 -> 0.06541693 | K14: ='BALANCE SHEET '!K19/'BALANCE SHEET '!$K$23 -> 0.053386685
A15: Net Property Plant & Equip | B15: ='BALANCE SHEET '!B20/'BALANCE SHEET '!$B$23 -> 0.077385575 | C15: ='BALANCE SHEET '!C20/'BALANCE SHEET '!$C$23 -> 0.063229308 | D15: ='BALANCE SHEET '!D20/'BALANCE SHEET '!$D$23 -> 0.052941774 | E15: ='BALANCE SHEET '!E20/'BALANCE SHEET '!$E$23 -> 0.088693177 | F15: ='BALANCE SHEET '!F20/'BALANCE SHEET '!$F$23 -> 0.10562745 | G15: ='BALANCE SHEET '!G20/'BALANCE SHEET '!$G$23 -> 0.09667918 | H15: ='BALANCE SHEET '!H20/'BALANCE SHEET '!$H$23 -> 0.074641381 | I15: ='BALANCE SHEET '!I20/'BALANCE SHEET '!$I$23 -> 0.06286917 | J15: ='BALANCE SHEET '!J20/'BALANCE SHEET '!$J$23 -> 0.0924433 | K15: ='BALANCE SHEET '!K20/'BALANCE SHEET '!$K$23 -> 0.059548442
A16: Intangible Assets | B16: ='BALANCE SHEET '!B21/'BALANCE SHEET '!$B$23 -> 0.11662965 | C16: ='BALANCE SHEET '!C21/'BALANCE SHEET '!$C$23 -> 0.1063772 | D16: ='BALANCE SHEET '!D21/'BALANCE SHEET '!$D$23 -> 0.073366528 | E16: ='BALANCE SHEET '!E21/'BALANCE SHEET '!$E$23 -> 0.059603238 | F16: ='BALANCE SHEET '!F21/'BALANCE SHEET '!$F$23 -> 0.049879627 | G16: ='BALANCE SHEET '!G21/'BALANCE SHEET '!$G$23 -> 0.038521513 | H16: ='BALANCE SHEET '!H21/'BALANCE SHEET '!$H$23 -> 0.24070022 | I16: ='BALANCE SHEET '!I21/'BALANCE SHEET '!$I$23 -> 0.15135673 | J16: ='BALANCE SHEET '!J21/'BALANCE SHEET '!$J$23 -> 0.14686028 | K16: ='BALANCE SHEET '!K21/'BALANCE SHEET '!$K$23 -> 0.084317186
A17: Other Assets | B17: ='BALANCE SHEET '!B22/'BALANCE SHEET '!$B$23 -> 0.012622046 | C17: ='BALANCE SHEET '!C22/'BALANCE SHEET '!$C$23 -> 0.0090909091 | D17: ='BALANCE SHEET '!D22/'BALANCE SHEET '!$D$23 -> 0.0063001727 | E17: ='BALANCE SHEET '!E22/'BALANCE SHEET '!$E$23 -> 0.028378258 | F17: ='BALANCE SHEET '!F22/'BALANCE SHEET '!$F$23 -> 0.050255793 | G17: ='BALANCE SHEET '!G22/'BALANCE SHEET '!$G$23 -> 0.042506497 | H17: ='BALANCE SHEET '!H22/'BALANCE SHEET '!$H$23 -> 0.099024001 | I17: ='BALANCE SHEET '!I22/'BALANCE SHEET '!$I$23 -> 0.050874692 | J17: ='BALANCE SHEET '!J22/'BALANCE SHEET '!$J$23 -> 0.028726142 | K17: ='BALANCE SHEET '!K22/'BALANCE SHEET '!$K$23 -> 0.088942308
... A35: Total Liabilities & Equity | B35: ='BALANCE SHEET '!B40/'BALANCE SHEET '!$B$23 -> 1 | C35: ='BALANCE SHEET '!C40/'BALANCE SHEET '!$C$23 -> 1 | D35: ='BALANCE SHEET '!D40/'BALANCE SHEET '!$D$23 -> 1 | E35: ='BALANCE SHEET '!E40/'BALANCE SHEET '!$E$23 -> 1 | F35: ='BALANCE SHEET '!F40/'BALANCE SHEET '!$F$23 -> 1 | G35: ='BALANCE SHEET '!G40/'BALANCE SHEET '!$G$23 -> 1 | H35: ='BALANCE SHEET '!H40/'BALANCE SHEET '!$H$23 -> 1 | I35: ='BALANCE SHEET '!I40/'BALANCE SHEET '!$I$23 -> 1 | J35: ='BALANCE SHEET '!J40/'BALANCE SHEET '!$J$23 -> 1 | K35: ='BALANCE SHEET '!K40/'BALANCE SHEET '!$K$23 -> 1

Sheet INCOME STATEMENT
A4: Powered by Clearbit
A5: NVIDIA Corp (NMS: NVDA)
A6: year | B6: 2015 | C6: 2016 | D6: 2017 | E6: 2018 | F6: 2019 | G6: 2020 | H6: 2021 | I6: 2022 | J6: 2023 | K6: 2024
A7: Report Date | B7: 01/25/2015 | C7: 01/31/2016 | D7: 01/29/2017 | E7: 01/28/2018 | F7: 01/27/2019 | G7: 01/26/2020 | H7: 01/31/2021 | I7: 01/30/2022 | J7: 01/29/2023 | K7: 01/28/2024
A8: Currency | B8: USD | C8: USD | D8: USD | E8: USD | F8: USD | G8: USD | H8: USD | I8: USD | J8: USD | K8: USD
A11: Audit Status | B11: Not Qualified | C11: Not Qualified | D11: Not Qualified | E11: Not Qualified | F11: Not Qualified | G11: Not Qualified | H11: Not Qualified | I11: Not Qualified | J11: Not Qualified | K11: Not Qualified | L11: average growth | M11: ST.d
A12: Standardized Annual Income Statement | C12: =(C17-B17)/B17 -> 0.070168217 | D12: =(D17-C17)/C17 -> 0.37924152 | E12: =(E17-D17)/D17 -> 0.40578871 | F12: =(F17-E17)/E17 -> 0.2060943 | G12: =(G17-F17)/F17 -> -0.068111984 | H12: =(H17-G17)/G17 -> 0.52729438 | I12: =(I17-H17)/H17 -> 0.61403298 | J12: =(J17-I17)/I17 -> 0.002229323 | K12: =(K17-J17)/J17 -> 1.2585453 | L12: =AVERAGE(C12:K12) -> 0.37725363 | M12: =_xlfn.STDEV.S(C12:K12) -> 0.40599578
A14: Consolidated | B14: Yes | C14: Yes | D14: Yes | E14: Yes | F14: Yes | G14: Yes | H14: Yes | I14: Yes | J14: Yes | K14: Yes
A15: Scale | B15: Thousands | C15: Thousands | D15: Thousands | E15: Thousands | F15: Thousands | G15: Thousands | H15: Thousands | I15: Thousands | J15: Thousands | K15: Thousands
A16: Sales Revenue | B16: - | C16: - | D16: - | E16: - | F16: - | G16: - | H16: - | I16: - | J16: - | K16: 60922000
A17: Total Revenue | B17: 4681507 | C17: 5010000 | D17: 6910000 | E17: 9714000 | F17: 11716000 | G17: 10918000 | H17: 16675000 | I17: 26914000 | J17: 26974000 | K17: 60922000
A18: Direct Costs | B18: 2082030 | C18: 2199000 | D18: 2847000 | E18: 3892000 | F18: 4545000 | G18: 4150000 | H18: 6279000 | I18: 9439000 | J18: 11618000 | K18: 16621000
A19: Gross Profit | B19: 2599477 | C19: 2811000 | D19: 4063000 | E19: 5822000 | F19: 7171000 | G19: 6768000 | H19: 10396000 | I19: 17475000 | J19: 15356000 | K19: 44301000
A20: Selling General & Admin | B20: 480763 | C20: 602000 | D20: 663000 | E20: 815000 | F20: 991000 | G20: 1093000 | H20: 1940000 | I20: 2166000 | J20: 2440000 | K20: 2654000
A21: Research & Development | B21: 1359725 | C21: 1331000 | D21: 1463000 | E21: 1797000 | F21: 2376000 | G21: 2829000 | H21: 3924000 | I21: 5268000 | J21: 7339000 | K21: 8675000
A22: Total Indirect Operating Costs | B22: 1840488 | C22: 2064000 | D22: 2129000 | E22: 2612000 | F22: 3367000 | G22: 3922000 | H22: 5864000 | I22: 7434000 | J22: 11132000 | K22: 11329000
A23: Operating Income(EBIT) | B23: 758989 | C23: 747000 | D23: 1934000 | E23: 3210000 | F23: 3804000 | G23: 2846000 | H23: 4532000 | I23: 10041000 | J23: 4224000 | K23: 32972000
A24: Interest Income | B24: -18043 | C24: -8000 | D24: -4000 | E24: 8000 | F24: 78000 | G24: 126000 | H24: -127000 | I24: -207000 | J24: 5000 | K24: 609000
A25: Other Non-Operating Income | B25: 13890 | C25: 4000 | D25: -25000 | E25: -22000 | F25: 14000 | G25: -2000 | H25: 4000 | I25: 107000 | J25: -48000 | K25: 237000
A26: Total Non-Operating Income | B26: -4153 | C26: -4000 | D26: -29000 | E26: -14000 | F26: 92000 | G26: 124000 | H26: -123000 | I26: -100000 | J26: -43000 | K26: 846000
A27: Earnings Before Tax(EBT) | B27: 754836 | C27: 743000 | D27: 1905000 | E27: 3196000 | F27: 3896000 | G27: 2970000 | H27: 4409000 | I27: 9941000 | J27: 4181000 | K27: 33818000
A28: Taxation | B28: 124249 | C28: 129000 | D28: 239000 | E28: 149000 | F28: -245000 | G28: 174000 | H28: 77000 | I28: 189000 | J28: -187000 | K28: 4058000
... A39: avg stock price | B39: 0.575 | C39: 1.3218 | D39: 3.7025 | E39: 5.7588 | F39: 4.3386 | G39: 9.8599 | H39: 19.4838 | I39: 18.5445 | J39: 36.5525 | K39: 107.8096
A40: Market capitilization | B40: =B39*B37 -> 12532999 | C40: =C39*C37 -> 28498008 | D40: =D39*D37 -> 86638500 | E40: =E39*E37 -> 139593312 | F40: =F39*F37 -> 1.0516766e+08 | G40: =G39*G37 -> 241370352 | H40: =H39*H37 -> 4.8319824e+08 | I40: =I39*I37 -> 464725170 | ... K40: =K39*K37 -> 2656428544
A41: Cash Flow
A43: operating cash flow | B43: =B23+('BALANCE SHEET '!B19-'BALANCE SHEET '!A19)-'INCOME STATEMENT'!B28 -> #VALUE! | C43: =C23+('BALANCE SHEET '!C19-'BALANCE SHEET '!B19)-'INCOME STATEMENT'!C28 -> 630025 | D43: =D23+('BALANCE SHEET '!D19-'BALANCE SHEET '!C19)-'INCOME STATEMENT'!D28 -> 1731000 | E43: =E23+('BALANCE SHEET '!E19-'BALANCE SHEET '!D19)-'INCOME STATEMENT'!E28 -> 3131000 | F43: =F23+('BALANCE SHEET '!F19-'BALANCE SHEET '!E19)-'INCOME STATEMENT'!F28 -> 4076000 | G43: =G23+('BALANCE SHEET '!G19-'BALANCE SHEET '!F19)-'INCOME STATEMENT'!G28 -> 2916000 | H43: =H23+('BALANCE SHEET '!H19-'BALANCE SHEET '!G19)-'INCOME STATEMENT'!H28 -> 4852000 | I43: =I23+('BALANCE SHEET '!I19-'BALANCE SHEET '!H19)-'INCOME STATEMENT'!I28 -> 10347000 | ... K43: =K23+('BALANCE SHEET '!K19-'BALANCE SHEET '!J19)-'INCOME STATEMENT'!K28 -> 29729000
A44: change CAPEX | B44: ='BALANCE SHEET '!B18-'BALANCE SHEET '!A18 -> #VALUE! | C44: ='BALANCE SHEET '!C18-'BALANCE SHEET '!B18 -> -79257 | D44: ='BALANCE SHEET '!D18-'BALANCE SHEET '!C18 -> 91000 | E44: ='BALANCE SHEET '!E18-'BALANCE SHEET '!D18 -> 546000 | F44: ='BALANCE SHEET '!F18-'BALANCE SHEET '!E18 -> 434000 | G44: ='BALANCE SHEET '!G18-'BALANCE SHEET '!F18 -> 514000 | H44: ='BALANCE SHEET '!H18-'BALANCE SHEET '!G18 -> 872000 | I44: ='BALANCE SHEET '!I18-'BALANCE SHEET '!H18 -> 1124000 | ... K44: ='BALANCE SHEET '!K18-'BALANCE SHEET '!J18 -> 922000
A45: change NWC | B45: =('BALANCE SHEET '!B17-'BALANCE SHEET '!B29)-('BALANCE SHEET '!A17-'BALANCE SHEET '!A29) -> #VALUE! | C45: =('BALANCE SHEET '!C17-'BALANCE SHEET '!C29)-('BALANCE SHEET '!B17-'BALANCE SHEET '!B29) -> -1115267 | D45: =('BALANCE SHEET '!D17-'BALANCE SHEET '!D29)-('BALANCE SHEET '!C17-'BALANCE SHEET '!C29) -> 3046000 | E45: =('BALANCE SHEET '!E17-'BALANCE SHEET '!E29)-('BALANCE SHEET '!D17-'BALANCE SHEET '!D29) -> 1354000 | F45: =('BALANCE SHEET '!F17-'BALANCE SHEET '!F29)-('BALANCE SHEET '!E17-'BALANCE SHEET '!E29) -> 1126000 | G45: =('BALANCE SHEET '!G17-'BALANCE SHEET '!G29)-('BALANCE SHEET '!F17-'BALANCE SHEET '!F29) -> 2678000 | H45: =('BALANCE SHEET '!H17-'BALANCE SHEET '!H29)-('BALANCE SHEET '!G17-'BALANCE SHEET '!G29) -> 224000 | I45: =('BALANCE SHEET '!I17-'BALANCE SHEET '!I29)-('BALANCE SHEET '!H17-'BALANCE SHEET '!H29) -> 12364000 | ... K45: =('BALANCE SHEET '!K17-'BALANCE SHEET '!K29)-('BALANCE SHEET '!J17-'BALANCE SHEET '!J29) -> 17204000
A47: CFFA | B47: =B43-B44-B45 -> #VALUE! | C47: =C43-C44-C45 -> 1824549 | D47: =D43-D44-D45 -> -1406000 | E47: =E43-E44-E45 -> 1231000 | F47: =F43-F44-F45 -> 2516000 | G47: =G43-G44-G45 -> -276000 | H47: =H43-H44-H45 -> 3756000 | I47: =I43-I44-I45 -> -3141000 | ... K47: =K43-K44-K45 -> 11603000
A49: Growth | B49: 2015 | C49: 2016 | D49: 2017 | E49: 2018 | F49: 2019 | G49: 2020 | H49: 2021 | I49: 2022 | J49: 2023 | K49: 2024
A51: sales | M51: AVERAGE
A52: ULTI | C52: =(C17-B17)/B17 -> 0.070168217 | D52: =(D17-C17)/C17 -> 0.37924152 | E52: =(E17-D17)/D17 -> 0.40578871 | F52: =(F17-E17)/E17 -> 0.2060943 | G52: =(G17-F17)/F17 -> -0.068111984 | H52: =(H17-G17)/G17 -> 0.52729438 | I52: =(I17-H17)/H17 -> 0.61403298 | J52: =(J17-I17)/I17 -> 0.002229323 | K52: =(K17-J17)/J17 -> 1.2585453 | M52: =AVERAGE(C52:K52) -> 0.37725363
A53: Industry | C53: =(AMD!C100+INTEL!C101+QUALCOMM!C104)/3 -> -0.0062701687 | D53: =(AMD!D100+INTEL!D101+QUALCOMM!D104)/3 -> 0.031010396 | E53: =(AMD!E100+INTEL!E101+QUALCOMM!E104)/3 -> -0.13108 | F53: =(AMD!F100+INTEL!F101+QUALCOMM!F104)/3 -> -0.20805488 | G53: =(AMD!G100+INTEL!G101+QUALCOMM!G104)/3 -> -0.027432006 | H53: =(AMD!H100+INTEL!H101+QUALCOMM!H104)/3 -> -0.08533201 | I53: =(AMD!I100+INTEL!I101+QUALCOMM!I104)/3 -> -0.11063147 | J53: =(AMD!J100+INTEL!J101+QUALCOMM!J104)/3 -> -0.020959005 | K53: =(AMD!K100+INTEL!K101+QUALCOMM!K104)/3 -> 0.12834378 | M53: =AVERAGE(C53:K53) -> -0.047822818
B55: 0.575
A56: 2016 | B56: 1.3218
A57: 2017 | B57: 3.7025
A58: 2018 | B58: 5.7588
A59: 2019 | B59: 4.3386
A60: 2020 | B60: 9.8599
A61: 2021 | B61: 19.4838
...

Sheet Income statement c
B2: 2015 | C2: 2016 | D2: 2017 | E2: 2018 | F2: 2019 | G2: 2020 | H2: 2021 | I2: 2022 | J2: 2023 | K2: 2024
A3: Report Date | B3: 01/25/2015 | C3: 01/31/2016 | D3: 01/29/2017 | E3: 01/28/2018 | F3: 01/27/2019 | G3: 01/26/2020 | H3: 01/31/2021 | I3: 01/30/2022 | J3: 01/29/2023 | K3: 01/28/2024
A4: Total Revenue | B4: ='INCOME STATEMENT'!B17/'INCOME STATEMENT'!B$17 -> 1 | C4: ='INCOME STATEMENT'!C17/'INCOME STATEMENT'!C$17 -> 1 | D4: ='INCOME STATEMENT'!D17/'INCOME STATEMENT'!D$17 -> 1 | E4: ='INCOME STATEMENT'!E17/'INCOME STATEMENT'!E$17 -> 1 | F4: ='INCOME STATEMENT'!F17/'INCOME STATEMENT'!F$17 -> 1 | G4: ='INCOME STATEMENT'!G17/'INCOME STATEMENT'!G$17 -> 1 | H4: ='INCOME STATEMENT'!H17/'INCOME STATEMENT'!H$17 -> 1 | I4: ='INCOME STATEMENT'!I17/'INCOME STATEMENT'!I$17 -> 1 | ... K4: ='INCOME STATEMENT'!K17/'INCOME STATEMENT'!K$17 -> 1
A5: Direct Costs | B5: ='INCOME STATEMENT'!B18/'INCOME STATEMENT'!B$17 -> 0.444735 | C5: ='INCOME STATEMENT'!C18/'INCOME STATEMENT'!C$17 -> 0.43892216 | D5: ='INCOME STATEMENT'!D18/'INCOME STATEMENT'!D$17 -> 0.41201158 | E5: ='INCOME STATEMENT'!E18/'INCOME STATEMENT'!E$17 -> 0.40065884 | F5: ='INCOME STATEMENT'!F18/'INCOME STATEMENT'!F$17 -> 0.38793103 | G5: ='INCOME STATEMENT'!G18/'INCOME STATEMENT'!G$17 -> 0.38010625 | H5: ='INCOME STATEMENT'!H18/'INCOME STATEMENT'!H$17 -> 0.37655172 | I5: ='INCOME STATEMENT'!I18/'INCOME STATEMENT'!I$17 -> 0.35070967 | ... K5: ='INCOME STATEMENT'!K18/'INCOME STATEMENT'!K$17 -> 0.27282427
A6: Gross Profit | B6: ='INCOME STATEMENT'!B19/'INCOME STATEMENT'!B$17 -> 0.555265 | C6: ='INCOME STATEMENT'!C19/'INCOME STATEMENT'!C$17 -> 0.56107784 | D6: ='INCOME STATEMENT'!D19/'INCOME STATEMENT'!D$17 -> 0.58798842 | E6: ='INCOME STATEMENT'!E19/'INCOME STATEMENT'!E$17 -> 0.59934116 | F6: ='INCOME STATEMENT'!F19/'INCOME STATEMENT'!F$17 -> 0.61206897 | G6: ='INCOME STATEMENT'!G19/'INCOME STATEMENT'!G$17 -> 0.61989375 | H6: ='INCOME STATEMENT'!H19/'INCOME STATEMENT'!H$17 -> 0.62344828 | I6: ='INCOME STATEMENT'!I19/'INCOME STATEMENT'!I$17 -> 0.64929033 | ... K6: ='INCOME STATEMENT'!K19/'INCOME STATEMENT'!K$17 -> 0.72717573
A7: Selling General & Admin | B7: ='INCOME STATEMENT'!B20/'INCOME STATEMENT'!B$17 -> 0.10269407 | C7: ='INCOME STATEMENT'!C20/'INCOME STATEMENT'!C$17 -> 0.12015968 | D7: ='INCOME STATEMENT'!D20/'INCOME STATEMENT'!D$17 -> 0.095947902 | E7: ='INCOME STATEMENT'!E20/'INCOME STATEMENT'!E$17 -> 0.083899526 | F7: ='INCOME STATEMENT'!F20/'INCOME STATEMENT'!F$17 -> 0.084585183 | G7: ='INCOME STATEMENT'!G20/'INCOME STATEMENT'!G$17 -> 0.10010991 | H7: ='INCOME STATEMENT'!H20/'INCOME STATEMENT'!H$17 -> 0.11634183 | I7: ='INCOME STATEMENT'!I20/'INCOME STATEMENT'!I$17 -> 0.080478561 | ... K7: ='INCOME STATEMENT'!K20/'INCOME STATEMENT'!K$17 -> 0.043563901
A8: Research & Development | B8: ='INCOME STATEMENT'!B21/'INCOME STATEMENT'!B$17 -> 0.290446 | C8: ='INCOME STATEMENT'!C21/'INCOME STATEMENT'!C$17 -> 0.26566866 | D8: ='INCOME STATEMENT'!D21/'INCOME STATEMENT'!D$17 -> 0.21172214 | E8: ='INCOME STATEMENT'!E21/'INCOME STATEMENT'!E$17 -> 0.18499074 | F8: ='INCOME STATEMENT'!F21/'INCOME STATEMENT'!F$17 -> 0.20279959 | G8: ='INCOME STATEMENT'!G21/'INCOME STATEMENT'!G$17 -> 0.25911339 | H8: ='INCOME STATEMENT'!H21/'INCOME STATEMENT'!H$17 -> 0.23532234 | I8: ='INCOME STATEMENT'!I21/'INCOME STATEMENT'!I$17 -> 0.19573456 | ... K8: ='INCOME STATEMENT'!K21/'INCOME STATEMENT'!K$17 -> 0.14239519
A9: Restruct Remediation & Impair | B9: ='INCOME STATEMENT'!#REF!/'INCOME STATEMENT'!B$17 -> #REF! | C9: ='INCOME STATEMENT'!#REF!/'INCOME STATEMENT'!C$17 -> #REF! | D9: ='INCOME STATEMENT'!#REF!/'INCOME STATEMENT'!D$17 -> #REF! | E9: ='INCOME STATEMENT'!#REF!/'INCOME STATEMENT'!E$17 -> #REF! | F9: ='INCOME STATEMENT'!#REF!/'INCOME STATEMENT'!F$17 -> #REF! | G9: ='INCOME STATEMENT'!#REF!/'INCOME STATEMENT'!G$17 -> #REF! | H9: ='INCOME STATEMENT'!#REF!/'INCOME STATEMENT'!H$17 -> #REF! | I9: ='INCOME STATEMENT'!#REF!/'INCOME STATEMENT'!I$17 -> #REF! | ... K9: ='INCOME STATEMENT'!#REF!/'INCOME STATEMENT'!K$17 -> #REF!
A10: Total Indirect Operating Costs | B10: ='INCOME STATEMENT'!B22/'INCOME STATEMENT'!B$17 -> 0.39314007 | C10: ='INCOME STATEMENT'!C22/'INCOME STATEMENT'!C$17 -> 0.41197605 | D10: ='INCOME STATEMENT'!D22/'INCOME STATEMENT'!D$17 -> 0.3081042 | E10: ='INCOME STATEMENT'!E22/'INCOME STATEMENT'!E$17 -> 0.26889026 | F10: ='INCOME STATEMENT'!F22/'INCOME STATEMENT'!F$17 -> 0.28738477 | G10: ='INCOME STATEMENT'!G22/'INCOME STATEMENT'!G$17 -> 0.3592233 | H10: ='INCOME STATEMENT'!H22/'INCOME STATEMENT'!H$17 -> 0.35166417 | I10: ='INCOME STATEMENT'!I22/'INCOME STATEMENT'!I$17 -> 0.27621312 | ... K10: ='INCOME STATEMENT'!K22/'INCOME STATEMENT'!K$17 -> 0.1859591
A11: Operating Income(EBIT) | B11: ='INCOME STATEMENT'!B23/'INCOME STATEMENT'!B$17 -> 0.16212493 | C11: ='INCOME STATEMENT'!C23/'INCOME STATEMENT'!C$17 -> 0.1491018 | D11: ='INCOME STATEMENT'!D23/'INCOME STATEMENT'!D$17 -> 0.27988423 | E11: ='INCOME STATEMENT'!E23/'INCOME STATEMENT'!E$17 -> 0.3304509 | F11: ='INCOME STATEMENT'!F23/'INCOME STATEMENT'!F$17 -> 0.32468419 | G11: ='INCOME STATEMENT'!G23/'INCOME STATEMENT'!G$17 -> 0.26067045 | H11: ='INCOME STATEMENT'!H23/'INCOME STATEMENT'!H$17 -> 0.27178411 | I11: ='INCOME STATEMENT'!I23/'INCOME STATEMENT'!I$17 -> 0.37307721 | ... K11: ='INCOME STATEMENT'!K23/'INCOME STATEMENT'!K$17 -> 0.54121664
A12: Interest Income | B12: ='INCOME STATEMENT'!B24/'INCOME STATEMENT'!B$17 -> -0.0038541008 | C12: ='INCOME STATEMENT'!C24/'INCOME STATEMENT'!C$17 -> -0.0015968064 | D12: ='INCOME STATEMENT'!D24/'INCOME STATEMENT'!D$17 -> -0.0005788712 | E12: ='INCOME STATEMENT'!E24/'INCOME STATEMENT'!E$17 -> 0.00082355363 | F12: ='INCOME STATEMENT'!F24/'INCOME STATEMENT'!F$17 -> 0.0066575623 | G12: ='INCOME STATEMENT'!G24/'INCOME STATEMENT'!G$17 -> 0.011540575 | H12: ='INCOME STATEMENT'!H24/'INCOME STATEMENT'!H$17 -> -0.0076161919 | I12: ='INCOME STATEMENT'!I24/'INCOME STATEMENT'!I$17 -> -0.0076911644 | ... K12: ='INCOME STATEMENT'!K24/'INCOME STATEMENT'!K$17 -> 0.0099963888
A13: Other Non-Operating Income | B13: ='INCOME STATEMENT'!B25/'INCOME STATEMENT'!B$17 -> 0.0029669933 | C13: ='INCOME STATEMENT'!C25/'INCOME STATEMENT'!C$17 -> 0.00079840319 | D13: ='INCOME STATEMENT'!D25/'INCOME STATEMENT'!D$17 -> -0.003617945 | E13: ='INCOME STATEMENT'!E25/'INCOME STATEMENT'!E$17 -> -0.0022647725 | F13: ='INCOME STATEMENT'!F25/'INCOME STATEMENT'!F$17 -> 0.0011949471 | G13: ='INCOME STATEMENT'!G25/'INCOME STATEMENT'!G$17 -> -0.00018318373 | H13: ='INCOME STATEMENT'!H25/'INCOME STATEMENT'!H$17 -> 0.00023988006 | I13: ='INCOME STATEMENT'!I25/'INCOME STATEMENT'!I$17 -> 0.0039756261 | ... K13: ='INCOME STATEMENT'!K25/'INCOME STATEMENT'!K$17 -> 0.0038902203
A14: Total Non-Operating Income | B14: ='INCOME STATEMENT'!B26/'INCOME STATEMENT'!B$17 -> -0.00088710751 | C14: ='INCOME STATEMENT'!C26/'INCOME STATEMENT'!C$17 -> -0.00079840319 | D14: ='INCOME STATEMENT'!D26/'INCOME STATEMENT'!D$17 -> -0.0041968162 | E14: ='INCOME STATEMENT'!E26/'INCOME STATEMENT'!E$17 -> -0.0014412189 | F14: ='INCOME STATEMENT'!F26/'INCOME STATEMENT'!F$17 -> 0.0078525094 | G14: ='INCOME STATEMENT'!G26/'INCOME STATEMENT'!G$17 -> 0.011357391 | H14: ='INCOME STATEMENT'!H26/'INCOME STATEMENT'!H$17 -> -0.0073763118 | I14: ='INCOME STATEMENT'!I26/'INCOME STATEMENT'!I$17 -> -0.0037155384 | ... K14: ='INCOME STATEMENT'!K26/'INCOME STATEMENT'!K$17 -> 0.013886609
A15: Earnings Before Tax(EBT) | B15: ='INCOME STATEMENT'!B27/'INCOME STATEMENT'!B$17 -> 0.16123782 | C15: ='INCOME STATEMENT'!C27/'INCOME STATEMENT'!C$17 -> 0.14830339 | D15: ='INCOME STATEMENT'!D27/'INCOME STATEMENT'!D$17 -> 0.27568741 | E15: ='INCOME STATEMENT'!E27/'INCOME STATEMENT'!E$17 -> 0.32900968 | F15: ='INCOME STATEMENT'!F27/'INCOME STATEMENT'!F$17 -> 0.3325367 | G15: ='INCOME STATEMENT'!G27/'INCOME STATEMENT'!G$17 -> 0.27202784 | H15: ='INCOME STATEMENT'!H27/'INCOME STATEMENT'!H$17 -> 0.2644078 | I15: ='INCOME STATEMENT'!I27/'INCOME STATEMENT'!I$17 -> 0.36936167 | ... K15: ='INCOME STATEMENT'!K27/'INCOME STATEMENT'!K$17 -> 0.55510325
A16: Taxation | B16: ='INCOME STATEMENT'!B28/'INCOME STATEMENT'!B17 -> 0.026540385 | C16: ='INCOME STATEMENT'!C28/'INCOME STATEMENT'!C17 -> 0.025748503 | D16: ='INCOME STATEMENT'!D28/'INCOME STATEMENT'!D17 -> 0.034587554 | E16: ='INCOME STATEMENT'!E28/'INCOME STATEMENT'!E17 -> 0.015338686 | F16: ='INCOME STATEMENT'!F28/'INCOME STATEMENT'!F17 -> -0.020911574 | G16: ='INCOME STATEMENT'!G28/'INCOME STATEMENT'!G17 -> 0.015936985 | H16: ='INCOME STATEMENT'!H28/'INCOME STATEMENT'!H17 -> 0.0046176912 | I16: ='INCOME STATEMENT'!I28/'INCOME STATEMENT'!I17 -> 0.0070223675 | ... K16: ='INCOME STATEMENT'!K28/'INCOME STATEMENT'!K17 -> 0.066609763
A17: Net Income | B17: ='INCOME STATEMENT'!B29/'INCOME STATEMENT'!B$17 -> 0.13469744 | C17: ='INCOME STATEMENT'!C29/'INCOME STATEMENT'!C$17 -> 0.12255489 | D17: ='INCOME STATEMENT'!D29/'INCOME STATEMENT'!D$17 -> 0.24109986 | E17: ='INCOME STATEMENT'!E29/'INCOME STATEMENT'!E$17 -> 0.31367099 | F17: ='INCOME STATEMENT'!F29/'INCOME STATEMENT'!F$17 -> 0.35344828 | G17: ='INCOME STATEMENT'!G29/'INCOME STATEMENT'!G$17 -> 0.25609086 | H17: ='INCOME STATEMENT'!H29/'INCOME STATEMENT'!H$17 -> 0.2597901 | I17: ='INCOME STATEMENT'!I29/'INCOME STATEMENT'!I$17 -> 0.3623393 | ... K17: ='INCOME STATEMENT'!K29/'INCOME STATEMENT'!K$17 -> 0.48849348

Sheet CASHFLOW STATEMENT
A4: Powered by Clearbit
A5: NVIDIA Corp (NMS: NVDA)
A6: Standardized Annual Cash Flows | B6: 2015 | C6: 2016 | D6: 2017 | E6: 2018 | F6: 2019 | G6: 2020 | H6: 2021 | I6: 2022 | J6: 2023 | K6: 2024
A7: Report Date | B7: 01/25/2015 | C7: 01/31/2016 | D7: 01/29/2017 | E7: 01/28/2018 | F7: 01/27/2019 | G7: 01/26/2020 | H7: 01/31/2021 | I7: 01/30/2022 | J7: 01/29/2023 | K7: 01/28/2024
A8: Currency | B8: USD | C8: USD | D8: USD | E8: USD | F8: USD | G8: USD | H8: USD | I8: USD | J8: USD | K8: USD
A9: Audit Status | B9: Not Qualified | C9: Not Qualified | D9: Not Qualified | E9: Not Qualified | F9: Not Qualified | G9: Not Qualified | H9: Not Qualified | I9: Not Qualified | J9: Not Qualified | K9: Not Qualified
A10: Consolidated | B10: Yes | C10: Yes | D10: Yes | E10: Yes | F10: Yes | G10: Yes | H10: Yes | I10: Yes | J10: Yes | K10: Yes
A11: Scale | B11: Thousands | C11: Thousands | D11: Thousands | E11: Thousands | F11: Thousands | G11: Thousands | H11: Thousands | I11: Thousands | J11: Thousands | K11: Thousands
A12: Net Income | B12: 630587 | C12: 614000 | D12: 1666000 | E12: 3047000 | F12: 4141000 | G12: 2796000 | H12: 4332000 | I12: 9752000 | J12: 4368000 | K12: 29760000
A13: Adjustments from Inc to Cash | B13: 477596 | C13: 612000 | D13: 685000 | E13: 270000 | F13: 459000 | G13: 1248000 | H13: 2193000 | I13: 2719000 | J13: 3480000 | K13: 2052000
A14: Change in Working Capital | B14: -202527 | C14: -51000 | D14: -679000 | E14: 185000 | F14: -857000 | G14: 717000 | H14: -703000 | I14: -3363000 | J14: -2207000 | K14: -3722000
A15: Cash Flow from Operations | B15: 905656 | C15: 1175000 | D15: 1672000 | E15: 3502000 | F15: 3743000 | G15: 4761000 | H15: 5822000 | I15: 9108000 | J15: 5641000 | K15: 28090000
A16: Purchase of Pty Plant & Equip | B16: -122381 | C16: -86000 | D16: -176000 | E16: -593000 | F16: -600000 | G16: -489000 | H16: -1128000 | I16: -976000 | J16: -1833000 | K16: -1069000
A17: Purchase of Investments | B17: -2861809 | C17: -3477000 | D17: -3134000 | E17: -36000 | F17: -11157000 | G17: -1461000 | H17: -19308000 | I17: -24787000 | J17: -11897000 | K17: -18211000
A18: Disposal of Investments | B18: 2236780 | C18: 3138000 | D18: 2515000 | E18: 1941000 | F18: 7660000 | G18: 8109000 | H18: 9319000 | I18: 16220000 | J18: 21231000 | K18: 9782000
A19: Change in Business Activities | B19: 0 | C19: 0 | D19: 0 | E19: 0 | F19: 0 | G19: 0 | H19: -8524000 | I19: -263000 | J19: -49000 | K19: -83000
A20: Other Investing Cash Flows | B20: 20362 | C20: 25000 | D20: 2000 | E20: -34000 | F20: 0 | G20: -14000 | H20: -34000 | I20: -24000 | J20: -77000 | K20: -985000
A21: Cash Flow from Investing | B21: -727048 | C21: -400000 | D21: -793000 | E21: 1278000 | F21: -4097000 | G21: 6145000 | H21: -19675000 | I21: -9830000 | J21: 7375000 | K21: -10566000
A22: Change in LT Debt | B22: -2917 | C22: -3000 | D22: 1315000 | E22: -812000 | F22: -16000 | G22: 0 | H22: 4968000 | I22: 3977000 | J22: 0 | K22: -1250000
A23: Change in Equity | B23: -813600 | C23: -587000 | D23: -739000 | E23: -909000 | F23: -1442000 | G23: 149000 | H23: 194000 | I23: 281000 | J23: -9684000 | K23: -9130000
... A31: Net Purch of Pty Plant & Equip | B31: -122381 | C31: -86000 | D31: -176000 | E31: -593000 | F31: -600000 | G31: -489000 | H31: -1128000 | I31: -976000 | J31: -1833000 | K31: -1069000

Sheet FINANCIAL RATIOS
A1: Report Date | B1: 2015 | C1: 2016 | D1: 2017 | E1: 2018 | F1: 2019 | G1: 2020 | H1: 2021 | I1: 2022 | J1: 2023 | K1: 2024
A2: Revenue Growth | B2: ='INCOME STATEMENT'!B17/'INCOME STATEMENT'!B17 -> 1 | C2: =('INCOME STATEMENT'!C17-'INCOME STATEMENT'!B17)/'INCOME STATEMENT'!B17 -> 0.070168217 | D2: =('INCOME STATEMENT'!D17-'INCOME STATEMENT'!C17)/'INCOME STATEMENT'!C17 -> 0.37924152 | E2: =('INCOME STATEMENT'!E17-'INCOME STATEMENT'!D17)/'INCOME STATEMENT'!D17 -> 0.40578871 | F2: =('INCOME STATEMENT'!F17-'INCOME STATEMENT'!E17)/'INCOME STATEMENT'!E17 -> 0.2060943 | G2: =('INCOME STATEMENT'!G17-'INCOME STATEMENT'!F17)/'INCOME STATEMENT'!F17 -> -0.068111984 | H2: =('INCOME STATEMENT'!H17-'INCOME STATEMENT'!G17)/'INCOME STATEMENT'!G17 -> 0.52729438 | I2: =('INCOME STATEMENT'!I17-'INCOME STATEMENT'!H17)/'INCOME STATEMENT'!H17 -> 0.61403298 | J2: =('INCOME STATEMENT'!J17-'INCOME STATEMENT'!I17)/'INCOME STATEMENT'!I17 -> 0.002229323 | K2: =('INCOME STATEMENT'!K17-'INCOME STATEMENT'!J17)/'INCOME STATEMENT'!J17 -> 1.2585453
A3: Net Profit Margin | B3: ='INCOME STATEMENT'!B29/'INCOME STATEMENT'!B17 -> 0.13469744 | C3: ='INCOME STATEMENT'!C29/'INCOME STATEMENT'!C17 -> 0.12255489 | D3: ='INCOME STATEMENT'!D29/'INCOME STATEMENT'!D17 -> 0.24109986 | E3: ='INCOME STATEMENT'!E29/'INCOME STATEMENT'!E17 -> 0.31367099 | F3: ='INCOME STATEMENT'!F29/'INCOME STATEMENT'!F17 -> 0.35344828 | G3: ='INCOME STATEMENT'!G29/'INCOME STATEMENT'!G17 -> 0.25609086 | H3: ='INCOME STATEMENT'!H29/'INCOME STATEMENT'!H17 -> 0.2597901 | I3: ='INCOME STATEMENT'!I29/'INCOME STATEMENT'!I17 -> 0.3623393 | ... K3: ='INCOME STATEMENT'!K29/'INCOME STATEMENT'!K17 -> 0.48849348
A4: Gross Profit Margin | B4: ='INCOME STATEMENT'!B19/'INCOME STATEMENT'!B17 -> 0.555265 | C4: ='INCOME STATEMENT'!C19/'INCOME STATEMENT'!C17 -> 0.56107784 | D4: ='INCOME STATEMENT'!D19/'INCOME STATEMENT'!D17 -> 0.58798842 | E4: ='INCOME STATEMENT'!E19/'INCOME STATEMENT'!E17 -> 0.59934116 | F4: ='INCOME STATEMENT'!F19/'INCOME STATEMENT'!F17 -> 0.61206897 | G4: ='INCOME STATEMENT'!G19/'INCOME STATEMENT'!G17 -> 0.61989375 | H4: ='INCOME STATEMENT'!H19/'INCOME STATEMENT'!H17 -> 0.62344828 | I4: ='INCOME STATEMENT'!I19/'INCOME STATEMENT'!I17 -> 0.64929033 | ... K4: ='INCOME STATEMENT'!K19/'INCOME STATEMENT'!K17 -> 0.72717573
A5: Operating Income | B5: ='INCOME STATEMENT'!B23/'INCOME STATEMENT'!B17 -> 0.16212493 | C5: ='INCOME STATEMENT'!C23/'INCOME STATEMENT'!C17 -> 0.1491018 | D5: ='INCOME STATEMENT'!D23/'INCOME STATEMENT'!D17 -> 0.27988423 | E5: ='INCOME STATEMENT'!E23/'INCOME STATEMENT'!E17 -> 0.3304509 | F5: ='INCOME STATEMENT'!F23/'INCOME STATEMENT'!F17 -> 0.32468419 | G5: ='INCOME STATEMENT'!G23/'INCOME STATEMENT'!G17 -> 0.26067045 | H5: ='INCOME STATEMENT'!H23/'INCOME STATEMENT'!H17 -> 0.27178411 | I5: ='INCOME STATEMENT'!I23/'INCOME STATEMENT'!I17 -> 0.37307721 | ... K5: ='INCOME STATEMENT'!K23/'INCOME STATEMENT'!K17 -> 0.54121664
A6: Return On Assets | B6: ='INCOME STATEMENT'!B29/'BALANCE SHEET '!B23 -> 0.08756489 | C6: ='INCOME STATEMENT'!C29/'BALANCE SHEET '!C23 -> 0.083310719 | D6: ='INCOME STATEMENT'!D29/'BALANCE SHEET '!D23 -> 0.16929174 | E6: ='INCOME STATEMENT'!E29/'BALANCE SHEET '!E23 -> 0.27106129 | F6: ='INCOME STATEMENT'!F29/'BALANCE SHEET '!F23 -> 0.31154078 | G6: ='INCOME STATEMENT'!G29/'BALANCE SHEET '!G23 -> 0.16147849 | H6: ='INCOME STATEMENT'!H29/'BALANCE SHEET '!H23 -> 0.15046369 | I6: ='INCOME STATEMENT'!I29/'BALANCE SHEET '!I23 -> 0.2206984 | ... K6: ='INCOME STATEMENT'!K29/'BALANCE SHEET '!K23 -> 0.45277507
A7: Return on equity | B7: ='INCOME STATEMENT'!B29/'BALANCE SHEET '!B39 -> 0.14273191 | C7: ='INCOME STATEMENT'!C29/'BALANCE SHEET '!C39 -> 0.13476734 | D7: ='INCOME STATEMENT'!D29/'BALANCE SHEET '!D39 -> 0.28758847 | E7: ='INCOME STATEMENT'!E29/'BALANCE SHEET '!E39 -> 0.40784366 | F7: ='INCOME STATEMENT'!F29/'BALANCE SHEET '!F39 -> 0.44326697 | G7: ='INCOME STATEMENT'!G29/'BALANCE SHEET '!G39 -> 0.22910521 | H7: ='INCOME STATEMENT'!H29/'BALANCE SHEET '!H39 -> 0.25643758 | I7: ='INCOME STATEMENT'!I29/'BALANCE SHEET '!I39 -> 0.36645123 | ... K7: ='INCOME STATEMENT'!K29/'BALANCE SHEET '!K39 -> 0.6924473
A8: Liquidity Ratio
A9: Current Ratio | B9: ='BALANCE SHEET '!B17/'BALANCE SHEET '!B29 -> 6.3762341 | C9: ='BALANCE SHEET '!C17/'BALANCE SHEET '!C29 -> 2.5746491 | D9: ='BALANCE SHEET '!D17/'BALANCE SHEET '!D29 -> 4.7740492 | E9: ='BALANCE SHEET '!E17/'BALANCE SHEET '!E29 -> 8.0268864 | F9: ='BALANCE SHEET '!F17/'BALANCE SHEET '!F29 -> 7.9435666 | G9: ='BALANCE SHEET '!G17/'BALANCE SHEET '!G29 -> 7.6737668 | H9: ='BALANCE SHEET '!H17/'BALANCE SHEET '!H29 -> 4.0904459 | I9: ='BALANCE SHEET '!I17/'BALANCE SHEET '!I29 -> 6.6502884 | ... K9: ='BALANCE SHEET '!K17/'BALANCE SHEET '!K29 -> 4.1712915
A10: Quick Ratios | B10: =('BALANCE SHEET '!B11+'BALANCE SHEET '!B12+'BALANCE SHEET '!B14)/'BALANCE SHEET '!B29 -> 5.6883988 | C10: =('BALANCE SHEET '!C11+'BALANCE SHEET '!C12+'BALANCE SHEET '!C14)/'BALANCE SHEET '!C29 -> 2.3572948 | D10: =('BALANCE SHEET '!D11+'BALANCE SHEET '!D12+'BALANCE SHEET '!D14)/'BALANCE SHEET '!D29 -> 4.2639821 | E10: =('BALANCE SHEET '!E11+'BALANCE SHEET '!E12+'BALANCE SHEET '!E14)/'BALANCE SHEET '!E29 -> 7.2619254 | F10: =('BALANCE SHEET '!F11+'BALANCE SHEET '!F12+'BALANCE SHEET '!F14)/'BALANCE SHEET '!F29 -> 6.6561324 | G10: =('BALANCE SHEET '!G11+'BALANCE SHEET '!G12+'BALANCE SHEET '!G14)/'BALANCE SHEET '!G29 -> 7.0369955 | H10: =('BALANCE SHEET '!H11+'BALANCE SHEET '!H12+'BALANCE SHEET '!H14)/'BALANCE SHEET '!H29 -> 3.5643312 | I10: =('BALANCE SHEET '!I11+'BALANCE SHEET '!I12+'BALANCE SHEET '!I14)/'BALANCE SHEET '!I29 -> 5.9649366 | ... K10: =('BALANCE SHEET '!K11+'BALANCE SHEET '!K12+'BALANCE SHEET '!K14)/'BALANCE SHEET '!K29 -> 3.3847239
A11: Cash Ratio | B11: ='BALANCE SHEET '!B11/'BALANCE SHEET '!B33 -> 0.17843519 | C11: ='BALANCE SHEET '!C11/'BALANCE SHEET '!C33 -> 0.21179815 | D11: ='BALANCE SHEET '!D11/'BALANCE SHEET '!D33 -> 0.43626482 | E11: ='BALANCE SHEET '!E11/'BALANCE SHEET '!E33 -> 1.0615385 | F11: ='BALANCE SHEET '!F11/'BALANCE SHEET '!F33 -> 0.19797468 | G11: ='BALANCE SHEET '!G11/'BALANCE SHEET '!G33 -> 2.1318724 | H11: ='BALANCE SHEET '!H11/'BALANCE SHEET '!H33 -> 0.071188435 | I11: ='BALANCE SHEET '!I11/'BALANCE SHEET '!I33 -> 0.11322902 | ... K11: ='BALANCE SHEET '!K11/'BALANCE SHEET '!K33 -> 0.32
A12: Leverage Ratio
A13: Debt to Equity Ratio | B13: ='BALANCE SHEET '!B33/'BALANCE SHEET '!B39 -> 0.63001298 | C13: ='BALANCE SHEET '!C33/'BALANCE SHEET '!C39 -> 0.61764706 | D13: ='BALANCE SHEET '!D33/'BALANCE SHEET '!D39 -> 0.69877438 | E13: ='BALANCE SHEET '!E33/'BALANCE SHEET '!E39 -> 0.50461786 | F13: ='BALANCE SHEET '!F33/'BALANCE SHEET '!F39 -> 0.42282167 | G13: ='BALANCE SHEET '!G33/'BALANCE SHEET '!G39 -> 0.41879712 | H13: ='BALANCE SHEET '!H33/'BALANCE SHEET '!H39 -> 0.7043154 | I13: ='BALANCE SHEET '!I33/'BALANCE SHEET '!I39 -> 0.66041635 | ... K13: ='BALANCE SHEET '!K33/'BALANCE SHEET '!K39 -> 0.52934059
A14: Debt Ratio | B14: ='BALANCE SHEET '!B33/'BALANCE SHEET '!B23 -> 0.38650795 | C14: ='BALANCE SHEET '!C33/'BALANCE SHEET '!C23 -> 0.38181818 | D14: ='BALANCE SHEET '!D33/'BALANCE SHEET '!D23 -> 0.41134031 | E14: ='BALANCE SHEET '!E33/'BALANCE SHEET '!E23 -> 0.33537941 | F14: ='BALANCE SHEET '!F33/'BALANCE SHEET '!F23 -> 0.29717123 | G14: ='BALANCE SHEET '!G33/'BALANCE SHEET '!G23 -> 0.29517759 | H14: ='BALANCE SHEET '!H33/'BALANCE SHEET '!H23 -> 0.41325414 | I14: ='BALANCE SHEET '!I33/'BALANCE SHEET '!I23 -> 0.39774142 | ... K14: ='BALANCE SHEET '!K33/'BALANCE SHEET '!K23 -> 0.34612342
A17: Standardized Annual Income Statement | C17: ='INCOME STATEMENT'!C12 -> 0.070168217 | D17: ='INCOME STATEMENT'!D12 -> 0.37924152 | E17: ='INCOME STATEMENT'!E12 -> 0.40578871 | F17: ='INCOME STATEMENT'!F12 -> 0.2060943 | G17: ='INCOME STATEMENT'!G12 -> -0.068111984 | H17: ='INCOME STATEMENT'!H12 -> 0.52729438 | I17: ='INCOME STATEMENT'!I12 -> 0.61403298 | J17: ='INCOME STATEMENT'!J12 -> 0.002229323 | K17: ='INCOME STATEMENT'!K12 -> 1.2585453
A18: industry | C18: ='INCOME STATEMENT'!C53 -> -0.0062701687 | D18: ='INCOME STATEMENT'!D53 -> 0.031010396 | E18: ='INCOME STATEMENT'!E53 -> -0.13108 | F18: ='INCOME STATEMENT'!F53 -> -0.20805488 | G18: ='INCOME STATEMENT'!G53 -> -0.027432006 | H18: ='INCOME STATEMENT'!H53 -> -0.08533201 | I18: ='INCOME STATEMENT'!I53 -> -0.11063147 | J18: ='INCOME STATEMENT'!J53 -> -0.020959005 | K18: ='INCOME STATEMENT'!K53 -> 0.12834378
A19: Profitibility/return on investment
A20: EBIT/TA | B20: ='INCOME STATEMENT'!B23/'BALANCE SHEET '!B23 -> 0.10539511 | C20: ='INCOME STATEMENT'!C23/'BALANCE SHEET '!C23 -> 0.10135685 | D20: ='INCOME STATEMENT'!D23/'BALANCE SHEET '!D23 -> 0.19652474 | E20: ='INCOME STATEMENT'!E23/'BALANCE SHEET '!E23 -> 0.28556178 | F20: ='INCOME STATEMENT'!F23/'BALANCE SHEET '!F23 -> 0.28618718 | G20: ='INCOME STATEMENT'!G23/'BALANCE SHEET '!G23 -> 0.16436616 | H20: ='INCOME STATEMENT'!H23/'BALANCE SHEET '!H23 -> 0.1574103 | I20: ='INCOME STATEMENT'!I23/'BALANCE SHEET '!I23 -> 0.22723878 | ... K20: ='INCOME STATEMENT'!K23/'BALANCE SHEET '!K23 -> 0.50164314
A21: competitors | B21: =(AMD!B90+INTEL!B91+QUALCOMM!B94)/3 -> 0.043023434 | C21: =(AMD!C90+INTEL!C91+QUALCOMM!C94)/3 -> 0.057258474 | D21: =(AMD!D90+INTEL!D91+QUALCOMM!D94)/3 -> 0.21004713 | E21: =(AMD!E90+INTEL!E91+QUALCOMM!E94)/3 -> 0.16855101 | F21: =(AMD!F90+INTEL!F91+QUALCOMM!F94)/3 -> 0.1450254 | G21: =(AMD!G90+INTEL!G91+QUALCOMM!G94)/3 -> 0.16434233 | H21: =(AMD!H90+INTEL!H91+QUALCOMM!H94)/3 -> 0.087512296 | I21: =(AMD!I90+INTEL!I91+QUALCOMM!I94)/3 -> 0.024476337 | ... K21: =(AMD!K90+INTEL!K91+QUALCOMM!K94)/3 -> 0.069472984
A22: NI/TA | B22: ='INCOME STATEMENT'!B29/'BALANCE SHEET '!B23 -> 0.08756489 | C22: ='INCOME STATEMENT'!C29/'BALANCE SHEET '!C23 -> 0.083310719 | D22: ='INCOME STATEMENT'!D29/'BALANCE SHEET '!D23 -> 0.16929174 | E22: ='INCOME STATEMENT'!E29/'BALANCE SHEET '!E23 -> 0.27106129 | F22: ='INCOME STATEMENT'!F29/'BALANCE SHEET '!F23 -> 0.31154078 | G22: ='INCOME STATEMENT'!G29/'BALANCE SHEET '!G23 -> 0.16147849 | H22: ='INCOME STATEMENT'!H29/'BALANCE SHEET '!H23 -> 0.15046369 | I22: ='INCOME STATEMENT'!I29/'BALANCE SHEET '!I23 -> 0.2206984 | ... K22: ='INCOME STATEMENT'!K29/'BALANCE SHEET '!K23 -> 0.45277507
A23: competitors | B23: =(AMD!B91+INTEL!B92+QUALCOMM!B95)/3 -> 0.033669184 | C23: =(AMD!C91+INTEL!C92+QUALCOMM!C95)/3 -> 0.056680575 | D23: =(AMD!D91+INTEL!D92+QUALCOMM!D95)/3 -> 0.18751418 | E23: =(AMD!E91+INTEL!E92+QUALCOMM!E95)/3 -> 0.20503132 | F23: =(AMD!F91+INTEL!F92+QUALCOMM!F95)/3 -> 0.11303959 | G23: =(AMD!G91+INTEL!G92+QUALCOMM!G95)/3 -> 0.1204072 | H23: =(AMD!H91+INTEL!H92+QUALCOMM!H95)/3 -> 0.0092870416 | I23: =(AMD!I91+INTEL!I92+QUALCOMM!I95)/3 -> -0.011365868 | ... K23: =(AMD!K91+INTEL!K92+QUALCOMM!K95)/3 -> 0.035863397
A24: NI/TE | B24: ='INCOME STATEMENT'!B29/'BALANCE SHEET '!B23 -> 0.08756489 | C24: ='INCOME STATEMENT'!C29/'BALANCE SHEET '!C23 -> 0.083310719 | D24: ='INCOME STATEMENT'!D29/'BALANCE SHEET '!D23 -> 0.16929174 | E24: ='INCOME STATEMENT'!E29/'BALANCE SHEET '!E23 -> 0.27106129 | F24: ='INCOME STATEMENT'!F29/'BALANCE SHEET '!F23 -> 0.31154078 | G24: ='INCOME STATEMENT'!G29/'BALANCE SHEET '!G23 -> 0.16147849 | H24: ='INCOME STATEMENT'!H29/'BALANCE SHEET '!H23 -> 0.15046369 | I24: ='INCOME STATEMENT'!I29/'BALANCE SHEET '!I23 -> 0.2206984 | ... K24: ='INCOME STATEMENT'!K29/'BALANCE SHEET '!K23 -> 0.45277507
A25: competitors | B25: =(AMD!B92+INTEL!B93+QUALCOMM!B96)/3 -> 0.070783064 | C25: =(AMD!C92+INTEL!C93+QUALCOMM!C96)/3 -> 0.12507167 | D25: =(AMD!D92+INTEL!D93+QUALCOMM!D96)/3 -> 0.40631077 | E25: =(AMD!E92+INTEL!E93+QUALCOMM!E96)/3 -> 0.51457094 | F25: =(AMD!F92+INTEL!F93+QUALCOMM!F96)/3 -> 0.41129006 | G25: =(AMD!G92+INTEL!G93+QUALCOMM!G96)/3 -> 0.47689492 | H25: =(AMD!H92+INTEL!H93+QUALCOMM!H96)/3 -> -1.6300763 | I25: =(AMD!I92+INTEL!I93+QUALCOMM!I96)/3 -> -0.32570771 | ... K25: =(AMD!K92+INTEL!K93+QUALCOMM!K96)/3 -> -0.60102637
A26: Profit margin
A27: Gross Margin | B27: ='INCOME STATEMENT'!B19/'INCOME STATEMENT'!B17 -> 0.555265 | C27: ='INCOME STATEMENT'!C19/'INCOME STATEMENT'!C17 -> 0.56107784 | D27: ='INCOME STATEMENT'!D19/'INCOME STATEMENT'!D17 -> 0.58798842 | E27: ='INCOME STATEMENT'!E19/'INCOME STATEMENT'!E17 -> 0.59934116 | F27: ='INCOME STATEMENT'!F19/'INCOME STATEMENT'!F17 -> 0.61206897 | G27: ='INCOME STATEMENT'!G19/'INCOME STATEMENT'!G17 -> 0.61989375 | H27: ='INCOME STATEMENT'!H19/'INCOME STATEMENT'!H17 -> 0.62344828 | I27: ='INCOME STATEMENT'!I19/'INCOME STATEMENT'!I17 -> 0.64929033 | ... K27: ='INCOME STATEMENT'!K19/'INCOME STATEMENT'!K17 -> 0.72717573
A28: competitors | B28: =(AMD!B93+INTEL!B94+QUALCOMM!B97)/3 -> 0.44999281 | C28: =(AMD!C93+INTEL!C94+QUALCOMM!C97)/3 -> 0.46886836 | D28: =(AMD!D93+INTEL!D94+QUALCOMM!D97)/3 -> 0.49564942 | E28: =(AMD!E93+INTEL!E94+QUALCOMM!E97)/3 -> 0.52493669 | F28: =(AMD!F93+INTEL!F94+QUALCOMM!F97)/3 -> 0.53095351 | G28: =(AMD!G93+INTEL!G94+QUALCOMM!G97)/3 -> 0.53640518 | H28: =(AMD!H93+INTEL!H94+QUALCOMM!H97)/3 -> 0.50292796 | I28: =(AMD!I93+INTEL!I94+QUALCOMM!I97)/3 -> 0.47227941 | ... K28: =(AMD!K93+INTEL!K94+QUALCOMM!K97)/3 -> 0.51665899
A29: CGS/Revenue | B29: ='INCOME STATEMENT'!B18/'INCOME STATEMENT'!B17 -> 0.444735 | C29: ='INCOME STATEMENT'!C18/'INCOME STATEMENT'!C17 -> 0.43892216 | D29: ='INCOME STATEMENT'!D18/'INCOME STATEMENT'!D17 -> 0.41201158 | E29: ='INCOME STATEMENT'!E18/'INCOME STATEMENT'!E17 -> 0.40065884 | F29: ='INCOME STATEMENT'!F18/'INCOME STATEMENT'!F17 -> 0.38793103 | G29: ='INCOME STATEMENT'!G18/'INCOME STATEMENT'!G17 -> 0.38010625 | H29: ='INCOME STATEMENT'!H18/'INCOME STATEMENT'!H17 -> 0.37655172 | I29: ='INCOME STATEMENT'!I18/'INCOME STATEMENT'!I17 -> 0.35070967 | ... K29: ='INCOME STATEMENT'!K18/'INCOME STATEMENT'!K17 -> 0.27282427
A30: competitors | B30: =(AMD!B96+INTEL!B97+QUALCOMM!B100)/3 -> 0.55000719 | C30: =(AMD!C96+INTEL!C97+QUALCOMM!C100)/3 -> 0.53113164 | D30: =(AMD!D96+INTEL!D97+QUALCOMM!D100)/3 -> 0.50435058 | E30: =(AMD!E96+INTEL!E97+QUALCOMM!E100)/3 -> 0.47506331 | F30: =(AMD!F96+INTEL!F97+QUALCOMM!F100)/3 -> 0.46904649 | G30: =(AMD!G96+INTEL!G97+QUALCOMM!G100)/3 -> 0.46359482 | H30: =(AMD!H96+INTEL!H97+QUALCOMM!H100)/3 -> 0.49707204 | I30: =(AMD!I96+INTEL!I97+QUALCOMM!I100)/3 -> 0.52772059 | ... K30: =(AMD!K96+INTEL!K97+QUALCOMM!K100)/3 -> 0.48334101
A31: SGA/Revenue | B31: ='INCOME STATEMENT'!B20/'INCOME STATEMENT'!B17 -> 0.10269407 | C31: ='INCOME STATEMENT'!C20/'INCOME STATEMENT'!C17 -> 0.12015968 | D31: ='INCOME STATEMENT'!D20/'INCOME STATEMENT'!D17 -> 0.095947902 | E31: ='INCOME STATEMENT'!E20/'INCOME STATEMENT'!E17 -> 0.083899526 | F31: ='INCOME STATEMENT'!F20/'INCOME STATEMENT'!F17 -> 0.084585183 | G31: ='INCOME STATEMENT'!G20/'INCOME STATEMENT'!G17 -> 0.10010991 | H31: ='INCOME STATEMENT'!H20/'INCOME STATEMENT'!H17 -> 0.11634183 | I31: ='INCOME STATEMENT'!I20/'INCOME STATEMENT'!I17 -> 0.080478561 | ... K31: ='INCOME STATEMENT'!K20/'INCOME STATEMENT'!K17 -> 0.043563901
A32: competitors | B32: =(AMD!B97+INTEL!B98+QUALCOMM!B101)/3 -> 0.092741439 | C32: =(AMD!C97+INTEL!C98+QUALCOMM!C101)/3 -> 0.09073078 | D32: =(AMD!D97+INTEL!D98+QUALCOMM!D101)/3 -> 0.085767495 | E32: =(AMD!E97+INTEL!E98+QUALCOMM!E101)/3 -> 0.084798878 | F32: =(AMD!F97+INTEL!F98+QUALCOMM!F101)/3 -> 0.092976633 | G32: =(AMD!G97+INTEL!G98+QUALCOMM!G101)/3 -> 0.08756109 | H32: =(AMD!H97+INTEL!H98+QUALCOMM!H101)/3 -> 0.10750716 | I32: =(AMD!I97+INTEL!I98+QUALCOMM!I101)/3 -> 0.11533518 | ... K32: =(AMD!K97+INTEL!K98+QUALCOMM!K101)/3 -> 0.11522451
A33: R&D/Revenue | B33: ='INCOME STATEMENT'!B21/'INCOME STATEMENT'!B17 -> 0.290446 | C33: ='INCOME STATEMENT'!C21/'INCOME STATEMENT'!C17 -> 0.26566866 | D33: ='INCOME STATEMENT'!D21/'INCOME STATEMENT'!D17 -> 0.21172214 | E33: ='INCOME STATEMENT'!E21/'INCOME STATEMENT'!E17 -> 0.18499074 | F33: ='INCOME STATEMENT'!F21/'INCOME STATEMENT'!F17 -> 0.20279959 | G33: ='INCOME STATEMENT'!G21/'INCOME STATEMENT'!G17 -> 0.25911339 | H33: ='INCOME STATEMENT'!H21/'INCOME STATEMENT'!H17 -> 0.23532234 | I33: ='INCOME STATEMENT'!I21/'INCOME STATEMENT'!I17 -> 0.19573456 | ... K33: ='INCOME STATEMENT'!K21/'INCOME STATEMENT'!K17 -> 0.14239519
A34: competitors | B34: =(AMD!B94+INTEL!B95+QUALCOMM!B98)/3 -> 0.26624982 | C34: =(AMD!C94+INTEL!C95+QUALCOMM!C98)/3 -> 0.25138047 | D34: =(AMD!D94+INTEL!D95+QUALCOMM!D98)/3 -> 0.21216176 | E34: =(AMD!E94+INTEL!E95+QUALCOMM!E98)/3 -> 0.20304055 | F34: =(AMD!F94+INTEL!F95+QUALCOMM!F98)/3 -> 0.2192814 | G34: =(AMD!G94+INTEL!G95+QUALCOMM!G98)/3 -> 0.2098426 | H34: =(AMD!H94+INTEL!H95+QUALCOMM!H98)/3 -> 0.21876037 | I34: =(AMD!I94+INTEL!I95+QUALCOMM!I98)/3 -> 0.23023832 | ... K34: =(AMD!K94+INTEL!K95+QUALCOMM!K98)/3 -> 0.21031692
A35: Operating Costs/Sales | B35: =SUM('INCOME STATEMENT'!B20:B21)/'INCOME STATEMENT'!B17 -> 0.39314007 | C35: =SUM('INCOME STATEMENT'!C20:C21)/'INCOME STATEMENT'!C17 -> 0.38582834 | D35: =SUM('INCOME STATEMENT'!D20:D21)/'INCOME STATEMENT'!D17 -> 0.30767004 | E35: =SUM('INCOME STATEMENT'!E20:E21)/'INCOME STATEMENT'!E17 -> 0.26889026 | F35: =SUM('INCOME STATEMENT'!F20:F21)/'INCOME STATEMENT'!F17 -> 0.28738477 | G35: =SUM('INCOME STATEMENT'!G20:G21)/'INCOME STATEMENT'!G17 -> 0.3592233 | H35: =SUM('INCOME STATEMENT'!H20:H21)/'INCOME STATEMENT'!H17 -> 0.35166417 | I35: =SUM('INCOME STATEMENT'!I20:I21)/'INCOME STATEMENT'!I17 -> 0.27621312 | ... K35: =SUM('INCOME STATEMENT'!K20:K21)/'INCOME STATEMENT'!K17 -> 0.1859591
A36: Tax rate | B36: ='INCOME STATEMENT'!B28/'INCOME STATEMENT'!B27 -> 0.16460397 | C36: ='INCOME STATEMENT'!C28/'INCOME STATEMENT'!C27 -> 0.17362046 | D36: ='INCOME STATEMENT'!D28/'INCOME STATEMENT'!D27 -> 0.12545932 | E36: ='INCOME STATEMENT'!E28/'INCOME STATEMENT'!E27 -> 0.046620776 | F36: ='INCOME STATEMENT'!F28/'INCOME STATEMENT'!F27 -> -0.06288501 | G36: ='INCOME STATEMENT'!G28/'INCOME STATEMENT'!G27 -> 0.058585859 | H36: ='INCOME STATEMENT'!H28/'INCOME STATEMENT'!H27 -> 0.017464278 | I36: ='INCOME STATEMENT'!I28/'INCOME STATEMENT'!I27 -> 0.019012172 | ... K36: ='INCOME STATEMENT'!K28/'INCOME STATEMENT'!K27 -> 0.11999527
A37: Interest(on Avg Debt | B37: =('INCOME STATEMENT'!B26*-1)/AVERAGE('BALANCE SHEET '!B30:C30) -> 0.0058973551 | C37: =('INCOME STATEMENT'!C26*-1)/AVERAGE('BALANCE SHEET '!C30:D30) -> 0.004002001 | D37: =('INCOME STATEMENT'!D26*-1)/AVERAGE('BALANCE SHEET '!D30:E30) -> 0.014594867 | E37: =('INCOME STATEMENT'!E26*-1)/AVERAGE('BALANCE SHEET '!E30:F30) -> 0.0070475711 | F37: =('INCOME STATEMENT'!F26*-1)/AVERAGE('BALANCE SHEET '!F30:G30) -> -0.046242775 | G37: =('INCOME STATEMENT'!G26*-1)/AVERAGE('BALANCE SHEET '!G30:H30) -> -0.031175361 | H37: =('INCOME STATEMENT'!H26*-1)/AVERAGE('BALANCE SHEET '!H30:I30) -> 0.014547605 | I37: =('INCOME STATEMENT'!I26*-1)/AVERAGE('BALANCE SHEET '!I30:J30) -> 0.0096856991 | ... K37: =('INCOME STATEMENT'!K26*-1)/AVERAGE('BALANCE SHEET '!K30:L30) -> -0.10001182
A38: competitors | B38: =(AMD!B103+INTEL!B103+QUALCOMM!B106)/3 -> -0.021739315 | C38: =(AMD!C103+INTEL!C103+QUALCOMM!C106)/3 -> 0.025014656 | D38: =(AMD!D103+INTEL!D103+QUALCOMM!D106)/3 -> -0.072253864 | E38: =(AMD!E103+INTEL!E103+QUALCOMM!E106)/3 -> 0.043696217 | F38: =(AMD!F103+INTEL!F103+QUALCOMM!F106)/3 -> 0.10413051 | G38: =(AMD!G103+INTEL!G103+QUALCOMM!G106)/3 -> 0.0084702183 | H38: =(AMD!H103+INTEL!H103+QUALCOMM!H106)/3 -> 0.034206306 | I38: =(AMD!I103+INTEL!I103+QUALCOMM!I106)/3 -> -0.034908729 | ... K38: =(AMD!K103+INTEL!K103+QUALCOMM!K106)/3 -> 0.0098855579
A39: Net income/Revenue | B39: ='INCOME STATEMENT'!B29/'INCOME STATEMENT'!B17 -> 0.13469744 | C39: ='INCOME STATEMENT'!C29/'INCOME STATEMENT'!C17 -> 0.12255489 | D39: ='INCOME STATEMENT'!D29/'INCOME STATEMENT'!D17 -> 0.24109986 | E39: ='INCOME STATEMENT'!E29/'INCOME STATEMENT'!E17 -> 0.31367099 | F39: ='INCOME STATEMENT'!F29/'INCOME STATEMENT'!F17 -> 0.35344828 | G39: ='INCOME STATEMENT'!G29/'INCOME STATEMENT'!G17 -> 0.25609086 | H39: ='INCOME STATEMENT'!H29/'INCOME STATEMENT'!H17 -> 0.2597901 | I39: ='INCOME STATEMENT'!I29/'INCOME STATEMENT'!I17 -> 0.3623393 | ... K39: ='INCOME STATEMENT'!K29/'INCOME STATEMENT'!K17 -> 0.48849348
A40: AP, Acr Exp/Sales | B40: ='BALANCE SHEET '!B24/'INCOME STATEMENT'!B17 -> 0.12246377 | C40: ='BALANCE SHEET '!C24/'INCOME STATEMENT'!C17 -> 0.11716567 | D40: ='BALANCE SHEET '!D24/'INCOME STATEMENT'!D17 -> 0.12460203 | E40: ='BALANCE SHEET '!E24/'INCOME STATEMENT'!E17 -> 0.10376776 | F40: ='BALANCE SHEET '!F24/'INCOME STATEMENT'!F17 -> 0.089706384 | G40: ='BALANCE SHEET '!G24/'INCOME STATEMENT'!G17 -> 0.12218355 | H40: ='BALANCE SHEET '!H24/'INCOME STATEMENT'!H17 -> 0.12761619 | I40: ='BALANCE SHEET '!I24/'INCOME STATEMENT'!I17 -> 0.11859999 | ... K40: ='BALANCE SHEET '!K24/'INCOME STATEMENT'!K17 -> 0.12304258
A41: Depreciation/FA | B41: =('BALANCE SHEET '!B19-'BALANCE SHEET '!A19)/AVERAGE('BALANCE SHEET '!A18:B18) -> #VALUE! | C41: =('BALANCE SHEET '!C19-'BALANCE SHEET '!B19)/AVERAGE('BALANCE SHEET '!B18:C18) -> 0.010551684 | D41: =('BALANCE SHEET '!D19-'BALANCE SHEET '!C19)/AVERAGE('BALANCE SHEET '!C18:D18) -> 0.031427324 | E41: =('BALANCE SHEET '!E19-'BALANCE SHEET '!D19)/AVERAGE('BALANCE SHEET '!D18:E18) -> 0.047814208 | F41: =('BALANCE SHEET '!F19-'BALANCE SHEET '!E19)/AVERAGE('BALANCE SHEET '!E18:F18) -> 0.01381781 | G41: =('BALANCE SHEET '!G19-'BALANCE SHEET '!F19)/AVERAGE('BALANCE SHEET '!F18:G18) -> 0.10049423 | H41: =('BALANCE SHEET '!H19-'BALANCE SHEET '!G19)/AVERAGE('BALANCE SHEET '!G18:H18) -> 0.12720282 | I41: =('BALANCE SHEET '!I19-'BALANCE SHEET '!H19)/AVERAGE('BALANCE SHEET '!H18:I18) -> 0.1201748 | ... K41: =('BALANCE SHEET '!K19-'BALANCE SHEET '!J19)/AVERAGE('BALANCE SHEET '!J18:K18) -> 0.11706406
A42: FA/Sales | B42: ='BALANCE SHEET '!B18/'INCOME STATEMENT'!B17 -> 0.25189688 | C42: ='BALANCE SHEET '!C18/'INCOME STATEMENT'!C17 -> 0.21956088 | D42: ='BALANCE SHEET '!D18/'INCOME STATEMENT'!D17 -> 0.1723589 | E42: ='BALANCE SHEET '!E18/'INCOME STATEMENT'!E17 -> 0.17881408 | F42: ='BALANCE SHEET '!F18/'INCOME STATEMENT'!F17 -> 0.18530215 | G42: ='BALANCE SHEET '!G18/'INCOME STATEMENT'!G17 -> 0.24592416 | H42: ='BALANCE SHEET '!H18/'INCOME STATEMENT'!H17 -> 0.21331334 | I42: ='BALANCE SHEET '!I18/'INCOME STATEMENT'!I17 -> 0.17392435 | ... K42: ='BALANCE SHEET '!K18/'INCOME STATEMENT'!K17 -> 0.12184433
...

Sheet Projected Financial statement
A1: Projected Financial Statements
A2: Report Year | B2: 2023 | C2: 2024 | D2: 2025 | E2: 2026 | F2: 2027 | G2: 2028 | H2: 2029 | I2: 2030 | J2: 2031 | K2: 2032
A3: External Factors
A5: Risk Free Rate | D5: 0.0425 | E5: 0.0425 | F5: 0.0375 | G5: 0.0375 | H5: 0.0375 | I5: 0.035 | J5: 0.035 | K5: 0.035
A6: Market risk premium | D6: 0.0453 | E6: 0.0453 | F6: 0.0453 | G6: 0.0453 | H6: 0.0453 | I6: 0.0453 | J6: 0.0453 | K6: 0.0453
A7: Interest rate on debt (cost of debt) | D7: 0.0475 | E7: 0.045 | F7: 0.044 | G7: 0.044 | H7: 0.044 | I7: 0.044 | J7: 0.044 | K7: 0.044
A8: Annual sales growth | D8: 0.4 | E8: 0.35 | F8: 0.3 | G8: 0.25 | H8: 0.2 | I8: 0.18 | J8: 0.15 | K8: 0.12
A9: Cost of equity | D9: =D6*D42+D5 -> 0.119057 | E9: =E6*E42+E5 -> 0.119057 | F9: =F6*F42+F5 -> 0.114057 | G9: =G6*G42+G5 -> 0.114057 | H9: =H6*H42+H5 -> 0.114057 | I9: =I6*I42+I5 -> 0.111557 | J9: =J6*J42+J5 -> 0.111557 | K9: =K6*K42+K5 -> 0.111557
A10: Capital Structure (% debt) | C10: =C94/(C94+D44) -> 0.0025472669 | D10: =C10 -> 0.0025472669 | E10: =D10 -> 0.0025472669 | F10: =E10 -> 0.0025472669 | G10: =F10 -> 0.0025472669 | H10: =G10 -> 0.0025472669 | I10: =H10 -> 0.0025472669 | J10: =I10 -> 0.0025472669 | K10: =J10 -> 0.0025472669
A11: WACC (discount rate) | D11: =(1-D10)*D9+D10*D7*(1-D26) -> 0.11886021 | E11: =(1-E10)*E9+E10*E7*(1-E26) -> 0.1188546 | F11: =(1-F10)*F9+F10*F7*(1-F26) -> 0.1138651 | G11: =(1-G10)*G9+G10*G7*(1-G26) -> 0.1138651 | H11: =(1-H10)*H9+H10*H7*(1-H26) -> 0.1138651 | I11: =(1-I10)*I9+I10*I7*(1-I26) -> 0.11137147 | J11: =(1-J10)*J9+J10*J7*(1-J26) -> 0.11137147 | K11: =(1-K10)*K9+K10*K7*(1-K26) -> 0.11137147
A12: Perpetual CF growth | D12: 0.03
A13: Perpetual discount | D13: =K11 -> 0.11137147
A15: Debt portion to fin operations | D15: 1 | E15: 1 | F15: 1 | G15: 1 | H15: 1 | I15: 1 | J15: 1 | K15: 1
A16: Payout ratio | B16: 0 | C16: 0 | D16: 0 | E16: 0 | F16: 0 | G16: 0 | H16: 0 | I16: 0 | J16: 0 | K16: 0
A17: stock price | B17: 134.43
A19: Projected Assumptions
A21: Year | B21: 2023 | C21: 2024 | D21: 2025 | E21: 2026 | F21: 2027 | G21: 2028 | H21: 2029 | I21: 2030 | J21: 2031 | K21: 2032
A22: Sales Growth | C22: 1.26 | D22: 0.17 | E22: 0.24 | F22: 0.34 | G22: 0.47 | H22: 0.35 | I22: 0.29 | J22: 0.24 | K22: 0.17
A23: COGS/sales | C23: ='INCOME STATEMENT'!K18/'INCOME STATEMENT'!K17 -> 0.27282427 | D23: 0.2728 | E23: 0.2728 | F23: 0.2728 | G23: 0.2728 | H23: 0.2728 | I23: 0.2728 | J23: 0.2728 | K23: 0.2728
A24: SGA/Sales | C24: ='INCOME STATEMENT'!K20/'INCOME STATEMENT'!K17 -> 0.043563901 | D24: =C24 -> 0.043563901 | E24: =D24 -> 0.043563901 | F24: =E24 -> 0.043563901 | G24: =F24 -> 0.043563901 | H24: =G24 -> 0.043563901 | I24: =H24 -> 0.043563901 | J24: =I24 -> 0.043563901 | K24: =J24 -> 0.043563901
A25: Depreciation/sales | C25: ='BALANCE SHEET '!K19/'INCOME STATEMENT'!K17 -> 0.05759824 | D25: =C25 -> 0.05759824 | E25: =D25 -> 0.05759824 | F25: =E25 -> 0.05759824 | G25: =F25 -> 0.05759824 | H25: =G25 -> 0.05759824 | I25: =H25 -> 0.05759824 | J25: =I25 -> 0.05759824 | K25: =J25 -> 0.05759824
A26: Tax Rate | C26: ='INCOME STATEMENT'!K28/'INCOME STATEMENT'!K27 -> 0.11999527 | D26: =C26 -> 0.11999527 | E26: =D26 -> 0.11999527 | F26: =E26 -> 0.11999527 | G26: =F26 -> 0.11999527 | H26: =G26 -> 0.11999527 | I26: =H26 -> 0.11999527 | J26: =I26 -> 0.11999527 | K26: =J26 -> 0.11999527
A27: Cash/Sales | C27: ='BALANCE SHEET '!K11/'INCOME STATEMENT'!K17 -> 0.11949706 | D27: =C27 -> 0.11949706 | E27: =D27 -> 0.11949706 | F27: =E27 -> 0.11949706 | G27: =F27 -> 0.11949706 | H27: =G27 -> 0.11949706 | I27: =H27 -> 0.11949706 | J27: =I27 -> 0.11949706 | K27: =J27 -> 0.11949706
A28: Receivables/Sales | C28: ='BALANCE SHEET '!K14/'INCOME STATEMENT'!K17 -> 0.1641279 | D28: =C28 -> 0.1641279 | E28: =D28 -> 0.1641279 | F28: =E28 -> 0.1641279 | G28: =F28 -> 0.1641279 | H28: =G28 -> 0.1641279 | I28: =H28 -> 0.1641279 | J28: =I28 -> 0.1641279 | K28: =J28 -> 0.1641279
A29: Inventories/Sales | C29: ='BALANCE SHEET '!K15/'INCOME STATEMENT'!K17 -> 0.086701028 | D29: =C29 -> 0.086701028 | E29: =D29 -> 0.086701028 | F29: =E29 -> 0.086701028 | G29: =F29 -> 0.086701028 | H29: =G29 -> 0.086701028 | I29: =H29 -> 0.086701028 | J29: =I29 -> 0.086701028 | K29: =J29 -> 0.086701028
