Workbook

Sheet S&P500
A1: Date | B1: Open | C1: High | D1: Low | E1: Close | F1: Adj Close | G1: Volume
A2: 32874 | B2: 353.39999 | C2: 360.59 | D2: 319.82999 | E2: 329.07999 | F2: 329.07999 | G2: 3793250000
A3: 32905 | B3: 329.07999 | C3: 336.09 | D3: 322.10001 | E3: 331.89002 | F3: 331.89002 | G3: 2961970000
A4: 32933 | B4: 331.89002 | C4: 344.48999 | D4: 331.07999 | E4: 339.94 | F4: 339.94 | G4: 3283280000
A5: 32964 | B5: 339.94 | C5: 347.29999 | D5: 327.76001 | E5: 330.79999 | F5: 330.79999 | G5: 2801220000
A6: 32994 | B6: 330.79999 | C6: 362.26001 | D6: 330.79999 | E6: 361.23001 | F6: 361.23001 | G6: 3596680000
A7: 33025 | B7: 361.26001 | C7: 368.78 | D7: 351.23001 | E7: 358.01999 | F7: 358.01999 | G7: 3226280000
A8: 33055 | B8: 358.01999 | C8: 369.78 | D8: 350.09 | E8: 356.14999 | F8: 356.14999 | G8: 3373540000
A9: 33086 | B9: 356.14999 | C9: 357.35001 | D9: 306.17999 | E9: 322.56 | F9: 322.56 | G9: 4020730000
A10: 33117 | B10: 322.56 | C10: 326.53 | D10: 295.98001 | E10: 306.04999 | F10: 306.04999 | G10: 2687280000
A11: 33147 | B11: 306.10001 | C11: 319.69 | D11: 294.51001 | E11: 304 | F11: 304 | G11: 3671900000
A12: 33178 | B12: 303.98999 | C12: 323.01999 | D12: 301.60998 | E12: 322.22 | F12: 322.22 | G12: 3149770000
A13: 33208 | B13: 322.23001 | C13: 333.98001 | D13: 321.97 | E13: 330.22 | F13: 330.22 | G13: 3116830000
... A409: 45261 | B409: 4559.4302 | C409: 4793.2998 | D409: 4546.5 | E409: 4769.8301 | F409: 4769.8301 | G409: 81530670000

Sheet Task 1 
A1: Date | B1: Open | C1: High | D1: Low | E1: Close | F1: Adj Close | G1: Volume | H1: MONTHLY_RETURNS_MSFT | I1: Date | J1: Open | K1: High | L1: Low | M1: Close | N1: Adj Close | O1: Volume | P1: MONTHLY_RETURNS_WMT | S1: MSFT | T1: WMT
A2: 32874 | B2: 0.605903 | C2: 0.666667 | D2: 0.583333 | E2: 0.642361 | F2: 0.39824 | G2: 2380968000 | I2: 32874 | J2: 5.59375 | K2: 5.921875 | L2: 5.140625 | M2: 5.328125 | N2: 3.280521 | O2: 116814400 | R2: Arithmetic Average | S2: =AVERAGE(H211:H403) -> 0.016643685 | T2: =AVERAGE(P211:P403) -> 0.0093609075 | X2: MSFT | AC2: WMT
A3: 32905 | B3: 0.642361 | C3: 0.697917 | D3: 0.640625 | E3: 0.685764 | F3: 0.425149 | G3: 1429344000 | I3: 32905 | J3: 5.296875 | K3: 5.5625 | L3: 5.046875 | M3: 5.5 | N3: 3.386345 | O3: 78285600 | R3: Geometic Mean | S3: {=GEOMEAN(H211:H403+1)-1} -> 0.014372059 | T3: {=GEOMEAN(P211:P403+1)-1} -> 0.0080799794
A4: 32933 | B4: 0.684028 | C4: 0.8125 | D4: 0.684028 | E4: 0.769097 | F4: 0.476812 | G4: 1717819200 | I4: 32933 | J4: 5.5 | K4: 5.953125 | L4: 5.484375 | M4: 5.90625 | N4: 3.636472 | O4: 95044800 | R4: Standard_dev | S4: =STDEV(H211:H403) -> 0.068050274 | T4: =STDEV(P211:P403) -> 0.050633311 | X4: Row Labels | Y4: Count of MONTHLY_RETURNS | AC4: Row Labels | AD4: Count of Monthly Returns
A5: 32964 | B5: 0.762153 | C5: 0.875 | D5: 0.758681 | E5: 0.805556 | F5: 0.499415 | G5: 1200837600 | I5: 32964 | J5: 5.875 | K5: 6.484375 | L5: 5.84375 | M5: 6.203125 | N5: 3.824924 | O5: 96115200 | R5: Covariance | S5: =IF(COUNT(H211:H403)=COUNT(P211:P403),COVAR(H211:H403,P211:P403)) -> 0.0008681316 | X5: <-0.15 | Y5: 3 | AC5: <-0.14 | AD5: 3
A6: 32994 | B6: 0.815972 | C6: 1.09375 | D6: 0.788194 | E6: 1.013889 | F6: 0.628574 | G6: 1634767200 | I6: 32994 | J6: 6.25 | K6: 7.1875 | L6: 6.203125 | M6: 7.046875 | N6: 4.345191 | O6: 136082400 | R6: Correlation | S6: =CORREL(H211:H403,P211:P403) -> 0.25326515 | X6: -0.15--0.13 | Y6: 1 | AC6: -0.12--0.1 | AD6: 2
A7: 33025 | B7: 1.017361 | C7: 1.079861 | D7: 0.986111 | E7: 1.055556 | F7: 0.654407 | G7: 1165960800 | I7: 33025 | J7: 7.09375 | K7: 7.953125 | L7: 7.0625 | M7: 7.796875 | N7: 4.80765 | O7: 158752800 | X7: -0.13--0.11 | Y7: 1 | AC7: -0.08--0.06 | AD7: 6
A8: 33055 | B8: 1.055556 | C8: 1.121528 | D8: 0.913194 | E8: 0.923611 | F8: 0.572605 | G8: 1548979200 | I8: 33055 | J8: 7.828125 | K8: 9.1875 | L8: 7.5625 | M8: 7.84375 | N8: 4.842253 | O8: 207493200 | X8: -0.11--0.09 | Y8: 6 | AC8: -0.06--0.04 | AD8: 14
A9: 33086 | B9: 0.920139 | C9: 0.934028 | D9: 0.704861 | E9: 0.854167 | F9: 0.529553 | G9: 1983837600 | I9: 33086 | J9: 7.71875 | K9: 7.8125 | L9: 6.21875 | M9: 7.125 | N9: 4.398538 | O9: 217812400 | X9: -0.09--0.07 | Y9: 8 | AC9: -0.04--0.02 | AD9: 30
A10: 33117 | B10: 0.847222 | C10: 0.881944 | D10: 0.756944 | E10: 0.875 | F10: 0.542468 | G10: 1270843200 | I10: 33117 | J10: 7 | K10: 7.21875 | L10: 6.40625 | M10: 6.8125 | N10: 4.211104 | O10: 107956000 | X10: -0.07--0.05 | Y10: 15 | AC10: -0.02--1.73472347597681E-17 | AD10: 28
A11: 33147 | B11: 0.899306 | C11: 0.951389 | D11: 0.743056 | E11: 0.885417 | F11: 0.548927 | G11: 2198116800 | I11: 33147 | J11: 6.9375 | K11: 7.5 | L11: 6.21875 | M11: 6.6875 | N11: 4.133835 | O11: 163780800 | X11: -0.05--0.03 | Y11: 11 | AC11: 0-0.02 | AD11: 35
A12: 33178 | B12: 0.875 | C12: 1.03125 | D12: 0.871528 | E12: 1.003472 | F12: 0.622117 | G12: 1253152800 | I12: 33178 | J12: 6.71875 | K12: 7.5625 | L12: 6.5625 | M12: 7.53125 | N12: 4.655396 | O12: 90453200 | X12: -0.03--0.01 | Y12: 16 | AC12: 0.02-0.04 | AD12: 24
A13: 33208 | B13: 1.017361 | C13: 1.065972 | D13: 0.979167 | E13: 1.045139 | F13: 0.647948 | G13: 960004800 | I13: 33208 | J13: 7.6875 | K13: 8.25 | L13: 7.34375 | M13: 7.5625 | N13: 4.674715 | O13: 91630000 | X13: -0.00999999999999998-0.01 | Y13: 19 | AC13: 0.04-0.06 | AD13: 20
A14: 33239 | B14: 1.041667 | C14: 1.381944 | D14: 1.013889 | E14: 1.362847 | F14: 0.844916 | G14: 2219774400 | I14: 33239 | J14: 7.5 | K14: 8.25 | L14: 7.125 | M14: 8.25 | N14: 5.105473 | O14: 122999600 | X14: 0.01-0.03 | Y14: 32 | AC14: 0.06-0.08 | AD14: 16
A15: 33270 | B15: 1.375 | C15: 1.513889 | D15: 1.350694 | E15: 1.440972 | F15: 0.89335 | G15: 1781582400 | I15: 33270 | J15: 8.3125 | K15: 9.53125 | L15: 8.1875 | M15: 8.84375 | N15: 5.472917 | O15: 143195600 | X15: 0.03-0.05 | Y15: 26 | AC15: 0.08-0.1 | AD15: 8
A16: 33298 | B16: 1.430556 | C16: 1.569444 | D16: 1.291667 | E16: 1.473958 | F16: 0.913801 | G16: 1932552000 | I16: 33298 | J16: 8.8125 | K16: 9.96875 | L16: 8.6875 | M16: 9.6875 | N16: 5.995063 | O16: 103148400 | X16: 0.05-0.07 | Y16: 22 | AC16: 0.1-0.12 | AD16: 6
A17: 33329 | B17: 1.472222 | C17: 1.631944 | D17: 1.333333 | E17: 1.375 | F17: 0.85245 | G17: 1985781600 | I17: 33329 | J17: 9.71875 | K17: 11.0625 | L17: 9.625 | M17: 10.125 | N17: 6.272928 | O17: 112803600 | X17: 0.07-0.09 | Y17: 11 | AC17: 0.14-0.16 | AD17: 1
A18: 33359 | B18: 1.368056 | C18: 1.5625 | D18: 1.342014 | E18: 1.524306 | F18: 0.945015 | G18: 1462701600 | I18: 33359 | J18: 10.1875 | K18: 10.71875 | L18: 9.96875 | M18: 10.71875 | N18: 6.640784 | O18: 102512800 | X18: 0.09-0.11 | Y18: 7 | AC18: Grand Total | AD18: 193
A19: 33390 | B19: 1.520833 | C19: 1.59375 | D19: 1.354167 | E19: 1.419271 | F19: 0.879897 | G19: 1295402400 | I19: 33390 | J19: 10.6875 | K19: 10.96875 | L19: 10.28125 | M19: 10.6875 | N19: 6.621425 | O19: 83916000 | X19: 0.11-0.13 | Y19: 5
A20: 33420 | B20: 1.432292 | C20: 1.541667 | D20: 1.260417 | E20: 1.53125 | F20: 0.949319 | G20: 1587283200 | I20: 33420 | J20: 10.75 | K20: 11.9375 | L20: 10.75 | M20: 11.90625 | N20: 7.383859 | O20: 104608800 | X20: 0.13-0.15 | Y20: 4
A21: 33451 | B21: 1.536458 | C21: 1.807292 | D21: 1.494792 | E21: 1.776042 | F21: 1.101081 | G21: 1281158400 | I21: 33451 | J21: 11.84375 | K21: 12.96875 | L21: 11.125 | M21: 12.65625 | N21: 7.848985 | O21: 137896400 | X21: 0.15-0.17 | Y21: 2
A22: 33482 | B22: 1.770833 | C22: 1.875 | D22: 1.666667 | E22: 1.854167 | F22: 1.149516 | G22: 834076800 | I22: 33482 | J22: 12.65625 | K22: 12.75 | L22: 11.65625 | M22: 11.9375 | N22: 7.409559 | O22: 94159600 | X22: 0.17-0.19 | Y22: 2
A23: 33512 | B23: 1.854167 | C23: 1.984375 | D23: 1.796875 | E23: 1.955729 | F23: 1.212481 | G23: 1061928000 | I23: 33512 | J23: 12 | K23: 12.40625 | L23: 11.3125 | M23: 11.5625 | N23: 7.176801 | O23: 102027200 | X23: 0.19-0.21 | Y23: 1
A24: 33543 | B24: 1.947917 | C24: 2.119792 | D24: 1.890625 | E24: 2.026042 | F24: 1.256073 | G24: 887236800 | I24: 33543 | J24: 11.5625 | K24: 12.75 | L24: 11.34375 | M24: 12.21875 | N24: 7.584128 | O24: 100899600 | X24: 0.23-0.25 | Y24: 1
A25: 33573 | B25: 2.005208 | C25: 2.333333 | D25: 2 | E25: 2.317708 | F25: 1.436895 | G25: 808771200 | I25: 33573 | J25: 12.0625 | K25: 14.96875 | L25: 12.03125 | M25: 14.71875 | N25: 9.135875 | O25: 130064400 | X25: Grand Total | Y25: 193
A26: 33604 | B26: 2.307292 | C26: 2.776042 | D26: 2.28125 | E26: 2.505208 | F26: 1.553138 | G26: 1468929600 | I26: 33604 | J26: 14.625 | K26: 14.875 | L26: 13.34375 | M26: 13.46875 | N26: 8.366979 | O26: 152891200
A27: 33635 | B27: 2.463542 | C27: 2.6875 | D27: 2.354167 | E27: 2.572917 | F27: 1.595115 | G27: 1394030400 | I27: 33635 | J27: 13.46875 | K27: 14.125 | L27: 12.53125 | M27: 13.5 | N27: 8.386395 | O27: 111859200
A28: 33664 | B28: 2.578125 | C28: 2.713542 | D28: 2.432292 | E28: 2.46875 | F28: 1.530535 | G28: 1204272000 | I28: 33664 | J28: 13.5 | K28: 13.625 | L28: 13 | M28: 13.3125 | N28: 8.269916 | O28: 91186800
A29: 33695 | B29: 2.442708 | C29: 2.692708 | D29: 2.229167 | E29: 2.296875 | F29: 1.423979 | G29: 2138961600 | I29: 33695 | J29: 13.21875 | K29: 13.8125 | L29: 12.625 | M29: 13.0625 | N29: 8.12256 | O29: 118958800
A30: 33725 | B30: 2.302083 | C30: 2.546875 | D30: 2.276042 | E30: 2.520833 | F30: 1.562825 | G30: 1069233600 | I30: 33725 | J30: 13.0625 | K30: 13.5 | L30: 12.78125 | M30: 13.25 | N30: 8.23915 | O30: 86198400
A31: 33756 | B31: 2.510417 | C31: 2.59375 | D31: 2.054688 | E31: 2.1875 | F31: 1.356171 | G31: 1576800000 | I31: 33756 | J31: 13.25 | K31: 13.96875 | L31: 13.0625 | M31: 13.4375 | N31: 8.355749 | O31: 92739600
A32: 33786 | B32: 2.195313 | C32: 2.335938 | D32: 2.046875 | E32: 2.273438 | F32: 1.409449 | G32: 1245196800 | I32: 33786 | J32: 13.46875 | K32: 14.0625 | L32: 13.3125 | M32: 13.96875 | N32: 8.694445 | O32: 91216800
A33: 33817 | B33: 2.273438 | C33: 2.34375 | D33: 2.125 | E33: 2.328125 | F33: 1.443353 | G33: 889324800 | I33: 33817 | J33: 13.9375 | K33: 14.8125 | L33: 13.78125 | M33: 14.28125 | N33: 8.888948 | O33: 70438800
A34: 33848 | B34: 2.3125 | C34: 2.5625 | D34: 2.289063 | E34: 2.515625 | F34: 1.559597 | G34: 1002921600 | I34: 33848 | J34: 14.25 | K34: 14.875 | L34: 14.1875 | M34: 14.78125 | N34: 9.200156 | O34: 70282800
A35: 33878 | B35: 2.5 | C35: 2.820313 | D35: 2.367188 | E35: 2.773438 | F35: 1.719432 | G35: 1146720000 | I35: 33878 | J35: 14.75 | K35: 15.5625 | L35: 13.84375 | M35: 15.21875 | N35: 9.481099 | O35: 93315200
A36: 33909 | B36: 2.78125 | C36: 2.96875 | D36: 2.726563 | E36: 2.910156 | F36: 1.804191 | G36: 1227161600 | I36: 33909 | J36: 15.21875 | K36: 16.15625 | L36: 15.03125 | M36: 16.09375 | N36: 10.026214 | O36: 83831200
A37: 33939 | B37: 2.898438 | C37: 2.9375 | D37: 2.664063 | E37: 2.667969 | F37: 1.654044 | G37: 1133328000 | I37: 33939 | J37: 16.03125 | K37: 16.46875 | L37: 15.59375 | M37: 16 | N37: 9.967805 | O37: 100028400
... A209: 39173 | B209: 27.889999 | C209: 30.74 | D209: 27.559999 | E209: 29.940001 | F209: 21.568956 | G209: 958964900 | I209: 39173 | J209: 47.060001 | K209: 49.950001 | L209: 46.830002 | M209: 47.919998 | N209: 33.290913 | O209: 257144500
A210: 39203 | B210: 29.940001 | C210: 31.16 | D210: 29.9 | E210: 30.690001 | F210: 22.109261 | G210: 1327154700 | H210: MONTHLY_RETURNS | I210: 39203 | J210: 47.919998 | K210: 48.880001 | L210: 46.32 | M210: 47.599998 | N210: 33.0686 | O210: 309199900 | P210: Monthly Returns
A211: 39234 | B211: 30.790001 | C211: 30.9 | D211: 29.040001 | E211: 29.469999 | F211: 21.299141 | G211: 1181412800 | H211: =(F212-F211)/F211 -> -0.016288075 | I211: 39234 | J211: 47.900002 | K211: 51.439999 | L211: 47.689999 | M211: 48.110001 | N211: 33.57806 | O211: 443564800 | P211: =(N212-N211)/N211 -> -0.04489765
...

Sheet Task 2 
B2: MSFT | C2: Wmt
A3: ='[1]Task 1'!A2 -> Arithmetic Average | B3: ='Task 1 '!S2 -> 0.016643685 | C3: ='Task 1 '!T2 -> 0.0093609075 | F3: variance_micro | G3: =_xlfn.VAR.S([1]MSFT!H211:H403) -> 0.0046308398 | J3: expected_return | K3: =B3*G5+C3*G6 -> 0.011620983 | L3: =K3 -> 0.011620983
A4: ='[1]Task 1'!A3 -> Geometic Mean | B4: ='Task 1 '!S3 -> 0.014372059 | C4: ='Task 1 '!T3 -> 0.0080799794 | F4: var_walmart | G4: =_xlfn.VAR.S([1]Wmt!H211:H403) -> 0.0025637321 | J4: std | K4: =SQRT(((G5*B5)^2+(G6*C5)^2+2*G5*G6*B5*C5*B7)) -> 0.04515459
A5: ='[1]Task 1'!A4 -> Standard_dev | B5: ='Task 1 '!S4 -> 0.068050274 | C5: ='Task 1 '!T4 -> 0.050633311 | F5: min_var_microsoft | G5: =(G4-(B7*B5*C5))/(G3+G4-2*B7*B5*C5) -> 0.31033154
A6: ='[1]Task 1'!A5 -> Covariance | B6: ='Task 1 '!S5 -> 0.0008681316 | F6: min_var_walmart | G6: =1-G5 -> 0.68966846
A7: ='[1]Task 1'!A6 -> Correlation | B7: ='Task 1 '!S6 -> 0.25326515
A11: W_MSFT | B11: W_WMT | D11: Portfolio_expected_return | E11: Variance_for_both | F11: portfolio_stdev_of_both | G11: exp_return_for_both
A12: 1 | B12: 0 | D12: =A12*$B$3+B12*$C$3 -> 0.016643685 | E12: =(A12*$B$5)^2+(B12*$C$5)^2+(2*A12*B12*$B$5*$C$5*$B$7) -> 0.0046308398 | F12: =SQRT((A12*$B$5)^2+(B12*$C$5)^2+2*A12*B12*$B$5*$C$5*$B$7) -> 0.068050274 | G12: =D12 -> 0.016643685
A13: 0.9 | B13: 0.1 | D13: =A13*$B$3+B13*$C$3 -> 0.015915407 | E13: =(A13*$B$5)^2+(B13*$C$5)^2+(2*A13*B13*$B$5*$C$5*$B$7) -> 0.0039336951 | F13: =SQRT((A13*$B$5)^2+(B13*$C$5)^2+2*A13*B13*$B$5*$C$5*$B$7) -> 0.062719177 | G13: =D13 -> 0.015915407
A14: 0.8 | B14: 0.2 | D14: =A14*$B$3+B14*$C$3 -> 0.01518713 | E14: =(A14*$B$5)^2+(B14*$C$5)^2+(2*A14*B14*$B$5*$C$5*$B$7) -> 0.0033455358 | F14: =SQRT((A14*$B$5)^2+(B14*$C$5)^2+2*A14*B14*$B$5*$C$5*$B$7) -> 0.057840607 | G14: =D14 -> 0.01518713
A15: 0.7 | B15: 0.3 | D15: =A15*$B$3+B15*$C$3 -> 0.014458852 | E15: =(A15*$B$5)^2+(B15*$C$5)^2+(2*A15*B15*$B$5*$C$5*$B$7) -> 0.0028663617 | F15: =SQRT((A15*$B$5)^2+(B15*$C$5)^2+2*A15*B15*$B$5*$C$5*$B$7) -> 0.053538414 | G15: =D15 -> 0.014458852
A16: 0.6 | B16: 0.4 | D16: =A16*$B$3+B16*$C$3 -> 0.013730574 | E16: =(A16*$B$5)^2+(B16*$C$5)^2+(2*A16*B16*$B$5*$C$5*$B$7) -> 0.002496173 | F16: =SQRT((A16*$B$5)^2+(B16*$C$5)^2+2*A16*B16*$B$5*$C$5*$B$7) -> 0.049961715 | G16: =D16 -> 0.013730574
A17: 0.5 | B17: 0.5 | D17: =A17*$B$3+B17*$C$3 -> 0.013002296 | E17: =(A17*$B$5)^2+(B17*$C$5)^2+(2*A17*B17*$B$5*$C$5*$B$7) -> 0.0022349696 | F17: =SQRT((A17*$B$5)^2+(B17*$C$5)^2+2*A17*B17*$B$5*$C$5*$B$7) -> 0.047275465 | G17: =D17 -> 0.013002296
A18: 0.4 | B18: 0.6 | D18: =A18*$B$3+B18*$C$3 -> 0.012274019 | E18: =(A18*$B$5)^2+(B18*$C$5)^2+(2*A18*B18*$B$5*$C$5*$B$7) -> 0.0020827514 | F18: =SQRT((A18*$B$5)^2+(B18*$C$5)^2+2*A18*B18*$B$5*$C$5*$B$7) -> 0.045637172 | G18: =D18 -> 0.012274019
A19: 0.3 | B19: 0.7 | D19: =A19*$B$3+B19*$C$3 -> 0.011545741 | E19: =(A19*$B$5)^2+(B19*$C$5)^2+(2*A19*B19*$B$5*$C$5*$B$7) -> 0.0020395186 | F19: =SQRT((A19*$B$5)^2+(B19*$C$5)^2+2*A19*B19*$B$5*$C$5*$B$7) -> 0.04516103 | G19: =D19 -> 0.011545741
A20: 0.2 | B20: 0.8 | D20: =A20*$B$3+B20*$C$3 -> 0.010817463 | E20: =(A20*$B$5)^2+(B20*$C$5)^2+(2*A20*B20*$B$5*$C$5*$B$7) -> 0.0021052712 | F20: =SQRT((A20*$B$5)^2+(B20*$C$5)^2+2*A20*B20*$B$5*$C$5*$B$7) -> 0.045883234 | G20: =D20 -> 0.010817463
A21: 0.1 | B21: 0.9 | D21: =A21*$B$3+B21*$C$3 -> 0.010089185 | E21: =(A21*$B$5)^2+(B21*$C$5)^2+(2*A21*B21*$B$5*$C$5*$B$7) -> 0.002280009 | F21: =SQRT((A21*$B$5)^2+(B21*$C$5)^2+2*A21*B21*$B$5*$C$5*$B$7) -> 0.04774944 | G21: =D21 -> 0.010089185
A22: 0 | B22: 1 | D22: =A22*$B$3+B22*$C$3 -> 0.0093609075 | E22: =(A22*$B$5)^2+(B22*$C$5)^2+(2*A22*B22*$B$5*$C$5*$B$7) -> 0.0025637321 | F22: =SQRT((A22*$B$5)^2+(B22*$C$5)^2+2*A22*B22*$B$5*$C$5*$B$7) -> 0.050633311 | G22: =D22 -> 0.0093609075
D24: =MIN(D12:D22) -> 0.0093609075 | E24: =MIN(E12:E22) -> 0.0020395186 | F24: =MIN(F12:F22) -> 0.04516103

Sheet Task 3
A1: Date | B1: Adj Close | C1: Date | D1: Adj Close | E1: Rf | F1: Monthly return of MSFT | G1: Monthly return of S&p 500 | H1: Excess Returns MSFT (Y) | I1: Excess Returns S&P 500 (X) | J1: dummy | K1: interaction | P1: max
A2: 32874 | B2: 0.398241 | C2: 32874 | D2: 329.07999 | E2: 0.0065969645 | F2: =(B3/B2)-1 -> 0.067567126 | G2: =(D3/D2)-1 -> 0.0085390425 | H2: =F2-E2 -> 0.060970162 | I2: =G2-E2 -> 0.001942078 | J2: =IF(H2=$P$3, 1, 0) -> 0 | K2: =I2*J2 -> 0
A3: 32905 | B3: 0.425149 | C3: 32905 | D3: 331.89002 | E3: 0.0067982918 | F3: =(B4/B3)-1 -> 0.1215174 | G3: =(D4/D3)-1 -> 0.024254984 | H3: =F3-E3 -> 0.11471911 | I3: =G3-E3 -> 0.017456692 | J3: =IF(H3=$P$3, 1, 0) -> 0 | K3: =I3*J3 -> 0 | P3: =MAX(H2:H408) -> 0.40351586
A4: 32933 | B4: 0.476812 | C4: 32933 | D4: 339.94 | E4: 0.0068910629 | F4: =(B5/B4)-1 -> 0.047404428 | G4: =(D5/D4)-1 -> -0.026887139 | H4: =F4-E4 -> 0.040513365 | I4: =G4-E4 -> -0.033778202 | J4: =IF(H4=$P$3, 1, 0) -> 0 | K4: =I4*J4 -> 0 | Q4: average return | R4: =AVERAGE(F2:F408) -> 0.020644568
A5: 32964 | B5: 0.499415 | C5: 32964 | D5: 330.79999 | E5: 0.0070454728 | F5: =(B6/B5)-1 -> 0.25862059 | G5: =(D6/D5)-1 -> 0.09198919 | H5: =F5-E5 -> 0.25157511 | I5: =G5-E5 -> 0.084943717 | J5: =IF(H5=$P$3, 1, 0) -> 0 | K5: =I5*J5 -> 0 | Q5: std | R5: =STDEV(F2:F408) -> 0.086967136 | T5: -0.2
A6: 32994 | B6: 0.628574 | C6: 32994 | D6: 361.23001 | E6: 0.0070223279 | F6: =(B7/B6)-1 -> 0.041097786 | G6: =(D7/D6)-1 -> -0.0088863658 | H6: =F6-E6 -> 0.034075459 | I6: =G6-E6 -> -0.015908694 | J6: =IF(H6=$P$3, 1, 0) -> 0 | K6: =I6*J6 -> 0 | Q6: z score | R6: =(T5-R4)/R5 -> -2.5371029
A7: 33025 | B7: 0.654407 | C7: 33025 | D7: 358.01999 | E7: 0.0068060263 | F7: =(B8/B7)-1 -> -0.12500172 | G7: =(D8/D7)-1 -> -0.0052231581 | H7: =F7-E7 -> -0.13180775 | I7: =G7-E7 -> -0.012029184 | J7: =IF(H7=$P$3, 1, 0) -> 0 | K7: =I7*J7 -> 0 | Q7: Probability | R7: =_xlfn.NORM.S.DIST(R6,TRUE) -> 0.0055887054
A8: 33055 | B8: 0.572605 | C8: 33055 | D8: 356.14999 | E8: 0.0067982918 | F8: =(B9/B8)-1 -> -0.07518621 | G8: =(D9/D8)-1 -> -0.094314184 | H8: =F8-E8 -> -0.081984502 | I8: =G8-E8 -> -0.10111248 | J8: =IF(H8=$P$3, 1, 0) -> 0 | K8: =I8*J8 -> 0
A9: 33086 | B9: 0.529553 | C9: 33086 | D9: 322.56 | E9: 0.0070146116 | F9: =(B10/B9)-1 -> 0.024388494 | G9: =(D10/D9)-1 -> -0.051184307 | H9: =F9-E9 -> 0.017373882 | I9: =G9-E9 -> -0.058198919 | J9: =IF(H9=$P$3, 1, 0) -> 0 | K9: =I9*J9 -> 0
A10: 33117 | B10: 0.542468 | C10: 33117 | D10: 306.04999 | E10: 0.0071225801 | F10: =(B11/B10)-1 -> 0.011906693 | G10: =(D11/D10)-1 -> -0.006698213 | H10: =F10-E10 -> 0.004784113 | I10: =G10-E10 -> -0.013820793 | J10: =IF(H10=$P$3, 1, 0) -> 0 | K10: =I10*J10 -> 0
A11: 33147 | B11: 0.548927 | C11: 33147 | D11: 304 | E11: 0.0069914589 | F11: =(B12/B11)-1 -> 0.13333103 | G11: =(D12/D11)-1 -> 0.059934214 | H11: =F11-E11 -> 0.12633957 | I11: =G11-E11 -> 0.052942755 | J11: =IF(H11=$P$3, 1, 0) -> 0 | K11: =I11*J11 -> 0
A12: 33178 | B12: 0.622116 | C12: 33178 | D12: 322.22 | E12: 0.0067363921 | F12: =(B13/B12)-1 -> 0.041522803 | G12: =(D13/D12)-1 -> 0.024827757 | H12: =F12-E12 -> 0.034786411 | I12: =G12-E12 -> 0.018091365 | J12: =IF(H12=$P$3, 1, 0) -> 0 | K12: =I12*J12 -> 0
A13: 33208 | B13: 0.647948 | C13: 33208 | D13: 330.22 | E13: 0.0064883738 | F13: =(B14/B13)-1 -> 0.30398736 | G13: =(D14/D13)-1 -> 0.041517752 | H13: =F13-E13 -> 0.29749898 | I13: =G13-E13 -> 0.035029378 | J13: =IF(H13=$P$3, 1, 0) -> 0 | K13: =I13*J13 -> 0
A14: 33239 | B14: 0.844916 | C14: 33239 | D14: 343.92999 | E14: 0.0065038947 | F14: =(B15/B14)-1 -> 0.057325225 | G14: =(D15/D14)-1 -> 0.067281175 | H14: =F14-E14 -> 0.050821331 | I14: =G14-E14 -> 0.06077728 | J14: =IF(H14=$P$3, 1, 0) -> 0 | K14: =I14*J14 -> 0
A15: 33270 | B15: 0.893351 | C15: 33270 | D15: 367.07001 | E15: 0.0063174705 | F15: =(B16/B15)-1 -> 0.022891338 | G15: =(D16/D15)-1 -> 0.022202833 | H15: =F15-E15 -> 0.016573868 | I15: =G15-E15 -> 0.015885362 | J15: =IF(H15=$P$3, 1, 0) -> 0 | K15: =I15*J15 -> 0
A16: 33298 | B16: 0.913801 | C16: 33298 | D16: 375.22 | E16: 0.0065194129 | F16: =(B17/B16)-1 -> -0.06713825 | G16: =(D17/D16)-1 -> 0.00031979905 | H16: =F16-E16 -> -0.073657663 | I16: =G16-E16 -> -0.0061996138 | J16: =IF(H16=$P$3, 1, 0) -> 0 | K16: =I16*J16 -> 0
A17: 33329 | B17: 0.85245 | C17: 33329 | D17: 375.34 | E17: 0.0064650876 | F17: =(B18/B17)-1 -> 0.10858701 | G17: =(D18/D17)-1 -> 0.038604975 | H17: =F17-E17 -> 0.10212193 | I17: =G17-E17 -> 0.032139887 | J17: =IF(H17=$P$3, 1, 0) -> 0 | K17: =I17*J17 -> 0
A18: 33359 | B18: 0.945015 | C18: 33359 | D18: 389.82999 | E18: 0.0064883738 | F18: =(B19/B18)-1 -> -0.068906843 | G18: =(D19/D18)-1 -> -0.047892629 | H18: =F18-E18 -> -0.075395217 | I18: =G18-E18 -> -0.054381003 | J18: =IF(H18=$P$3, 1, 0) -> 0 | K18: =I18*J18 -> 0
A19: 33390 | B19: 0.879897 | C19: 33390 | D19: 371.16 | E19: 0.0066512116 | F19: =(B20/B19)-1 -> 0.078899007 | G19: =(D20/D19)-1 -> 0.044859343 | H19: =F19-E19 -> 0.072247796 | I19: =G19-E19 -> 0.038208132 | J19: =IF(H19=$P$3, 1, 0) -> 0 | K19: =I19*J19 -> 0
... A408: 45231 | B408: 378.14252 | C408: 45231 | D408: 4567.7998 | E408: 0.0046333333 | F408: =(B409/B408)-1 -> -0.0055600942 | G408: =(D409/D408)-1 -> 0.044229231 | H408: =F408-E408 -> -0.010193427 | I408: =G408-E408 -> 0.039595898 | J408: =IF(H408=$P$3, 1, 0) -> 0 | K408: =I408*J408 -> 0
A409: 45261 | B409: 376.04001 | C409: 45261 | D409: 4769.8301 | E409: 0.004625 | F409: =(B410/B409)-1 -> -1 | G409: =(D410/D409)-1 -> -1

Sheet Regression
A1: SUMMARY OUTPUT
A3: Regression Statistics
A4: Multiple R | B4: 0.62247969
A5: R Square | B5: 0.38748097
A6: Adjusted R Square | B6: 0.38197345
A7: Standard Error | B7: 0.068159816
A8: Observations | B8: 407
A10: ANOVA
B11: df | C11: SS | D11: MS | E11: F | F11: Significance F
A12: Regression | B12: 3 | C12: 1.1873233 | D12: 0.39577442 | E12: 127.78567 | F12: 3.5653188e-58
A13: Residual | B13: 404 | C13: 1.8768872 | D13: 0.0046457605
A14: Total | B14: 407 | C14: 3.0642105
B16: Coefficients | C16: Standard Error | D16: t Stat | E16: P-value | F16: Lower 95% | G16: Upper 95% | H16: Lower 95.0% | I16: Upper 95.0%
A17: Intercept | B17: 0.011533869 | C17: 0.0033972597 | D17: 3.3950508 | E17: 0.00075408142 | F17: 0.0048553551 | G17: 0.018212383 | H17: 0.0048553551 | I17: 0.018212383
A18: Excess Returns S&P 500 (X) | B18: 1.1761179 | C18: 0.078694341 | D18: 14.945393 | E18: 1.6247607e-40 | F18: 1.0214163 | G18: 1.3308194 | H18: 1.0214163 | I18: 1.3308194
A19: dummy | B19: 0.35626164 | C19: 0.068275275 | D19: 5.2180184 | E19: 2.8972132e-07 | F19: 0.22204247 | G19: 0.49048082 | H19: 0.22204247 | I19: 0.49048082
A20: interaction | B20: 0 | C20: 0 | D20: 65535 | E20: #NUM! | F20: 0 | G20: 0 | H20: 0 | I20: 0
