Workbook

Sheet IS
A4: Powered by Clearbit
A5: Target Corp (NYS: TGT)
A7: Exchange rate used is that of the Year End reported date
A8: Sales Growth | C8: =C23/B23-1 -> 0.016070396 | D8: =D23/C23-1 -> -0.058141899 | E8: =E23/D23-1 -> 0.034304626 | F8: =F23/E23-1 -> 0.04837296 | G8: =G23/F23-1 -> 0.036573067 | H8: =H23/G23-1 -> 0.19778011 | I8: =I23/H23-1 -> 0.13300414 | J8: =J23/I23-1 -> 0.029385406 | K8: =K23/J23-1 -> -0.015652493
A9: SGA Growth | C9: =C26/B26-1 -> -0.00074952303 | D9: =D26/C26-1 -> -0.089260143 | E9: =E26/D26-1 -> 0.066786463 | F9: =F26/E26-1 -> 0.1035233 | G9: =G26/F26-1 -> 0.032436558 | H9: =H26/G26-1 -> 0.14673813 | I9: =I26/H26-1 -> 0.061079774 | J9: =J26/I26-1 -> 0.045868773 | K9: =K26/J26-1 -> 0.043373027
A10: tax/Ebit | C10: =B36/B35 -> 0.32959212 | D10: =C36/C35 -> 0.32541133 | E10: =D36/D35 -> 0.32686003 | F10: =E36/E35 -> 0.19692814 | G10: =F36/F35 -> 0.20293798 | H10: =G36/G35 -> 0.21980907 | I10: =H36/H35 -> 0.21240534 | J10: =I36/I35 -> 0.22016392 | K10: =J36/J35 -> 0.18665886
A11: Depreciation/Sales | C11: =B27/IS!B23 -> 0.0293178 | D11: =C27/IS!C23 -> 0.029992546 | E11: =D27/IS!D23 -> 0.033067127 | F11: =E27/IS!E23 -> 0.030523519 | G11: =F27/IS!F23 -> 0.029513244 | H11: =G27/IS!G23 -> 0.030174621 | I11: =H27/IS!H23 -> 0.023834717 | J11: =I27/IS!I23 -> 0.022112165 | K11: =J27/IS!J23 -> 0.021856672
A15: Standardized Annual Income Statement
A16: Report Date | B16: 2015 | C16: 2016 | D16: 2017 | E16: 2018 | F16: 2019 | G16: 2020 | H16: 2021 | I16: 2022 | J16: 2023 | K16: 2024
A17: Currency | B17: USD | C17: USD | D17: USD | E17: USD | F17: USD | G17: USD | H17: USD | I17: USD | J17: USD | K17: USD
A18: Audit Status | B18: Not Qualified | C18: Not Qualified | D18: Not Qualified | E18: Not Qualified | F18: Not Qualified | G18: Not Qualified | H18: Not Qualified | I18: Not Qualified | J18: Not Qualified | K18: Not Qualified
A19: Consolidated | B19: Yes | C19: Yes | D19: Yes | E19: Yes | F19: Yes | G19: Yes | H19: Yes | I19: Yes | J19: Yes | K19: Yes
A20: Scale | B20: Millions | C20: Millions | D20: Millions | E20: Millions | F20: Millions | G20: Millions | H20: Millions | I20: Millions | J20: Millions | K20: Millions
A21: Sales Revenue | B21: 72618 | C21: 73785 | D21: 69495 | E21: 71879 | F21: 74433 | G21: 77130 | H21: 92400 | I21: 104611 | J21: 107588 | K21: 105803
A22: Other Revenue | B22: - | C22: - | D22: - | E22: - | F22: 923 | G22: 982 | H22: 1161 | I22: 1394 | J22: 1532 | K22: 1609
A23: Total Revenue | B23: 72618 | C23: 73785 | D23: 69495 | E23: 71879 | F23: 75356 | G23: 78112 | H23: 93561 | I23: 106005 | J23: 109120 | K23: 107412
A24: Direct Costs | B24: 51278 | C24: 51997 | D24: 48872 | E24: 51125 | F24: 53299 | G24: 54864 | H24: 66177 | I24: 74963 | J24: 82229 | K24: 77736
A25: Gross Profit | B25: 21340 | C25: 21788 | D25: 20623 | E25: 20754 | F25: 22057 | G25: 23248 | H25: 27384 | I25: 31042 | J25: 26891 | K25: 29676
A26: Selling General & Admin | B26: 14676 | C26: 14665 | D26: 13356 | E26: 14248 | F26: 15723 | G26: 16233 | H26: 18615 | I26: 19752 | J26: 20658 | K26: 21554
A27: Depreciation & Amortization | B27: 2129 | C27: 2213 | D27: 2298 | E27: 2194 | F27: 2224 | G27: 2357 | H27: 2230 | I27: 2344 | J27: 2385 | K27: 2415
A28: Other Operating Expense | B28: 0 | C28: 0 | D28: 0 | E28: 0 | F28: 0 | G28: 0 | H28: 0 | I28: 0 | J28: 0 | K28: 0
A29: Total Indirect Operating Costs | B29: 16805 | C29: 16878 | D29: 15654 | E29: 16442 | F29: 17947 | G29: 18590 | H29: 20845 | I29: 22096 | J29: 23043 | K29: 23969
A30: Operating Income | B30: 4535 | C30: 4910 | D30: 4969 | E30: 4312 | F30: 4110 | G30: 4658 | H30: 6539 | I30: 8946 | J30: 3848 | K30: 5707
A31: Interest Income | B31: -882 | C31: -607 | D31: -1004 | E31: -666 | F31: -461 | G31: -477 | H31: -977 | I31: -421 | J31: -478 | K31: -502
A32: Gains on Sale of Assets | B32: - | C32: 620 | D32: - | E32: - | F32: - | G32: - | H32: - | I32: - | J32: - | K32: -
A33: Other Non-Operating Income | B33: 0 | C33: 0 | D33: 0 | E33: 0 | F33: 27 | G33: 9 | H33: -16 | I33: 382 | J33: 48 | K33: 92
A34: Total Non-Operating Income | B34: -882 | C34: 13 | D34: -1004 | E34: -666 | F34: -434 | G34: -468 | H34: -993 | I34: -39 | J34: -430 | K34: -410
A35: Earnings Before Tax | B35: 3653 | C35: 4923 | D35: 3965 | E35: 3646 | F35: 3676 | G35: 4190 | H35: 5546 | I35: 8907 | J35: 3418 | K35: 5297
A36: Taxation | B36: 1204 | C36: 1602 | D36: 1296 | E36: 718 | F36: 746 | G36: 921 | H36: 1178 | I36: 1961 | J36: 638 | K36: 1159
A37: Discontinued Operations | B37: -4085 | C37: 42 | D37: 68 | E37: 6 | F37: 7 | G37: 12 | H37: - | I37: - | J37: - | K37: -
A38: Extraordinary Items | B38: 0 | C38: 0 | D38: 0 | E38: 0 | F38: 0 | G38: 0 | H38: 0 | I38: 0 | J38: 0 | K38: 0
A39: Accounting Changes | B39: 0 | C39: 0 | D39: 0 | E39: 0 | F39: 0 | G39: 0 | H39: 0 | I39: 0 | J39: 0 | K39: 0
A40: Net Income | B40: -1636 | C40: 3363 | D40: 2737 | E40: 2934 | F40: 2937 | G40: 3281 | H40: 4368 | I40: 6946 | J40: 2780 | K40: 4138
A41: Preference Dividends & Similar | B41: 0 | C41: 0 | D41: 0 | E41: 0 | F41: 0 | G41: 0 | H41: 0 | I41: 0 | J41: 0 | K41: 0
A42: Net Income to Common | B42: -1636 | C42: 3363 | D42: 2737 | E42: 2934 | F42: 2937 | G42: 3281 | H42: 4368 | I42: 6946 | J42: 2780 | K42: 4138
A43: Average Shares Basic | B43: 634.7 | C43: 627.7 | D43: 577.6 | E43: 546.8 | F43: 528.6 | G43: 510.9 | H43: 500.6 | I43: 488.1 | J43: 462.1 | K43: 461.5
A44: EPS Net Basic | B44: -2.58 | C44: 5.35 | D44: 4.74 | E44: 5.36 | F44: 5.55 | G44: 6.42 | H44: 8.72 | I44: 14.23 | J44: 6.02 | K44: 8.96
A45: EPS Continuing Basic | B45: 3.86 | C45: 5.29 | D45: 4.62 | E45: 5.35 | F45: 5.54 | G45: 6.39 | H45: 8.72 | I45: 14.23 | J45: 6.02 | K45: 8.96
A46: Average Shares Diluted | B46: 640.1 | C46: 632.9 | D46: 582.5 | E46: 550.3 | F46: 533.2 | G46: 515.6 | H46: 505.4 | I46: 492.7 | J46: 464.7 | K46: 462.8
A47: EPS Net Diluted | B47: -2.56 | C47: 5.31 | D47: 4.7 | E47: 5.33 | F47: 5.51 | G47: 6.36 | H47: 8.64 | I47: 14.1 | J47: 5.98 | K47: 8.94
...

Sheet SalesGrowthRegression
A1: SUMMARY OUTPUT
A3: Regression Statistics
A4: Multiple R | B4: 0.80122785
A5: R Square | B5: 0.64196607
A6: Adjusted R Square | B6: 0.59081837
A7: Standard Error | B7: 0.048847118
A8: Observations | B8: 9
A10: ANOVA
B11: df | C11: SS | D11: MS | E11: F | F11: Significance F
A12: Regression | B12: 1 | C12: 0.029947724 | D12: 0.029947724 | E12: 12.55122 | F12: 0.0094347429
A13: Residual | B13: 7 | C13: 0.016702287 | D13: 0.002386041
A14: Total | B14: 8 | C14: 0.046650011
B16: Coefficients | C16: Standard Error | D16: t Stat | E16: P-value | F16: Lower 95% | G16: Upper 95% | H16: Lower 95.0% | I16: Upper 95.0%
A17: Intercept | B17: 0.0046074297 | C17: 0.020182233 | D17: 0.22829138 | E17: 0.82594524 | F17: -0.043115967 | G17: 0.052330827 | H17: -0.043115967 | I17: 0.052330827
A18: SGAgrowth | B18: 0.92784974 | C18: 0.26189951 | D18: 3.5427701 | E18: 0.0094347429 | F18: 0.30855581 | G18: 1.5471437 | H18: 0.30855581 | I18: 1.5471437
B22: =B17+B18*4.55 -> 4.2263237

Sheet SalesRegression
B3: Year | C3: SalesGrowth | D3: SGAgrowth
B4: 2016 | C4: 0.016070396 | D4: -0.00074952303
B5: =B4+1 -> 2017 | C5: -0.058141899 | D5: -0.089260143
B6: =B5+1 -> 2018 | C6: 0.034304626 | D6: 0.066786463
B7: =B6+1 -> 2019 | C7: 0.04837296 | D7: 0.1035233
B8: =B7+1 -> 2020 | C8: 0.036573067 | D8: 0.032436558
B9: =B8+1 -> 2021 | C9: 0.19778011 | D9: 0.14673813
B10: =B9+1 -> 2022 | C10: 0.13300414 | D10: 0.061079774
B11: =B10+1 -> 2023 | C11: 0.029385406 | D11: 0.045868773
B12: =B11+1 -> 2024 | C12: -0.015652493 | D12: 0.043373027
B13: Avg | C13: =AVERAGE(C4:C12) -> 0.046855146 | D13: =AVERAGE(D4:D12) -> 0.045532929
B14: StdDev | C14: =_xlfn.STDEV.S(C4:C12) -> 0.076362631 | D14: =_xlfn.STDEV.S(D4:D12) -> 0.065941568

Sheet StockReturns
B3: Date | C3: Rf | D3: Adj Close | E3: Stock monthly returns | F3: S&P Monthy Return | G3: Stock excess returns | H3: S&P Excess returns
B4: 32874 | C4: 0.0065969645 | D4: 2.58 | E4: =D5/D4-1 -> 0.031007752 | F4: 0.0085389571 | G4: =E4-C4 -> 0.024410787 | H4: =F4-C4 -> 0.0019419926
B5: 32905 | C5: 0.0067982918 | D5: 2.66 | E5: =D6/D5-1 -> 0.12406015 | F5: 0.024255024 | G5: =E5-C5 -> 0.11726186 | H5: =F5-C5 -> 0.017456732
B6: 32933 | C6: 0.0068910629 | D6: 2.99 | E6: =D7/D6-1 -> -0.016722408 | F6: -0.026887098 | G6: =E6-C6 -> -0.023613471 | H6: =F6-C6 -> -0.033778161
B7: 32964 | C7: 0.0070454728 | D7: 2.94 | E7: =D8/D7-1 -> 0.11564626 | F7: 0.091989117 | G7: =E7-C7 -> 0.10860079 | H7: =F7-C7 -> 0.084943645
B8: 32994 | C8: 0.0070223279 | D8: 3.28 | E8: =D9/D8-1 -> -0.033536585 | F8: -0.0088863051 | G8: =E8-C8 -> -0.040558913 | H8: =F8-C8 -> -0.015908633
B9: 33025 | C9: 0.0068060263 | D9: 3.17 | E9: =D10/D9-1 -> -0.03785489 | F9: -0.0052231719 | G9: =E9-C9 -> -0.044660916 | H9: =F9-C9 -> -0.012029198 | K9: SUMMARY OUTPUT
B10: 33055 | C10: 0.0067982918 | D10: 3.05 | E10: =D11/D10-1 -> -0.18688525 | F10: -0.094314193 | G10: =E10-C10 -> -0.19368354 | H10: =F10-C10 -> -0.10111249
B11: 33086 | C11: 0.0070146116 | D11: 2.48 | E11: =D12/D11-1 -> -0.068548387 | F11: -0.051184276 | G11: =E11-C11 -> -0.075562999 | H11: =F11-C11 -> -0.058198887 | K11: Regression Statistics
B12: 33117 | C12: 0.0071225801 | D12: 2.31 | E12: =D13/D12-1 -> -0.095238095 | F12: -0.0066982519 | G12: =E12-C12 -> -0.10236068 | H12: =F12-C12 -> -0.013820832 | K12: Multiple R | L12: 0.54467159
B13: 33147 | C13: 0.0069914589 | D13: 2.09 | E13: =D14/D13-1 -> 0.13875598 | F13: 0.059934211 | G13: =E13-C13 -> 0.13176452 | H13: =F13-C13 -> 0.052942752 | K13: R Square | L13: 0.29666714
B14: 33178 | C14: 0.0067363921 | D14: 2.38 | E14: =D15/D14-1 -> 0.06302521 | F14: 0.024827757 | G14: =E14-C14 -> 0.056288818 | H14: =F14-C14 -> 0.018091365 | K14: Adjusted R Square | L14: 0.29493052
B15: 33208 | C15: 0.0064883738 | D15: 2.53 | E15: =D16/D15-1 -> 0.14229249 | F15: 0.041517776 | G15: =E15-C15 -> 0.13580412 | H15: =F15-C15 -> 0.035029402 | K15: Standard Error | L15: 0.068400451
B16: 33239 | C16: 0.0065038947 | D16: 2.89 | E16: =D17/D16-1 -> 0.041522491 | F16: 0.067281133 | G16: =E16-C16 -> 0.035018597 | H16: =F16-C16 -> 0.060777238 | K16: Observations | L16: 407
B17: 33270 | C17: 0.0063174705 | D17: 3.01 | E17: =D18/D17-1 -> 0.033222591 | F17: 0.02220285 | G17: =E17-C17 -> 0.026905121 | H17: =F17-C17 -> 0.015885379
B18: 33298 | C18: 0.0065194129 | D18: 3.11 | E18: =D19/D18-1 -> 0.067524116 | F18: 0.00031981238 | G18: =E18-C18 -> 0.061004703 | H18: =F18-C18 -> -0.0061996005 | K18: ANOVA
B19: 33329 | C19: 0.0064650876 | D19: 3.32 | E19: =D20/D19-1 -> 0.069277108 | F19: 0.038604998 | G19: =E19-C19 -> 0.062812021 | H19: =F19-C19 -> 0.032139911 | L19: df | M19: SS | N19: MS | O19: F | P19: Significance F
B20: 33359 | C20: 0.0064883738 | D20: 3.55 | E20: =D21/D20-1 -> -0.10140845 | F20: -0.047892671 | G20: =E20-C20 -> -0.10789682 | H20: =F20-C20 -> -0.054381045 | K20: Regression | L20: 1 | M20: 0.79924789 | N20: 0.79924789 | O20: 170.82977 | P20: 8.1170645e-33
B21: 33390 | C21: 0.0066512116 | D21: 3.19 | E21: =D22/D21-1 -> -0.037617555 | F21: 0.04485936 | G21: =E21-C21 -> -0.044268766 | H21: =F21-C21 -> 0.038208148 | K21: Residual | L21: 405 | M21: 1.8948418 | N21: 0.0046786217
B22: 33420 | C22: 0.006643464 | D22: 3.07 | E22: =D23/D22-1 -> 0.13355049 | F22: 0.019648797 | G22: =E22-C22 -> 0.12690702 | H22: =F22-C22 -> 0.013005333 | K22: Total | L22: 406 | M22: 2.6940897
B23: 33451 | C23: 0.0063563402 | D23: 3.48 | E23: =D24/D23-1 -> -0.060344828 | F23: -0.019143717 | G23: =E23-C23 -> -0.066701168 | H23: =F23-C23 -> -0.025500057
B24: 33482 | C24: 0.0061618262 | D24: 3.27 | E24: =D25/D24-1 -> -0.12538226 | F24: 0.011834167 | G24: =E24-C24 -> -0.13154409 | H24: =F24-C24 -> 0.0056723407 | L24: Coefficients | M24: Standard Error | N24: t Stat | O24: P-value | P24: Lower 95% | Q24: Upper 95% | R24: Lower 95.0% | S24: Upper 95.0%
B25: 33512 | C25: 0.0060683124 | D25: 2.86 | E25: =D26/D25-1 -> -0.1013986 | F25: -0.043903682 | G25: =E25-C25 -> -0.10746691 | H25: =F25-C25 -> -0.049971994 | K25: Intercept | L25: 0.0054880433 | M25: 0.0034055622 | N25: 1.6114941 | O25: 0.10785108 | P25: -0.0012067426 | Q25: 0.012182829 | R25: -0.0012067426 | S25: 0.012182829
B26: 33543 | C26: 0.0059825074 | D26: 2.57 | E26: =D27/D26-1 -> 0.085603113 | F26: 0.11158787 | G26: =E26-C26 -> 0.079620605 | H26: =F26-C26 -> 0.10560536 | K26: S&P Excess returns | L26: 1.0317037 | M26: 0.078935653 | N26: 13.070186 | O26: 8.1170645e-33 | P26: 0.87652895 | Q26: 1.1868785 | R26: 0.87652895 | S26: 1.1868785
B27: 33573 | C27: 0.005724608 | D27: 2.79 | E27: =D28/D27-1 -> 0.050179211 | F27: -0.019923757 | G27: =E27-C27 -> 0.044454603 | H27: =F27-C27 -> -0.025648365
B28: 33604 | C28: 0.005677639 | D28: 2.93 | E28: =D29/D28-1 -> 0.04778157 | F28: 0.0095895103 | G28: =E28-C28 -> 0.042103931 | H28: =F28-C28 -> 0.0039118713
B29: 33635 | C29: 0.0059200531 | D29: 3.07 | E29: =D30/D29-1 -> -0.081433225 | F29: -0.021831839 | G29: =E29-C29 -> -0.087353278 | H29: =F29-C29 -> -0.027751892
B30: 33664 | C30: 0.0060761089 | D30: 2.82 | E30: =D31/D30-1 -> -0.017730496 | F30: 0.02789269 | G30: =E30-C30 -> -0.023806605 | H30: =F30-C30 -> 0.021816581
B31: 33695 | C31: 0.0060293201 | D31: 2.77 | E31: =D32/D31-1 -> 0.10830325 | F31: 0.00096397156 | G31: =E31-C31 -> 0.10227393 | H31: =F31-C31 -> -0.0050653485
B32: 33725 | C32: 0.005959092 | D32: 3.07 | E32: =D33/D32-1 -> -0.006514658 | F32: -0.017358854 | G32: =E32-C32 -> -0.01247375 | H32: =F32-C32 -> -0.023317946
B33: 33756 | C33: 0.0058575561 | D33: 3.05 | E33: =D34/D33-1 -> -0.019672131 | F33: 0.039373744 | G33: =E33-C33 -> -0.025529687 | H33: =F33-C33 -> 0.033516188
B34: 33786 | C34: 0.0055287443 | D34: 2.99 | E34: =D35/D34-1 -> 0.010033445 | F34: -0.023997548 | G34: =E34-C34 -> 0.0045047006 | H34: =F34-C34 -> -0.029526293
B35: 33817 | C35: 0.0053324599 | D35: 3.02 | E35: =D36/D35-1 -> 0.059602649 | F35: 0.0091056204 | G35: =E35-C35 -> 0.054270189 | H35: =F35-C35 -> 0.0037731604
B36: 33848 | C36: 0.0051987454 | D36: 3.2 | E36: =D37/D36-1 -> 0.096875 | F36: 0.0021062709 | G36: =E36-C36 -> 0.091676255 | H36: =F36-C36 -> -0.0030924745
B37: 33878 | C37: 0.0053324599 | D37: 3.51 | E37: =D38/D37-1 -> 0.028490028 | F37: 0.030261775 | G37: =E37-C37 -> 0.023157569 | H37: =F37-C37 -> 0.024929315
B38: 33909 | C38: 0.0055522701 | D38: 3.61 | E38: =D39/D38-1 -> -0.033240997 | F38: 0.010107801 | G38: =E38-C38 -> -0.038793267 | H38: =F38-C38 -> 0.004555531
... B410: 45231 | C410: 0.0046333333 | D410: 129.55 | E410: =D411/D410-1 -> 0.075414898 | F410: 0.044229169 | G410: =E410-C410 -> 0.070781564 | H410: =F410-C410 -> 0.039595836
B411: 45261 | C411: 0.004625 | D411: 139.32 | G411: =E411-C411 -> -0.004625 | H411: =F411-C411 -> -0.004625
E412: =AVERAGE(E4:E410) -> 0.013137764

Sheet Projections
B1: ASSUMPTIONS
B3: Year | C3: =IS!J16 -> 2023 | D3: =IS!K16 -> 2024 | E3: 2025 | F3: 2026 | G3: 2027 | H3: 2028 | I3: 2029 | J3: 2030 | K3: 2031 | L3: 2032 | M3: 2033
B4: Sales Growth | E4: 0.042 | F4: 0.042 | G4: 0.04 | H4: 0.04 | I4: 0.038 | J4: 0.038 | K4: 0.036 | L4: 0.036 | M4: 0.034
B5: COGS/sales | E5: 0.7 | F5: 0.7 | G5: 0.702 | H5: 0.702 | I5: 0.704 | J5: 0.704 | K5: 0.706 | L5: 0.706 | M5: 0.706
B6: SGA/Sales | E6: 0.198 | F6: =E6+0.001 -> 0.199 | G6: =F6+0.001 -> 0.2 | H6: =G6+0.001 -> 0.201 | I6: =H6+0.001 -> 0.202 | J6: =I6+0.001 -> 0.203 | K6: =J6+0.001 -> 0.204 | L6: =K6+0.001 -> 0.205 | M6: =L6+0.001 -> 0.206
B7: Depreciation/sales | E7: 0.027 | F7: 0.027 | G7: 0.027 | H7: 0.027 | I7: 0.027 | J7: 0.027 | K7: 0.027 | L7: 0.027 | M7: 0.027
B8: Taxation/EBIT | E8: 0.25 | F8: 0.25 | G8: 0.25 | H8: 0.25 | I8: 0.25 | J8: 0.25 | K8: 0.25 | L8: 0.25 | M8: 0.25
B10: Cash/Sales | E10: 0.04 | F10: 0.04 | G10: 0.04 | H10: 0.03 | I10: 0.03 | J10: 0.03 | K10: 0.03 | L10: 0.03 | M10: 0.03
B11: Receivables/Sales | E11: 0.015 | F11: 0.015 | G11: 0.015 | H11: 0.015 | I11: 0.015 | J11: 0.015 | K11: 0.015 | L11: 0.015 | M11: 0.015
B12: Inventories/Sales | E12: 0.14 | F12: 0.14 | G12: 0.14 | H12: 0.14 | I12: 0.14 | J12: 0.14 | K12: 0.14 | L12: 0.14 | M12: 0.14
B13: FA/Sales | E13: 0.55 | F13: 0.55 | G13: 0.55 | H13: 0.55 | I13: 0.55 | J13: 0.55 | K13: 0.55 | L13: 0.55 | M13: 0.55
B14: Other Assets/Sales | E14: 0.03 | F14: 0.03 | G14: 0.03 | H14: 0.03 | I14: 0.03 | J14: 0.03 | K14: 0.03 | L14: 0.03 | M14: 0.03
B15: Accounts Payable/sales | E15: 0.19 | F15: 0.19 | G15: 0.19 | H15: 0.19 | I15: 0.19 | J15: 0.19 | K15: 0.19 | L15: 0.19 | M15: 0.19
B16: Other Current Liabilities/Sales | E16: 0.01 | F16: 0.01 | G16: 0.01 | H16: 0.01 | I16: 0.01 | J16: 0.01 | K16: 0.01 | L16: 0.01 | M16: 0.01
B17: LT debt/Slales | E17: 0.17 | F17: 0.17 | G17: 0.17 | H17: 0.17 | I17: 0.17 | J17: 0.17 | K17: 0.17 | L17: 0.17 | M17: 0.17
B18: Deferred LT liabilities/Sales | E18: 0.02 | F18: 0.02 | G18: 0.02 | H18: 0.02 | I18: 0.02 | J18: 0.02 | K18: 0.02 | L18: 0.02 | M18: 0.02
B19: Other Liabilites/Sales | E19: 0.035 | F19: 0.035 | G19: 0.035 | H19: 0.035 | I19: 0.035 | J19: 0.035 | K19: 0.035 | L19: 0.035 | M19: 0.035
... B21: Retained Earnings/Sales | E21: 0.09 | F21: 0.09 | G21: 0.09 | H21: 0.09 | I21: 0.09 | J21: 0.09 | K21: 0.09 | L21: 0.09 | M21: 0.09
B23: External Factors
B25: Risk Free Rate | E25: 0.035 | F25: 0.03 | G25: 0.0275 | H25: 0.0275 | I25: 0.0275 | J25: 0.0275 | K25: 0.0275 | L25: 0.0275 | M25: 0.0275
B26: Market risk premium | E26: 0.055 | F26: 0.055 | G26: 0.055 | H26: 0.055 | I26: 0.055 | J26: 0.055 | K26: 0.055 | L26: 0.055 | M26: 0.055
B27: Interest rate on debt (cost of debt) | E27: 0.064 | F27: 0.064 | G27: 0.064 | H27: 0.064 | I27: 0.064 | J27: 0.064 | K27: 0.064 | L27: 0.064 | M27: 0.064
B28: Annual sales growth | F28: =E4 -> 0.042 | G28: =F4 -> 0.042 | H28: =G4 -> 0.04 | I28: =H4 -> 0.04 | J28: =I4 -> 0.038 | K28: =J4 -> 0.038 | L28: =K4 -> 0.036 | M28: =L4 -> 0.036
B29: Cost of equity | E29: =E25+D39*E26 -> 0.09165 | F29: =F25+E39*F26 -> 0.08665 | G29: =G25+F39*G26 -> 0.0836 | H29: =H25+G39*H26 -> 0.0836 | I29: =I25+H39*I26 -> 0.0836 | J29: =J25+I39*J26 -> 0.08305 | K29: =K25+J39*K26 -> 0.08305 | L29: =L25+K39*L26 -> 0.08305 | M29: =M25+L39*M26 -> 0.0825
B30: Capital Structure (% debt) | E30: =E70/($C$41+E70) -> 0.27457478 | F30: =E30 -> 0.27457478 | G30: =F30 -> 0.27457478 | H30: =G30 -> 0.27457478 | I30: =H30 -> 0.27457478 | J30: =I30 -> 0.27457478 | K30: =J30 -> 0.27457478 | L30: =K30 -> 0.27457478 | M30: =L30 -> 0.27457478
B31: WACC (discount rate) | E31: =(1-E30)*E29+E30*E27*(1-E8) -> 0.079664811 | F31: =(1-F30)*F29+F30*F27*(1-F8) -> 0.076037685 | G31: =(1-G30)*G29+G30*G27*(1-G8) -> 0.073825138 | H31: =(1-H30)*H29+H30*H27*(1-H8) -> 0.073825138 | I31: =(1-I30)*I29+I30*I27*(1-I8) -> 0.073825138 | J31: =(1-J30)*J29+J30*J27*(1-J8) -> 0.073426154 | K31: =(1-K30)*K29+K30*K27*(1-K8) -> 0.073426154 | L31: =(1-L30)*L29+L30*L27*(1-L8) -> 0.073426154 | M31: =(1-M30)*M29+M30*M27*(1-M8) -> 0.07302717
B32: Perpetual CF growth | E32: 0.03
B33: Perpetual discount | E33: =M31 -> 0.07302717
B35: Payout and financing
B37: Debt portion to fin operations | E37: 1 | F37: 1 | G37: 1 | H37: 1 | I37: 1 | J37: 1 | K37: 1 | L37: 1 | M37: 1
B38: Payout ratio | C38: 0.46 | D38: 0.46 | E38: 0.46 | F38: 0.46 | G38: 0.46 | H38: 0.46 | I38: 0.46 | J38: 0.46 | K38: 0.46 | L38: 0.46 | M38: 0.46
B39: beta | C39: 1.03 | D39: 1.03 | E39: 1.03 | F39: 1.02 | G39: 1.02 | H39: 1.02 | I39: 1.01 | J39: 1.01 | K39: 1.01 | L39: 1 | M39: 1 | O39: Common Size IS as percent of Total revenue
B40: Number of shares | C40: 417.48
B41: Market cap | C41: =62990 -> 62990
B43: Income statement | O43: 2023 | P43: 2024 | Q43: 2025 | R43: 2026 | S43: 2027 | T43: 2028 | U43: 2029 | V43: 2030 | W43: 2031 | X43: 2032 | Y43: 2033
B45: =IS!A21 -> Sales Revenue | C45: =IS!J21 -> 107588 | D45: =IS!K21 -> 105803
B46: =IS!A22 -> Other Revenue | C46: =IS!J22 -> 1532 | D46: =IS!K22 -> 1609
B47: =IS!A23 -> Total Revenue | C47: =IS!J23 -> 109120 | D47: =IS!K23 -> 107412 | E47: =D47*(1+E4) -> 111923.3 | F47: =E47*(1+F4) -> 116624.08 | G47: =F47*(1+G4) -> 121289.05 | H47: =G47*(1+H4) -> 126140.61 | I47: =H47*(1+I4) -> 130933.95 | J47: =I47*(1+J4) -> 135909.44 | K47: =J47*(1+K4) -> 140802.18 | L47: =K47*(1+L4) -> 145871.06 | M47: =L47*(1+M4) -> 150830.68
B48: =IS!A24 -> Direct Costs | C48: =IS!J24 -> 82229 | D48: =IS!K24 -> 77736 | E48: =E47*(E5) -> 78346.313 | F48: =F47*(F5) -> 81636.858 | G48: =G47*(G5) -> 85144.91 | H48: =H47*(H5) -> 88550.707 | I48: =I47*(I5) -> 92177.502 | J48: =J47*(J5) -> 95680.247 | K48: =K47*(K5) -> 99406.34 | L48: =L47*(L5) -> 102984.97 | M48: =M47*(M5) -> 106486.46
B49: =IS!A25 -> Gross Profit | C49: =IS!J25 -> 26891 | D49: =IS!K25 -> 29676 | E49: =E47-E48 -> 33576.991 | F49: =F47-F48 -> 34987.225 | G49: =G47-G48 -> 36144.136 | H49: =H47-H48 -> 37589.901 | I49: =I47-I48 -> 38756.45 | J49: =J47-J48 -> 40229.195 | K49: =K47-K48 -> 41395.841 | L49: =L47-L48 -> 42886.092 | M49: =M47-M48 -> 44344.219
...

Sheet WACC,RV
C2: Target | E2: Costco | F2: Walmart | G2: Kroger | H2: Lowes | I2: Kohl's
B3: Market Cap | C3: =Projections!C41 -> 62990 | E3: 388215.16 | F3: 646516.53 | G3: 40240.291 | H3: 153288.51 | I3: 2162.96
B4: Shares outstanding | C4: =Projections!C40 -> 417.48 | E4: 442.79 | F4: 8054 | G4: 720 | H4: 574 | I4: 111
B5: NET INCOME | C5: 4138 | E5: 6292 | F5: 15511 | G5: 2164 | H5: 7726 | I5: 317
B6: EBITDA | C6: 5297 | E6: 8487 | F6: 21848 | G6: 2836 | H6: 10175 | I6: 373
B7: SALES | C7: 105803 | E7: 237710 | F7: 642637 | G7: 150039 | H7: 86377 | I7: 16586
B8: BOOK VALUE (EQUITY) | C8: 13432 | E8: 25058 | F8: 83861 | G8: 11615 | H8: -15050 | I8: 3893
J9: Average
B10: P/E | C10: =C3/C5 -> 15.22233 | E10: =E3/E5 -> 61.699803 | F10: =F3/F5 -> 41.681164 | G10: =G3/G5 -> 18.595329 | H10: =H3/H5 -> 19.840605 | I10: =I3/I5 -> 6.8232177 | J10: =AVERAGE(C10,G10,H10) -> 17.886088
B11: EBITDA multiplier | C11: =C3/C6 -> 11.891637 | E11: =E3/E6 -> 45.742331 | F11: =F3/F6 -> 29.591566 | G11: =G3/G6 -> 14.189101 | H11: =H3/H6 -> 15.06521 | I11: =I3/I6 -> 5.7988204 | J11: =AVERAGE(C11,G11,H11) -> 13.715316
B12: Sales multiplier | C12: =C3/C7 -> 0.59535174 | E12: =E3/E7 -> 1.6331461 | F12: =F3/F7 -> 1.0060369 | G12: =G3/G7 -> 0.26819887 | H12: =H3/H7 -> 1.774645 | I12: =I3/I7 -> 0.13040878 | J12: =AVERAGE(C12,E12,F12,G12,H12,I12) -> 0.9012979
B13: Book Value multiplier | C13: =C3/C8 -> 4.6895473 | E13: =E3/E8 -> 15.492663 | F13: =F3/F8 -> 7.7093825 | G13: =G3/G8 -> 3.4645106 | I13: =I3/I8 -> 0.55560236 | J13: =AVERAGE(C13,F13,G13,I13) -> 4.1047607
B15: Target
C16: Cap Based on AVG | D16: Price per share
B17: P/E (forward or last earnings) | C17: =J10*C5 -> 74012.63 | D17: =C17/Projections!$C$40 -> 177.28425
B18: EBITDA multiplier | C18: =J11*C6 -> 72650.029 | D18: =C18/Projections!$C$40 -> 174.02038
B19: Sales multiplier | C19: =J12*C7 -> 95360.021 | D19: =C19/Projections!$C$40 -> 228.41818
B20: Book Value multiplier | C20: =J13*C8 -> 55135.146 | D20: =C20/Projections!$C$40 -> 132.06656
C22: Average | D22: =AVERAGE(D17:D20) -> 177.94734

Sheet CS IS
A4: Powered by Clearbit
A5: Target Corp (NYS: TGT)
A7: Exchange rate used is that of the Year End reported date
A10: Standardized Annual Income Statement
A11: Report Date | B11: =IS!B16 -> 2015 | C11: =IS!C16 -> 2016 | D11: =IS!D16 -> 2017 | E11: =IS!E16 -> 2018 | F11: =IS!F16 -> 2019 | G11: =IS!G16 -> 2020 | H11: =IS!H16 -> 2021 | I11: =IS!I16 -> 2022 | ... K11: =IS!K16 -> 2024 | L11: Average
A12: Currency
A13: Audit Status
A14: Consolidated
A15: Scale
A16: Sales Revenue | B16: =IS!B21/IS!B$23 -> 1 | C16: =IS!C21/IS!C$23 -> 1 | D16: =IS!D21/IS!D$23 -> 1 | E16: =IS!E21/IS!E$23 -> 1 | F16: =IS!F21/IS!F$23 -> 0.98775147 | G16: =IS!G21/IS!G$23 -> 0.98742831 | H16: =IS!H21/IS!H$23 -> 0.98759098 | I16: =IS!I21/IS!I$23 -> 0.98684968 | ... K16: =IS!K21/IS!K$23 -> 0.9850203
A17: Other Revenue | F17: =IS!F22/IS!F$23 -> 0.012248527 | G17: =IS!G22/IS!G$23 -> 0.012571692 | H17: =IS!H22/IS!H$23 -> 0.012409017 | I17: =IS!I22/IS!I$23 -> 0.013150323 | J17: =IS!J22/IS!J$23 -> 0.014039589 | K17: =IS!K22/IS!K$23 -> 0.014979704
A18: Total Revenue | B18: =IS!B23/IS!B$23 -> 1 | C18: =IS!C23/IS!C$23 -> 1 | D18: =IS!D23/IS!D$23 -> 1 | E18: =IS!E23/IS!E$23 -> 1 | F18: =IS!F23/IS!F$23 -> 1 | G18: =IS!G23/IS!G$23 -> 1 | H18: =IS!H23/IS!H$23 -> 1 | I18: =IS!I23/IS!I$23 -> 1 | ... K18: =IS!K23/IS!K$23 -> 1
A19: Direct Costs | B19: =IS!B24/IS!B$23 -> 0.70613347 | C19: =IS!C24/IS!C$23 -> 0.70470963 | D19: =IS!D24/IS!D$23 -> 0.70324484 | E19: =IS!E24/IS!E$23 -> 0.71126476 | F19: =IS!F24/IS!F$23 -> 0.70729603 | G19: =IS!G24/IS!G$23 -> 0.70237608 | H19: =IS!H24/IS!H$23 -> 0.70731394 | I19: =IS!I24/IS!I$23 -> 0.70716476 | ... K19: =IS!K24/IS!K$23 -> 0.72371802 | L19: =AVERAGE(B19:K19) -> 0.71267864
A20: Gross Profit | B20: =IS!B25/IS!B$23 -> 0.29386653 | C20: =IS!C25/IS!C$23 -> 0.29529037 | D20: =IS!D25/IS!D$23 -> 0.29675516 | E20: =IS!E25/IS!E$23 -> 0.28873524 | F20: =IS!F25/IS!F$23 -> 0.29270397 | G20: =IS!G25/IS!G$23 -> 0.29762392 | H20: =IS!H25/IS!H$23 -> 0.29268606 | I20: =IS!I25/IS!I$23 -> 0.29283524 | ... K20: =IS!K25/IS!K$23 -> 0.27628198 | L20: =AVERAGE(B20:K20) -> 0.28732136
A21: Selling General & Admin | B21: =IS!B26/IS!B$23 -> 0.20209865 | C21: =IS!C26/IS!C$23 -> 0.19875313 | D21: =IS!D26/IS!D$23 -> 0.19218649 | E21: =IS!E26/IS!E$23 -> 0.19822201 | F21: =IS!F26/IS!F$23 -> 0.20864961 | G21: =IS!G26/IS!G$23 -> 0.20781698 | H21: =IS!H26/IS!H$23 -> 0.19896111 | I21: =IS!I26/IS!I$23 -> 0.18633083 | ... K21: =IS!K26/IS!K$23 -> 0.20066659 | L21: =AVERAGE(B21:K21) -> 0.19829999
A22: Depreciation & Amortization | B22: =IS!B27/IS!B$23 -> 0.0293178 | C22: =IS!C27/IS!C$23 -> 0.029992546 | D22: =IS!D27/IS!D$23 -> 0.033067127 | E22: =IS!E27/IS!E$23 -> 0.030523519 | F22: =IS!F27/IS!F$23 -> 0.029513244 | G22: =IS!G27/IS!G$23 -> 0.030174621 | H22: =IS!H27/IS!H$23 -> 0.023834717 | I22: =IS!I27/IS!I$23 -> 0.022112165 | ... K22: =IS!K27/IS!K$23 -> 0.022483521 | L22: =AVERAGE(B22:K22) -> 0.027287593
A23: Total Indirect Operating Costs | B23: =IS!B29/IS!B$23 -> 0.23141645 | C23: =IS!C29/IS!C$23 -> 0.22874568 | D23: =IS!D29/IS!D$23 -> 0.22525362 | E23: =IS!E29/IS!E$23 -> 0.22874553 | F23: =IS!F29/IS!F$23 -> 0.23816285 | G23: =IS!G29/IS!G$23 -> 0.2379916 | H23: =IS!H29/IS!H$23 -> 0.22279582 | I23: =IS!I29/IS!I$23 -> 0.208443 | ... K23: =IS!K29/IS!K$23 -> 0.22315011 | L23: =AVERAGE(B23:K23) -> 0.22558759
A24: Operating Income | B24: =IS!B30/IS!B$23 -> 0.062450081 | C24: =IS!C30/IS!C$23 -> 0.066544691 | D24: =IS!D30/IS!D$23 -> 0.071501547 | E24: =IS!E30/IS!E$23 -> 0.059989705 | F24: =IS!F30/IS!F$23 -> 0.054541112 | G24: =IS!G30/IS!G$23 -> 0.059632323 | H24: =IS!H30/IS!H$23 -> 0.069890232 | I24: =IS!I30/IS!I$23 -> 0.084392246 | ... K24: =IS!K30/IS!K$23 -> 0.053131866 | L24: =AVERAGE(B24:K24) -> 0.061733773
A25: Interest Income | B25: =IS!B31/IS!B$23 -> -0.012145749 | C25: =IS!C31/IS!C$23 -> -0.0082266043 | D25: =IS!D31/IS!D$23 -> -0.014447083 | E25: =IS!E31/IS!E$23 -> -0.0092655713 | F25: =IS!F31/IS!F$23 -> -0.0061176283 | G25: =IS!G31/IS!G$23 -> -0.0061066161 | H25: =IS!H31/IS!H$23 -> -0.010442385 | I25: =IS!I31/IS!I$23 -> -0.0039715108 | ... K25: =IS!K31/IS!K$23 -> -0.0046735933 | L25: =AVERAGE(B25:K25) -> -0.0079777239
A26: Other Non-Operating Income | C26: =IS!C32/IS!C$23 -> 0.0084027919
A27: Total Non-Operating Income | B27: =IS!B33/IS!B$23 -> 0 | C27: =IS!C33/IS!C$23 -> 0 | D27: =IS!D33/IS!D$23 -> 0 | E27: =IS!E33/IS!E$23 -> 0 | F27: =IS!F33/IS!F$23 -> 0.00035829927 | G27: =IS!G33/IS!G$23 -> 0.00011521917 | H27: =IS!H33/IS!H$23 -> -0.00017101143 | I27: =IS!I33/IS!I$23 -> 0.0036036036 | ... K27: =IS!K33/IS!K$23 -> 0.0008565151 | L27: =AVERAGE(B27:K27) -> 0.00052025084
A28: Earnings Before Tax | B28: =IS!B34/IS!B$23 -> -0.012145749 | C28: =IS!C34/IS!C$23 -> 0.00017618757 | D28: =IS!D34/IS!D$23 -> -0.014447083 | E28: =IS!E34/IS!E$23 -> -0.0092655713 | F28: =IS!F34/IS!F$23 -> -0.0057593291 | G28: =IS!G34/IS!G$23 -> -0.005991397 | H28: =IS!H34/IS!H$23 -> -0.010613397 | I28: =IS!I34/IS!I$23 -> -0.00036790717 | ... K28: =IS!K34/IS!K$23 -> -0.0038170782 | L28: =AVERAGE(B28:K28) -> -0.0066171939
A29: Taxation | B29: =IS!B35/IS!B$23 -> 0.050304332 | C29: =IS!C35/IS!C$23 -> 0.066720878 | D29: =IS!D35/IS!D$23 -> 0.057054464 | E29: =IS!E35/IS!E$23 -> 0.050724134 | F29: =IS!F35/IS!F$23 -> 0.048781782 | G29: =IS!G35/IS!G$23 -> 0.053640926 | H29: =IS!H35/IS!H$23 -> 0.059276835 | I29: =IS!I35/IS!I$23 -> 0.084024338 | ... K29: =IS!K35/IS!K$23 -> 0.049314788 | L29: =AVERAGE(B29:K29) -> 0.055116579
A30: Discontinued Operations | B30: =IS!B36/IS!B$23 -> 0.016579911 | C30: =IS!C36/IS!C$23 -> 0.02171173 | D30: =IS!D36/IS!D$23 -> 0.018648824 | E30: =IS!E36/IS!E$23 -> 0.0099890093 | F30: =IS!F36/IS!F$23 -> 0.0098996762 | G30: =IS!G36/IS!G$23 -> 0.011790762 | H30: =IS!H36/IS!H$23 -> 0.012590716 | I30: =IS!I36/IS!I$23 -> 0.018499127 | ... K30: =IS!K36/IS!K$23 -> 0.010790228 | L30: =AVERAGE(B30:K30) -> 0.013634676
A31: Net Income | B31: =IS!B37/IS!B$23 -> -0.056253271 | C31: =IS!C37/IS!C$23 -> 0.00056922139 | D31: =IS!D37/IS!D$23 -> 0.00097848766 | E31: =IS!E37/IS!E$23 -> 8.3473615e-05 | F31: =IS!F37/IS!F$23 -> 9.2892404e-05 | G31: =IS!G37/IS!G$23 -> 0.00015362556 | H31: =IS!H40/IS!H$23 -> 0.046686119 | I31: =IS!I40/IS!I$23 -> 0.065525211 | J31: =IS!J40/IS!J$23 -> 0.02547654 | K31: =IS!K40/IS!K$23 -> 0.03852456 | L31: =AVERAGE(B31:K31) -> 0.012183686
A32: Net Income to Common | B32: =IS!B38/IS!B$23 -> 0 | C32: =IS!C38/IS!C$23 -> 0 | D32: =IS!D38/IS!D$23 -> 0 | E32: =IS!E38/IS!E$23 -> 0 | F32: =IS!F38/IS!F$23 -> 0 | G32: =IS!G38/IS!G$23 -> 0 | H32: =IS!H38/IS!H$23 -> 0 | I32: =IS!I38/IS!I$23 -> 0 | ... K32: =IS!K38/IS!K$23 -> 0
A35: Average Shares Basic | B35: 634.7 | C35: 627.7 | D35: 577.6 | E35: 546.8 | F35: 528.6 | G35: 510.9 | H35: 500.6 | I35: 488.1 | J35: 462.1 | K35: 461.5
A36: EPS Net Basic | B36: -2.58 | C36: 5.35 | D36: 4.74 | E36: 5.36 | F36: 5.55 | G36: 6.42 | H36: 8.72 | I36: 14.23 | J36: 6.02 | K36: 8.96
A37: EPS Continuing Basic | B37: 3.86 | C37: 5.29 | D37: 4.62 | E37: 5.35 | F37: 5.54 | G37: 6.39 | H37: 8.72 | I37: 14.23 | J37: 6.02 | K37: 8.96
A38: Average Shares Diluted | B38: 640.1 | C38: 632.9 | D38: 582.5 | E38: 550.3 | F38: 533.2 | G38: 515.6 | H38: 505.4 | I38: 492.7 | J38: 464.7 | K38: 462.8
A39: EPS Net Diluted | B39: -2.56 | C39: 5.31 | D39: 4.7 | E39: 5.33 | F39: 5.51 | G39: 6.36 | H39: 8.64 | I39: 14.1 | J39: 5.98 | K39: 8.94
A40: EPS Continuing Diluted | B40: 3.83 | C40: 5.25 | D40: 4.58 | E40: 5.32 | F40: 5.5 | G40: 6.34 | H40: 8.64 | I40: 14.1 | J40: 5.98 | K40: 8.94
A41: Shares Outstanding | B41: 640.214 | C41: 602.227 | D41: 556.156 | E41: 541.682 | F41: 517.762 | G41: 504.199 | H41: 500.877 | I41: 471.274 | J41: 460.347 | K41: 461.675

Sheet BS
A4: Powered by Clearbit
A5: Target Corp (NYS: TGT)
A7: Exchange rate used is that of the Year End reported date
A8: S&P | B8: 2104.5 | C8: 1932.23 | D8: 2363.64 | E8: 2713.83 | F8: 2784.49 | G8: 2954.22 | H8: 3811.15 | I8: 4373.94 | J8: 3970.15 | K8: 5096.27
C9: =C8/B8-1 -> -0.081857923 | D9: =D8/C8-1 -> 0.22327052 | E9: =E8/D8-1 -> 0.14815708 | F9: =F8/E8-1 -> 0.026037003 | G9: =G8/F8-1 -> 0.060955507 | H9: =H8/G8-1 -> 0.2900698 | I9: =I8/H8-1 -> 0.14766934 | J9: =J8/I8-1 -> -0.092317224 | K9: =K8/J8-1 -> 0.28364671
A10: Standardized Annual Balance Sheet
A11: Report Date | B11: 01/31/2015 | C11: 01/30/2016 | D11: 01/28/2017 | E11: 02/03/2018 | F11: 02/02/2019 | G11: 02/01/2020 | H11: 01/30/2021 | I11: 01/29/2022 | J11: 01/28/2023 | K11: 02/03/2024 | M11: 2015 | N11: =M11+1 -> 2016 | O11: =N11+1 -> 2017 | P11: =O11+1 -> 2018 | Q11: =P11+1 -> 2019 | R11: =Q11+1 -> 2020 | S11: =R11+1 -> 2021 | T11: =S11+1 -> 2022 | U11: =T11+1 -> 2023 | V11: =U11+1 -> 2024
A12: Currency | B12: USD | C12: USD | D12: USD | E12: USD | F12: USD | G12: USD | H12: USD | I12: USD | J12: USD | K12: USD | W12: Average
A13: Audit Status | B13: Not Qualified | C13: Not Qualified | D13: Not Qualified | E13: Not Qualified | F13: Not Qualified | G13: Not Qualified | H13: Not Qualified | I13: Not Qualified | J13: Not Qualified | K13: Not Qualified
A14: Consolidated | B14: Yes | C14: Yes | D14: Yes | E14: Yes | F14: Yes | G14: Yes | H14: Yes | I14: Yes | J14: Yes | K14: Yes
A15: Scale | B15: Millions | C15: Millions | D15: Millions | E15: Millions | F15: Millions | G15: Millions | H15: Millions | I15: Millions | J15: Millions | K15: Millions
A16: Cash & Equivalents | B16: 2210 | C16: 4046 | D16: 2512 | E16: 2643 | F16: 1556 | G16: 2577 | H16: 8511 | I16: 5911 | J16: 2229 | K16: 3805
A17: Cash & Equivs & ST Investments | B17: 2210 | C17: 4046 | D17: 2512 | E17: 2643 | F17: 1556 | G17: 2577 | H17: 8511 | I17: 5911 | J17: 2229 | K17: 3805 | M17: =B17/IS!B23 -> 0.030433226 | N17: =C17/IS!C23 -> 0.054834994 | O17: =D17/IS!D23 -> 0.036146485 | P17: =E17/IS!E23 -> 0.036770128 | Q17: =F17/IS!F23 -> 0.020648654 | R17: =G17/IS!G23 -> 0.03299109 | S17: =H17/IS!H23 -> 0.09096739 | T17: =I17/IS!I23 -> 0.055761521 | ... V17: =K17/IS!K23 -> 0.035424347 | W17: =AVERAGE(M17:V17) -> 0.041440489
A18: Receivables (ST) | B18: 1122 | C18: 779 | D18: 749 | E18: 929 | F18: 1100 | G18: 962 | H18: 1135 | I18: 1353 | J18: 1695 | K18: 1404 | M18: =B18/IS!$B$23 -> 0.015450715 | N18: =C18/IS!$B$23 -> 0.010727368 | O18: =D18/IS!$B$23 -> 0.010314247 | P18: =E18/IS!$B$23 -> 0.012792971 | Q18: =F18/IS!$B$23 -> 0.01514776 | R18: =G18/IS!$B$23 -> 0.013247404 | S18: =H18/IS!$B$23 -> 0.015629734 | T18: =I18/IS!$B$23 -> 0.018631744 | ... V18: =K18/IS!$B$23 -> 0.019334049 | W18: =AVERAGE(M18:V18) -> 0.015461731
A19: Inventories | B19: 8790 | C19: 8601 | D19: 8309 | E19: 8657 | F19: 9497 | G19: 8992 | H19: 10653 | I19: 13902 | J19: 13499 | K19: 11886 | M19: =B19/IS!$B$23 -> 0.12104437 | N19: =C19/IS!$B$23 -> 0.11844171 | O19: =D19/IS!$B$23 -> 0.11442067 | P19: =E19/IS!$B$23 -> 0.11921287 | Q19: =F19/IS!$B$23 -> 0.13078025 | R19: =G19/IS!$B$23 -> 0.12382605 | S19: =H19/IS!$B$23 -> 0.14669917 | T19: =I19/IS!$B$23 -> 0.19144014 | ... V19: =K19/IS!$B$23 -> 0.16367843 | W19: =AVERAGE(M19:V19) -> 0.14154342
A20: Current Tax Assets | B20: 188 | C20: - | D20: - | E20: - | F20: - | G20: - | H20: - | I20: - | J20: - | K20: -
A21: Prepayments (ST) | B21: 231 | C21: 214 | D21: 207 | E21: 181 | F21: 157 | G21: 154 | H21: 171 | I21: 170 | J21: 188 | K21: 201
A22: Discontinued Ops (ST Asset) | B22: 1333 | C22: 322 | D22: 69 | E22: - | F22: - | G22: - | H22: - | I22: - | J22: - | K22: -
A23: Other Current Assets | B23: 213 | C23: 168 | D23: 144 | E23: 154 | F23: 209 | G23: 217 | H23: 286 | I23: 237 | J23: 235 | K23: 202
A24: Total Current Assets | B24: 14087 | C24: 14130 | D24: 11990 | E24: 12564 | F24: 12519 | G24: 12902 | H24: 20756 | I24: 21573 | J24: 17846 | K24: 17498 | M24: =B24/IS!$B$23 -> 0.19398772 | N24: =C24/IS!$B$23 -> 0.19457986 | O24: =D24/IS!$B$23 -> 0.16511058 | P24: =E24/IS!$B$23 -> 0.17301495 | Q24: =F24/IS!$B$23 -> 0.17239527 | R24: =G24/IS!$B$23 -> 0.17766945 | S24: =H24/IS!$B$23 -> 0.28582445 | T24: =I24/IS!$B$23 -> 0.29707511 | ... V24: =K24/IS!$B$23 -> 0.24095954 | W24: =AVERAGE(M24:V24) -> 0.21463687
A25: Gross Property Plant & Equip | B25: 41064 | C25: 41463 | D25: 42071 | E25: 43199 | F25: 44220 | G25: 45947 | H25: 47157 | I25: 49318 | J25: 54143 | K25: 57509 | M25: =B25/IS!$B$23 -> 0.56547963 | N25: =C25/IS!$B$23 -> 0.57097414 | O25: =D25/IS!$B$23 -> 0.57934672 | P25: =E25/IS!$B$23 -> 0.59488006 | Q25: =F25/IS!$B$23 -> 0.60893993 | R25: =G25/IS!$B$23 -> 0.63272191 | S25: =H25/IS!$B$23 -> 0.64938445 | T25: =I25/IS!$B$23 -> 0.67914291 | ... V25: =K25/IS!$B$23 -> 0.79193864 | W25: =AVERAGE(M25:V25) -> 0.64183949
A26: Accumulated Depreciation | B26: 15106 | C26: 16246 | D26: 17413 | E26: 18181 | F26: 18687 | G26: 19664 | H26: 20278 | I26: 21137 | J26: 22631 | K26: 24413 | M26: =B26/B25 -> 0.3678648 | N26: =C26/C25 -> 0.39181921 | O26: =D26/D25 -> 0.41389556 | P26: =E26/E25 -> 0.42086622 | Q26: =F26/F25 -> 0.42259159 | R26: =G26/G25 -> 0.42797136 | S26: =H26/H25 -> 0.43001039 | T26: =I26/I25 -> 0.42858591 | ... V26: =K26/K25 -> 0.42450747 | W26: =AVERAGE(M26:V26) -> 0.41460982
A27: Net Property Plant & Equip | B27: 25958 | C27: 25217 | D27: 24658 | E27: 25018 | F27: 25533 | G27: 26283 | H27: 26879 | I27: 28181 | J27: 31512 | K27: 33096 | M27: =B27/IS!$B$23 -> 0.35745958 | N27: =C27/IS!$B$23 -> 0.3472555 | O27: =D27/IS!$B$23 -> 0.33955769 | P27: =E27/IS!$B$23 -> 0.34451513 | Q27: =F27/IS!$B$23 -> 0.35160704 | R27: =G27/IS!$B$23 -> 0.36193506 | S27: =H27/IS!$B$23 -> 0.37014239 | T27: =I27/IS!$B$23 -> 0.38807183 | ... V27: =K27/IS!$B$23 -> 0.45575477 | W27: =AVERAGE(M27:V27) -> 0.3750241
A28: Intangible Assets | B28: 302 | C28: 277 | D28: 259 | E28: 782 | F28: 699 | G28: 686 | H28: 668 | I28: 656 | J28: 645 | K28: 639
A29: Prepayments (LT) | B29: - | C29: 66 | D29: 43 | E29: 46 | F29: 11 | G29: - | H29: - | I29: - | J29: - | K29: 57
A30: Discontinued Ops (LT Asset) | B30: 442 | C30: 75 | D30: 12 | E30: - | F30: - | G30: - | H30: - | I30: - | J30: - | K30: -
A31: Other Assets | B31: 615 | C31: 497 | D31: 469 | E31: 589 | F31: 2528 | G31: 2908 | H31: 2945 | I31: 3401 | J31: 3332 | K31: 4066 | M31: =B31/IS!$B$23 -> 0.0084689746 | N31: =C31/IS!$B$23 -> 0.0068440332 | O31: =D31/IS!$B$23 -> 0.0064584538 | P31: =E31/IS!$B$23 -> 0.0081109367 | Q31: =F31/IS!$B$23 -> 0.034812305 | R31: =G31/IS!$B$23 -> 0.040045168 | S31: =H31/IS!$B$23 -> 0.040554683 | T31: =I31/IS!$B$23 -> 0.046834118 | ... V31: =K31/IS!$B$23 -> 0.055991627 | W31: =AVERAGE(M31:V31) -> 0.029400424
A32: Total Assets | B32: 41404 | C32: 40262 | D32: 37431 | E32: 38999 | F32: 41290 | G32: 42779 | H32: 51248 | I32: 53811 | J32: 53335 | K32: 55356 | M32: =B32/IS!$B$23 -> 0.57016167 | N32: =C32/IS!$B$23 -> 0.55443554 | O32: =D32/IS!$B$23 -> 0.51545071 | P32: =E32/IS!$B$23 -> 0.53704316 | Q32: =F32/IS!$B$23 -> 0.56859181 | R32: =G32/IS!$B$23 -> 0.58909637 | S32: =H32/IS!$B$23 -> 0.70572034 | T32: =I32/IS!$B$23 -> 0.74101462 | ... V32: =K32/IS!$B$23 -> 0.76229034 | W32: =AVERAGE(M32:V32) -> 0.62782643
A33: Accounts Payable & Accrued Exps | B33: 10755 | C33: 10414 | D33: 10145 | E33: 12118 | F33: 12966 | G33: 13171 | H33: 17263 | I33: 20012 | J33: 17582 | K33: 16697 | M33: =B33/IS!$B$23 -> 0.14810378 | N33: =C33/IS!$B$23 -> 0.14340797 | O33: =D33/IS!$B$23 -> 0.13970365 | P33: =E33/IS!$B$23 -> 0.16687323 | Q33: =F33/IS!$B$23 -> 0.17855077 | R33: =G33/IS!$B$23 -> 0.18137376 | S33: =H33/IS!$B$23 -> 0.23772343 | T33: =I33/IS!$B$23 -> 0.27557906 | ... V33: =K33/IS!$B$23 -> 0.22992922 | W33: =AVERAGE(M33:V33) -> 0.19433612
A34: Accounts Payable | B34: 7759 | C34: 7418 | D34: 7252 | E34: 8677 | F34: 9761 | G34: 9920 | H34: 12859 | I34: 15478 | J34: 13487 | K34: 12098 | M34: =B34/IS!$B$23 -> 0.10684679 | N34: =C34/IS!$B$23 -> 0.10215098 | O34: =D34/IS!$B$23 -> 0.099865047 | P34: =E34/IS!$B$23 -> 0.11948828 | Q34: =F34/IS!$B$23 -> 0.13441571 | R34: =G34/IS!$B$23 -> 0.13660525 | S34: =H34/IS!$B$23 -> 0.17707731 | T34: =I34/IS!$B$23 -> 0.21314275 | ... V34: =K34/IS!$B$23 -> 0.16659781 | W34: =AVERAGE(M34:V34) -> 0.14419152
A35: Accrued Expenses | B35: 2387 | C35: 2352 | D35: 2200 | E35: 2714 | F35: 2365 | G35: 2316 | H35: 3369 | I35: 3332 | J35: 2855 | K35: 4599 | M35: =B35/IS!$B$23 -> 0.032870638 | N35: =C35/IS!$B$23 -> 0.032388664 | O35: =D35/IS!$B$23 -> 0.030295519 | P35: =E35/IS!$B$23 -> 0.037373654 | Q35: =F35/IS!$B$23 -> 0.032567683 | R35: =G35/IS!$B$23 -> 0.031892919 | S35: =H35/IS!$B$23 -> 0.046393456 | T35: =I35/IS!$B$23 -> 0.045883941 | ... V35: =K35/IS!$B$23 -> 0.063331405 | W35: =AVERAGE(M35:V35) -> 0.03923132
A36: Current Debt | B36: 91 | C36: 815 | D36: 1718 | E36: 270 | F36: 1052 | G36: 161 | H36: 1144 | I36: 171 | J36: 130 | K36: 997
A37: Current Lease Obligations | B37: - | C37: - | D37: - | E37: - | F37: - | G37: - | H37: - | I37: - | J37: - | K37: 119
A38: Discontinued Ops (ST Liab) | B38: 103 | C38: 153 | D38: 1 | E38: - | F38: - | G38: - | H38: - | I38: - | J38: - | K38: -
A39: Other Current Liabilities | B39: 787 | C39: 1240 | D39: 844 | E39: 813 | F39: 996 | G39: 1155 | H39: 1718 | I39: 1564 | J39: 1788 | K39: 1491 | M39: =B39/IS!$B$23 -> 0.010837533 | N39: =C39/IS!$B$23 -> 0.017075656 | O39: =D39/IS!$B$23 -> 0.011622463 | P39: =E39/IS!$B$23 -> 0.011195571 | Q39: =F39/IS!$B$23 -> 0.013715608 | R39: =G39/IS!$B$23 -> 0.015905147 | S39: =H39/IS!$B$23 -> 0.023658046 | T39: =I39/IS!$B$23 -> 0.02153736 | ... V39: =K39/IS!$B$23 -> 0.020532099 | W39: =AVERAGE(M39:V39) -> 0.017070148
A40: Total Current Liabilities | B40: 11736 | C40: 12622 | D40: 12708 | E40: 13201 | F40: 15014 | G40: 14487 | H40: 20125 | I40: 21747 | J40: 19500 | K40: 19304 | M40: =B40/IS!$B$23 -> 0.16161282 | N40: =C40/IS!$B$23 -> 0.17381366 | O40: =D40/IS!$B$23 -> 0.17499793 | P40: =E40/IS!$B$23 -> 0.18178688 | Q40: =F40/IS!$B$23 -> 0.20675315 | R40: =G40/IS!$B$23 -> 0.19949599 | S40: =H40/IS!$B$23 -> 0.27713515 | T40: =I40/IS!$B$23 -> 0.29947121 | ... V40: =K40/IS!$B$23 -> 0.26582941 | W40: =AVERAGE(M40:V40) -> 0.22094247
A41: LT Debt & Leases | B41: 12705 | C41: 11945 | D41: 11031 | E41: 11317 | F41: 10223 | G41: 11338 | H41: 11536 | I41: 13549 | J41: 16009 | K41: 14922 | M41: =B41/IS!$B$23 -> 0.17495662 | N41: =C41/IS!$B$23 -> 0.1644909 | O41: =D41/IS!$B$23 -> 0.15190449 | P41: =E41/IS!$B$23 -> 0.1558429 | Q41: =F41/IS!$B$23 -> 0.14077777 | R41: =G41/IS!$B$23 -> 0.15613209 | S41: =H41/IS!$B$23 -> 0.15885869 | T41: =I41/IS!$B$23 -> 0.18657909 | ... V41: =K41/IS!$B$23 -> 0.20548624 | W41: =AVERAGE(M41:V41) -> 0.17154838
A42: Pensions & OPEB | B42: 151 | C42: 54 | D42: 46 | E42: 41 | F42: 40 | G42: 107 | H42: 57 | I42: 45 | J42: 37 | K42: 33
A43: Discontinued Ops (LT Liab) | B43: 193 | C43: 18 | D43: 18 | E43: - | F43: - | G43: - | H43: - | I43: - | J43: - | K43: -
A44: Deferred LT Liabilities | B44: 1321 | C44: 1483 | D44: 1491 | E44: 1313 | F44: 1542 | G44: 1661 | H44: 1499 | I44: 2045 | J44: 2645 | K44: 2899 | M44: =B44/IS!$B$23 -> 0.018191082 | N44: =C44/IS!$B$23 -> 0.020421934 | O44: =D44/IS!$B$23 -> 0.020532099 | P44: =E44/IS!$B$23 -> 0.018080917 | Q44: =F44/IS!$B$23 -> 0.021234405 | R44: =G44/IS!$B$23 -> 0.022873117 | S44: =H44/IS!$B$23 -> 0.020642265 | T44: =I44/IS!$B$23 -> 0.028161062 | ... V44: =K44/IS!$B$23 -> 0.039921232 | W44: =AVERAGE(M44:V44) -> 0.024648159
...

Sheet Financial Ratios
A4: Powered by Clearbit
A5: Target Corp (NYS: TGT)
A7: Exchange rate used is that of the Year End reported date
A10: Standardized Annual Balance Sheet
A11: Report Date | B11: 2015 | C11: 2016 | D11: 2017 | E11: 2018 | F11: 2019 | G11: 2020 | H11: 2021 | I11: 2022 | J11: 2023 | K11: 2024
A13: Short Term Liabilities
A14: Current ratio | B14: =BS!B24/BS!B40 -> 1.2003238 | C14: =BS!C24/BS!C40 -> 1.1194739 | D14: =BS!D24/BS!D40 -> 0.94350016 | E14: =BS!E24/BS!E40 -> 0.95174608 | F14: =BS!F24/BS!F40 -> 0.83382177 | G14: =BS!G24/BS!G40 -> 0.89059156 | H14: =BS!H24/BS!H40 -> 1.031354 | I14: =BS!I24/BS!I40 -> 0.9919989 | ... K14: =BS!K24/BS!K40 -> 0.90644426
A15: Quick ratio | B15: =(BS!B17+BS!B18)/BS!B40 -> 0.28391275 | C15: =(BS!C17+BS!C18)/BS!C40 -> 0.38226905 | D15: =(BS!D17+BS!D18)/BS!D40 -> 0.25661001 | E15: =(BS!E17+BS!E18)/BS!E40 -> 0.27058556 | F15: =(BS!F17+BS!F18)/BS!F40 -> 0.17690156 | G15: =(BS!G17+BS!G18)/BS!G40 -> 0.24428798 | H15: =(BS!H17+BS!H18)/BS!H40 -> 0.47930435 | I15: =(BS!I17+BS!I18)/BS!I40 -> 0.33402308 | ... K15: =(BS!K17+BS!K18)/BS!K40 -> 0.26984045
A16: Cash Ratio | B16: =BS!B16/BS!B40 -> 0.18830948 | C16: =BS!C16/BS!C40 -> 0.32055142 | D16: =BS!D16/BS!D40 -> 0.19767076 | E16: =BS!E16/BS!E40 -> 0.20021211 | F16: =BS!F16/BS!F40 -> 0.10363661 | G16: =BS!G16/BS!G40 -> 0.17788362 | H16: =BS!H16/BS!H40 -> 0.42290683 | I16: =BS!I16/BS!I40 -> 0.27180761 | ... K16: =BS!K16/BS!K40 -> 0.19710941
A18: Efficiency
A19: Inventory Turnover | C19: =IS!C24/((BS!B19+BS!C19)/2) -> 5.9797596 | D19: =IS!D24/((BS!C19+BS!D19)/2) -> 5.7802484 | E19: =IS!E24/((BS!D19+BS!E19)/2) -> 6.0267594 | F19: =IS!F24/((BS!E19+BS!F19)/2) -> 5.871874 | G19: =IS!G24/((BS!F19+BS!G19)/2) -> 5.934772 | H19: =IS!H24/((BS!G19+BS!H19)/2) -> 6.7372868 | I19: =IS!I24/((BS!H19+BS!I19)/2) -> 6.1057218 | J19: =IS!J24/((BS!I19+BS!J19)/2) -> 6.0018977 | K19: =IS!K24/((BS!J19+BS!K19)/2) -> 6.1245617
A20: fixed asset turnover | C20: =IS!C21/((BS!B27+BS!C27)/2) -> 2.8836346 | D20: =IS!D21/((BS!C27+BS!D27)/2) -> 2.7867669 | E20: =IS!E21/((BS!D27+BS!E27)/2) -> 2.8939126 | F20: =IS!F21/((BS!E27+BS!F27)/2) -> 2.9448676 | G20: =IS!G21/((BS!F27+BS!G27)/2) -> 2.9770727 | H20: =IS!H21/((BS!G27+BS!H27)/2) -> 3.4761672 | I20: =IS!I21/((BS!H27+BS!I27)/2) -> 3.799891 | J20: =IS!J21/((BS!I27+BS!J27)/2) -> 3.6047108 | K20: =IS!K21/((BS!J27+BS!K27)/2) -> 3.2752291
A21: Days in Inventory | C21: =365/C19 -> 61.039243 | D21: =365/D19 -> 63.146075 | E21: =365/E19 -> 60.563227 | F21: =365/F19 -> 62.160735 | G21: =365/G19 -> 61.501941 | H21: =365/H19 -> 54.176111 | I21: =365/I19 -> 59.779991 | J21: =365/J19 -> 60.814098 | K21: =365/K19 -> 59.596101
A23: Long term Solvency
A24: debt ratio | B24: =(BS!B36+BS!B41)/BS!B32 -> 0.30905227 | C24: =(BS!C36+BS!C41)/BS!C32 -> 0.31692415 | D24: =(BS!D36+BS!D41)/BS!D32 -> 0.34060004 | E24: =(BS!E36+BS!E41)/BS!E32 -> 0.29711018 | F24: =(BS!F36+BS!F41)/BS!F32 -> 0.27306854 | G24: =(BS!G36+BS!G41)/BS!G32 -> 0.26880011 | H24: =(BS!H36+BS!H41)/BS!H32 -> 0.24742429 | I24: =(BS!I36+BS!I41)/BS!I32 -> 0.25496646 | ... K24: =(BS!K36+BS!K41)/BS!K32 -> 0.28757497
A25: debt-equity ratio | B25: =(BS!B36+BS!B41)/BS!B54 -> 0.9141959 | C25: =(BS!C36+BS!C41)/BS!C54 -> 0.98479586 | D25: =(BS!D36+BS!D41)/BS!D54 -> 1.1639733 | E25: =(BS!E36+BS!E41)/BS!E54 -> 0.98958066 | F25: =(BS!F36+BS!F41)/BS!F54 -> 0.99805258 | G25: =(BS!G36+BS!G41)/BS!G54 -> 0.97177385 | H25: =(BS!H36+BS!H41)/BS!H54 -> 0.87811634 | I25: =(BS!I36+BS!I41)/BS!I54 -> 1.0696188 | ... K25: =(BS!K36+BS!K41)/BS!K54 -> 1.1851549
A26: interest coverage | B26: =IS!B35/(-IS!B31) -> 4.1417234 | C26: =IS!C35/(-IS!C31) -> 8.1103789 | D26: =IS!D35/(-IS!D31) -> 3.9492032 | E26: =IS!E35/(-IS!E31) -> 5.4744745 | F26: =IS!F35/(-IS!F31) -> 7.9739696 | G26: =IS!G35/(-IS!G31) -> 8.7840671 | H26: =IS!H35/(-IS!H31) -> 5.6765609 | I26: =IS!I35/(-IS!I31) -> 21.15677 | ... K26: =IS!K35/(-IS!K31) -> 10.551793
A28: Profitability Ratios
A29: gross profit margin | B29: =(IS!B23-IS!B24)/IS!B23 -> 0.29386653 | C29: =(IS!C23-IS!C24)/IS!C23 -> 0.29529037 | D29: =(IS!D23-IS!D24)/IS!D23 -> 0.29675516 | E29: =(IS!E23-IS!E24)/IS!E23 -> 0.28873524 | F29: =(IS!F23-IS!F24)/IS!F23 -> 0.29270397 | G29: =(IS!G23-IS!G24)/IS!G23 -> 0.29762392 | H29: =(IS!H23-IS!H24)/IS!H23 -> 0.29268606 | I29: =(IS!I23-IS!I24)/IS!I23 -> 0.29283524 | ... K29: =(IS!K23-IS!K24)/IS!K23 -> 0.27628198
A30: operating profit margin | B30: =IS!B30/IS!B23 -> 0.062450081 | C30: =IS!C30/IS!C23 -> 0.066544691 | D30: =IS!D30/IS!D23 -> 0.071501547 | E30: =IS!E30/IS!E23 -> 0.059989705 | F30: =IS!F30/IS!F23 -> 0.054541112 | G30: =IS!G30/IS!G23 -> 0.059632323 | H30: =IS!H30/IS!H23 -> 0.069890232 | I30: =IS!I30/IS!I23 -> 0.084392246 | ... K30: =IS!K30/IS!K23 -> 0.053131866
A31: net profit margin | B31: =IS!B40/IS!B23 -> -0.02252885 | C31: =IS!C40/IS!C23 -> 0.04557837 | D31: =IS!D40/IS!D23 -> 0.039384128 | E31: =IS!E40/IS!E23 -> 0.040818598 | F31: =IS!F40/IS!F23 -> 0.038974999 | G31: =IS!G40/IS!G23 -> 0.042003789 | H31: =IS!H40/IS!H23 -> 0.046686119 | I31: =IS!I40/IS!I23 -> 0.065525211 | ... K31: =IS!K40/IS!K23 -> 0.03852456
A33: Management Efficiency
A34: return on assets | B34: =IS!B40/BS!B32 -> -0.039513091 | C34: =IS!C40/BS!C32 -> 0.083527892 | D34: =IS!D40/BS!D32 -> 0.07312121 | E34: =IS!E40/BS!E32 -> 0.075232698 | F34: =IS!F40/BS!F32 -> 0.071131024 | G34: =IS!G40/BS!G32 -> 0.07669651 | H34: =IS!H40/BS!H32 -> 0.085232594 | I34: =IS!I40/BS!I32 -> 0.12908141 | ... K34: =IS!K40/BS!K32 -> 0.074752511
A35: return on equity | B35: =IS!B40/BS!B54 -> -0.11688219 | C35: =IS!C40/BS!C54 -> 0.25955082 | D35: =IS!D40/BS!D54 -> 0.24988588 | E35: =IS!E40/BS!E54 -> 0.25057648 | F35: =IS!F40/BS!F54 -> 0.25998053 | G35: =IS!G40/BS!G54 -> 0.27727542 | H35: =IS!H40/BS!H54 -> 0.30249307 | I35: =IS!I40/BS!I54 -> 0.54151399 | ... K35: =IS!K40/BS!K54 -> 0.30807028
A37: Valuation
A38: Share price | B38: 73.19 | C38: 71.25 | D38: 63.98 | E38: 74.63 | F38: 73.1 | G38: 111.14 | H38: 182.18 | I38: 221.99 | J38: 172.11 | K38: 139.08
A39: price/earning ratio | B39: =B38/B40 -> -28.641359 | C39: =C38/C40 -> 12.759047 | D39: =D38/D40 -> 13.00068 | E39: =E38/E40 -> 13.778367 | F39: =F38/F40 -> 12.886756 | G39: =G38/G40 -> 17.079146 | H39: =H38/H40 -> 20.890516 | I39: =I38/I40 -> 15.061635 | ... K39: =K38/K40 -> 15.5171
A40: earnings per share | B40: =IS!B40/IS!B49 -> -2.5553955 | C40: =IS!C40/IS!C49 -> 5.584273 | D40: =IS!D40/IS!D49 -> 4.9212811 | E40: =IS!E40/IS!E49 -> 5.4164621 | F40: =IS!F40/IS!F49 -> 5.6724904 | G40: =IS!G40/IS!G49 -> 6.5073513 | H40: =IS!H40/IS!H49 -> 8.7207039 | I40: =IS!I40/IS!I49 -> 14.738772 | ... K40: =IS!K40/IS!K49 -> 8.9630151
A41: price/sales | B41: =B38*IS!B49/IS!B21 -> 0.64525686 | C41: =C38*IS!C49/IS!C21 -> 0.58153654 | D41: =D38*IS!D49/IS!D21 -> 0.51202045 | E41: =E38*IS!E49/IS!E21 -> 0.56241361 | F41: =F38*IS!F49/IS!F21 -> 0.50848954 | G41: =G38*IS!G49/IS!G21 -> 0.72652245 | H41: =H38*IS!H49/IS!H21 -> 0.98755164 | I41: =I38*IS!I49/IS!I21 -> 1.000068 | ... K41: =K38*IS!K49/IS!K21 -> 0.60688032
A42: price/EBITDA | B42: =B38*IS!B49/IS!B35 -> 12.827063 | C42: =C38*IS!C49/IS!C35 -> 8.7159605 | D42: =D38*IS!D49/IS!D35 -> 8.9742398 | E42: =E38*IS!E49/IS!E35 -> 11.087693 | F42: =F38*IS!F49/IS!F35 -> 10.296083 | G42: =G38*IS!G49/IS!G35 -> 13.373909 | H42: =H38*IS!H49/IS!H35 -> 16.453259 | I42: =I38*IS!I49/IS!I35 -> 11.745606 | ... K42: =K38*IS!K49/IS!K35 -> 12.12191

Sheet Sheet2
A5: Short Term Liabilities
A6: Current ratio
A7: Quick ratio
A8: Cash Ratio
A10: Efficiency
A11: Inventory Turnover
A12: fixed asset turnover
A13: Days in Inventory
A15: Long term Solvency
A16: debt ratio
A17: debt-equity ratio
A18: interest coverage
... A34: price/EBITDA

Sheet Sheet1
A10: Liquidity ratios
A11: current ratio | C11: 1.2203719 | D11: 1.0458888 | E11: 0.97707865 | F11: 0.98982566 | G11: 1.0182174 | H11: 1.0106726 | I11: 1.1318628 | J11: 1.0021738 | K11: 1.0218139 | L11: 1.0683679
A12: Quick asset ratio | C12: 0.58721898 | D12: 0.4620919 | E12: 0.38401284 | F12: 0.41217491 | G12: 0.44805781 | H12: 0.47247924 | I12: 0.59793109 | J12: 0.47478007 | K12: 0.41533846 | L12: 0.52166275
A13: cash ratio | C13: 0.39814044 | D13: 0.29026602 | E13: 0.21695024 | F13: 0.25984567 | G13: 0.30387434 | H13: 0.36080389 | I13: 0.49416358 | J13: 0.3823919 | K13: 0.31886368 | L13: 0.4079445
A15: Asset Management Ratios
A16: average collection period | C16: 3.7199929 | D16: 3.8447835 | E16: 3.8492575 | F16: 4.0509979 | G16: 4.3028833 | H16: 3.6690504 | I16: 3.3925798 | J16: 3.3588443 | K16: 3.6041004 | L16: 3.4422593
A17: inventory turnover | C17: 11.643567 | D17: 11.34542 | E17: 11.472962 | F17: 11.377059 | G17: 11.155072 | H17: 11.661781 | I17: 11.839487 | J17: 12.007316 | K17: 11.134305 | L17: 12.767161
A18: cash conversion cycle
A21: Leverage Ratios
A23: debt ratio | C23: #VALUE! | D23: 0.18382177 | E23: 0.15562525 | F23: 0.18320632 | G23: 0.16108254 | H23: 0.15092511 | I23: 0.1378249 | J23: 0.12706688 | K23: 0.10270237 | L23: #VALUE!
A24: debt equity ratio | C24: #VALUE! | D24: 0.56690953 | E24: 0.4185047 | F24: 0.60104703 | G24: 0.50194612 | H24: 0.43968172 | I24: 0.40935579 | J24: 0.41658369 | K24: 0.3191747 | L24: #VALUE!
A27: Profitability Ratios
A28: gross profit | C28: 0.12590554 | D28: 0.13024208 | E28: 0.13323899 | F28: 0.13286572 | G28: 0.13013505 | H28: 0.12977479 | I28: 0.13085793 | J28: 0.12884769
A29: operating profit margin | C29: 0.028586648 | D29: 0.031187876 | E29: 0.03093018 | F29: 0.031862042 | G29: 0.031643781 | H29: 0.031021002 | I29: 0.032591553 | J29: 0.034236892
A30: net profit margin | C30: 0.018270597 | D30: 0.020456286 | E30: 0.019794641 | F30: 0.020763418 | G30: 0.02213652 | H30: 0.023961546 | I30: 0.023998417 | J30: 0.025555176
A31: return on assets | C31: 0.062318314 | D31: 0.071082536 | E31: 0.070862105 | F31: 0.073706221 | G31: 0.076757286 | H31: 0.080594714 | I31: 0.072035424 | J31: 0.084480664
A32: return on equity | C32: 0.16444267 | D32: 0.21921977 | E32: 0.19056114 | F32: 0.24180883 | G32: 0.23918187 | H32: 0.23479209 | I32: 0.21395349 | J32: 0.27696648
