Workbook

Sheet BALANCE SHEET 
A4: Powered by Clearbit
A5: NVIDIA Corp (NMS: NVDA)
A6: Standardized Annual Balance Sheet | B6: 2015 | C6: 2016 | D6: 2017 | E6: 2018 | F6: 2019 | G6: 2020 | H6: 2021 | I6: 2022 | J6: 2023 | K6: 2024
A7: Report Date | B7: 01/25/2015 | C7: 01/31/2016 | D7: 01/29/2017 | E7: 01/28/2018 | F7: 01/27/2019 | G7: 01/26/2020 | H7: 01/31/2021 | I7: 01/30/2022 | J7: 01/29/2023 | K7: 01/28/2024
A8: Currency | B8: USD | C8: USD | D8: USD | E8: USD | F8: USD | G8: USD | H8: USD | I8: USD | J8: USD | K8: USD
A9: Consolidated | B9: Yes | C9: Yes | D9: Yes | E9: Yes | F9: Yes | G9: Yes | H9: Yes | I9: Yes | J9: Yes | K9: Yes
A10: Scale | B10: Thousands | C10: Thousands | D10: Thousands | E10: Thousands | F10: Thousands | G10: Thousands | H10: Thousands | I10: Thousands | J10: Thousands | K10: Thousands
A11: Cash & Equivalents | B11: 496654 | C11: 596000 | D11: 1766000 | E11: 4002000 | F11: 782000 | G11: 10896000 | H11: 847000 | I11: 1990000 | J11: 3389000 | K11: 7280000
A12: Short Term Investments | B12: 4126685 | C12: 4441000 | D12: 5032000 | E12: 3106000 | F12: 6640000 | G12: 1000 | H12: 10714000 | I12: 19218000 | J12: 9907000 | K12: 18704000
A13: Cash & Equivs & ST Investments | B13: 4623339 | C13: 5037000 | D13: 6798000 | E13: 7108000 | F13: 7422000 | G13: 10897000 | H13: 11561000 | I13: 21208000 | J13: 13296000 | K13: 25984000
A14: Receivables (ST) | B14: 473637 | C14: 505000 | D14: 826000 | E14: 1265000 | F14: 1424000 | G14: 1657000 | H14: 2429000 | I14: 4650000 | J14: 3827000 | K14: 9999000
A15: Inventories | B15: 482893 | C15: 418000 | D15: 794000 | E15: 796000 | F15: 1575000 | G15: 979000 | H15: 1826000 | I15: 2605000 | J15: 5159000 | K15: 5282000
A16: Other Current Assets | B16: 70174 | C16: 93000 | D16: 118000 | E16: 86000 | F16: 136000 | G16: 157000 | H16: 239000 | I16: 366000 | J16: 791000 | K16: 3080000
A17: Total Current Assets | B17: 5713297 | C17: 6053000 | D17: 8536000 | E17: 9255000 | F17: 10557000 | G17: 13690000 | H17: 16055000 | I17: 28829000 | J17: 23073000 | K17: 44345000
A18: Gross Property Plant & Equip | B18: 1179257 | C18: 1100000 | D18: 1191000 | E18: 1737000 | F18: 2171000 | G18: 2685000 | H18: 3557000 | I18: 4681000 | J18: 6501000 | K18: 7423000
A19: Accumulated Depreciation | B19: 621975 | C19: 634000 | D19: 670000 | E19: 740000 | F19: 767000 | G19: 1011000 | H19: 1408000 | I19: 1903000 | J19: 2694000 | K19: 3509000
A20: Net Property Plant & Equip | B20: 557282 | C20: 466000 | D20: 521000 | E20: 997000 | F20: 1404000 | G20: 1674000 | H20: 2149000 | I20: 2778000 | J20: 3807000 | K20: 3914000
A21: Intangible Assets | B21: 839893 | C21: 784000 | D21: 722000 | E21: 670000 | F21: 663000 | G21: 667000 | H21: 6930000 | I21: 6688000 | J21: 6048000 | K21: 5542000
A22: Other Assets | B22: 90896 | C22: 67000 | D22: 62000 | E22: 319000 | F22: 668000 | G22: 736000 | H22: 2851000 | I22: 2248000 | J22: 1183000 | K22: 5846000
... A40: Total Liabilities & Equity | B40: 7201368 | C40: 7370000 | D40: 9841000 | E40: 11241000 | F40: 13292000 | G40: 17315000 | H40: 28791000 | I40: 44187000 | J40: 41182000 | K40: 65728000

Sheet Percentage Balance sheet
A1: Standardized Annual Balance Sheet | B1: 2015 | C1: 2016 | D1: 2017 | E1: 2018 | F1: 2019 | G1: 2020 | H1: 2021 | I1: 2022 | J1: 2023 | K1: 2024
A2: Report Date | B2: 01/25/2015 | C2: 01/31/2016 | D2: 01/29/2017 | E2: 01/28/2018 | F2: 01/27/2019 | G2: 01/26/2020 | H2: 01/31/2021 | I2: 01/30/2022 | J2: 01/29/2023 | K2: 01/28/2024
A3: Currency | B3: USD | C3: USD | D3: USD | E3: USD | F3: USD | G3: USD | H3: USD | I3: USD | J3: USD | K3: USD
A4: Consolidated | B4: Yes | C4: Yes | D4: Yes | E4: Yes | F4: Yes | G4: Yes | H4: Yes | I4: Yes | J4: Yes | K4: Yes
A5: Scale | B5: Thousands | C5: Thousands | D5: Thousands | E5: Thousands | F5: Thousands | G5: Thousands | H5: Thousands | I5: Thousands | J5: Thousands | K5: Thousands
A6: Cash & Equivalents | B6: ='BALANCE SHEET '!B11/'BALANCE SHEET '!$B$23 -> 0.068966619 | C6: ='BALANCE SHEET '!C11/'BALANCE SHEET '!$C$23 -> 0.080868385 | D6: ='BALANCE SHEET '!D11/'BALANCE SHEET '!$D$23 -> 0.17945331 | E6: ='BALANCE SHEET '!E11/'BALANCE SHEET '!$E$23 -> 0.35601815 | F6: ='BALANCE SHEET '!F11/'BALANCE SHEET '!$F$23 -> 0.05883238 | G6: ='BALANCE SHEET '!G11/'BALANCE SHEET '!$G$23 -> 0.62928097 | H6: ='BALANCE SHEET '!H11/'BALANCE SHEET '!$H$23 -> 0.029418916 | I6: ='BALANCE SHEET '!I11/'BALANCE SHEET '!$I$23 -> 0.04503587 | J6: ='BALANCE SHEET '!J11/'BALANCE SHEET '!$J$23 -> 0.082293235 | K6: ='BALANCE SHEET '!K11/'BALANCE SHEET '!$K$23 -> 0.11075949
A7: Short Term Investments | B7: ='BALANCE SHEET '!B12/'BALANCE SHEET '!$B$23 -> 0.57304182 | C7: ='BALANCE SHEET '!C12/'BALANCE SHEET '!$C$23 -> 0.60257802 | D7: ='BALANCE SHEET '!D12/'BALANCE SHEET '!$D$23 -> 0.51133015 | E7: ='BALANCE SHEET '!E12/'BALANCE SHEET '!$E$23 -> 0.27630994 | F7: ='BALANCE SHEET '!F12/'BALANCE SHEET '!$F$23 -> 0.4995486 | G7: ='BALANCE SHEET '!G12/'BALANCE SHEET '!$G$23 -> 5.7753393e-05 | H7: ='BALANCE SHEET '!H12/'BALANCE SHEET '!$H$23 -> 0.37213018 | I7: ='BALANCE SHEET '!I12/'BALANCE SHEET '!$I$23 -> 0.4349243 | J7: ='BALANCE SHEET '!J12/'BALANCE SHEET '!$J$23 -> 0.24056627 | K7: ='BALANCE SHEET '!K12/'BALANCE SHEET '!$K$23 -> 0.2845667
A8: Cash & Equivs & ST Investments | B8: ='BALANCE SHEET '!B13/'BALANCE SHEET '!$B$23 -> 0.64200844 | C8: ='BALANCE SHEET '!C13/'BALANCE SHEET '!$C$23 -> 0.6834464 | D8: ='BALANCE SHEET '!D13/'BALANCE SHEET '!$D$23 -> 0.69078346 | E8: ='BALANCE SHEET '!E13/'BALANCE SHEET '!$E$23 -> 0.63232808 | F8: ='BALANCE SHEET '!F13/'BALANCE SHEET '!$F$23 -> 0.55838098 | G8: ='BALANCE SHEET '!G13/'BALANCE SHEET '!$G$23 -> 0.62933872 | H8: ='BALANCE SHEET '!H13/'BALANCE SHEET '!$H$23 -> 0.4015491 | I8: ='BALANCE SHEET '!I13/'BALANCE SHEET '!$I$23 -> 0.47996017 | J8: ='BALANCE SHEET '!J13/'BALANCE SHEET '!$J$23 -> 0.3228595 | K8: ='BALANCE SHEET '!K13/'BALANCE SHEET '!$K$23 -> 0.39532619
A9: Receivables (ST) | B9: ='BALANCE SHEET '!B14/'BALANCE SHEET '!$B$23 -> 0.06577042 | C9: ='BALANCE SHEET '!C14/'BALANCE SHEET '!$C$23 -> 0.068521031 | D9: ='BALANCE SHEET '!D14/'BALANCE SHEET '!$D$23 -> 0.083934559 | E9: ='BALANCE SHEET '!E14/'BALANCE SHEET '!$E$23 -> 0.11253447 | F9: ='BALANCE SHEET '!F14/'BALANCE SHEET '!$F$23 -> 0.10713211 | G9: ='BALANCE SHEET '!G14/'BALANCE SHEET '!$G$23 -> 0.095697372 | H9: ='BALANCE SHEET '!H14/'BALANCE SHEET '!$H$23 -> 0.084366642 | I9: ='BALANCE SHEET '!I14/'BALANCE SHEET '!$I$23 -> 0.10523457 | J9: ='BALANCE SHEET '!J14/'BALANCE SHEET '!$J$23 -> 0.09292895 | K9: ='BALANCE SHEET '!K14/'BALANCE SHEET '!$K$23 -> 0.15212695
A10: Inventories | B10: ='BALANCE SHEET '!B15/'BALANCE SHEET '!$B$23 -> 0.067055732 | C10: ='BALANCE SHEET '!C15/'BALANCE SHEET '!$C$23 -> 0.056716418 | D10: ='BALANCE SHEET '!D15/'BALANCE SHEET '!$D$23 -> 0.080682857 | E10: ='BALANCE SHEET '!E15/'BALANCE SHEET '!$E$23 -> 0.070812205 | F10: ='BALANCE SHEET '!F15/'BALANCE SHEET '!$F$23 -> 0.11849233 | G10: ='BALANCE SHEET '!G15/'BALANCE SHEET '!$G$23 -> 0.056540572 | H10: ='BALANCE SHEET '!H15/'BALANCE SHEET '!$H$23 -> 0.063422597 | I10: ='BALANCE SHEET '!I15/'BALANCE SHEET '!$I$23 -> 0.058953991 | J10: ='BALANCE SHEET '!J15/'BALANCE SHEET '!$J$23 -> 0.12527318 | K10: ='BALANCE SHEET '!K15/'BALANCE SHEET '!$K$23 -> 0.08036149
A11: Other Current Assets | B11: ='BALANCE SHEET '!B16/'BALANCE SHEET '!$B$23 -> 0.0097445374 | C11: ='BALANCE SHEET '!C16/'BALANCE SHEET '!$C$23 -> 0.012618725 | D11: ='BALANCE SHEET '!D16/'BALANCE SHEET '!$D$23 -> 0.011990651 | E11: ='BALANCE SHEET '!E16/'BALANCE SHEET '!$E$23 -> 0.0076505649 | F11: ='BALANCE SHEET '!F16/'BALANCE SHEET '!$F$23 -> 0.010231718 | G11: ='BALANCE SHEET '!G16/'BALANCE SHEET '!$G$23 -> 0.0090672827 | H11: ='BALANCE SHEET '!H16/'BALANCE SHEET '!$H$23 -> 0.0083012052 | I11: ='BALANCE SHEET '!I16/'BALANCE SHEET '!$I$23 -> 0.0082829792 | J11: ='BALANCE SHEET '!J16/'BALANCE SHEET '!$J$23 -> 0.019207421 | K11: ='BALANCE SHEET '!K16/'BALANCE SHEET '!$K$23 -> 0.046859786
A12: Total Current Assets | B12: ='BALANCE SHEET '!B17/'BALANCE SHEET '!$B$23 -> 0.79336273 | C12: ='BALANCE SHEET '!C17/'BALANCE SHEET '!$C$23 -> 0.82130258 | D12: ='BALANCE SHEET '!D17/'BALANCE SHEET '!$D$23 -> 0.86739153 | E12: ='BALANCE SHEET '!E17/'BALANCE SHEET '!$E$23 -> 0.82332533 | F12: ='BALANCE SHEET '!F17/'BALANCE SHEET '!$F$23 -> 0.79423714 | G12: ='BALANCE SHEET '!G17/'BALANCE SHEET '!$G$23 -> 0.79064395 | H12: ='BALANCE SHEET '!H17/'BALANCE SHEET '!$H$23 -> 0.55763954 | I12: ='BALANCE SHEET '!I17/'BALANCE SHEET '!$I$23 -> 0.65243171 | J12: ='BALANCE SHEET '!J17/'BALANCE SHEET '!$J$23 -> 0.56026905 | K12: ='BALANCE SHEET '!K17/'BALANCE SHEET '!$K$23 -> 0.67467442
A13: Gross Property Plant & Equip | B13: ='BALANCE SHEET '!B18/'BALANCE SHEET '!$B$23 -> 0.16375458 | C13: ='BALANCE SHEET '!C18/'BALANCE SHEET '!$C$23 -> 0.14925373 | D13: ='BALANCE SHEET '!D18/'BALANCE SHEET '!$D$23 -> 0.12102429 | E13: ='BALANCE SHEET '!E18/'BALANCE SHEET '!$E$23 -> 0.15452362 | F13: ='BALANCE SHEET '!F18/'BALANCE SHEET '!$F$23 -> 0.16333133 | G13: ='BALANCE SHEET '!G18/'BALANCE SHEET '!$G$23 -> 0.15506786 | H13: ='BALANCE SHEET '!H18/'BALANCE SHEET '!$H$23 -> 0.12354555 | I13: ='BALANCE SHEET '!I18/'BALANCE SHEET '!$I$23 -> 0.10593614 | J13: ='BALANCE SHEET '!J18/'BALANCE SHEET '!$J$23 -> 0.15786023 | K13: ='BALANCE SHEET '!K18/'BALANCE SHEET '!$K$23 -> 0.11293513
A14: Accumulated Depreciation | B14: ='BALANCE SHEET '!B19/'BALANCE SHEET '!$B$23 -> 0.086369007 | C14: ='BALANCE SHEET '!C19/'BALANCE SHEET '!$C$23 -> 0.086024423 | D14: ='BALANCE SHEET '!D19/'BALANCE SHEET '!$D$23 -> 0.068082512 | E14: ='BALANCE SHEET '!E19/'BALANCE SHEET '!$E$23 -> 0.065830442 | F14: ='BALANCE SHEET '!F19/'BALANCE SHEET '!$F$23 -> 0.057703882 | G14: ='BALANCE SHEET '!G19/'BALANCE SHEET '!$G$23 -> 0.05838868 | H14: ='BALANCE SHEET '!H19/'BALANCE SHEET '!$H$23 -> 0.048904171 | I14: ='BALANCE SHEET '!I19/'BALANCE SHEET '!$I$23 -> 0.043066965 | J14: ='BALANCE SHEET '!J19/'BALANCE SHEET '!$J$23 -> 0.06541693 | K14: ='BALANCE SHEET '!K19/'BALANCE SHEET '!$K$23 -> 0.053386685
A15: Net Property Plant & Equip | B15: ='BALANCE SHEET '!B20/'BALANCE SHEET '!$B$23 -> 0.077385575 | C15: ='BALANCE SHEET '!C20/'BALANCE SHEET '!$C$23 -> 0.063229308 | D15: ='BALANCE SHEET '!D20/'BALANCE SHEET '!$D$23 -> 0.052941774 | E15: ='BALANCE SHEET '!E20/'BALANCE SHEET '!$E$23 -> 0.088693177 | F15: ='BALANCE SHEET '!F20/'BALANCE SHEET '!$F$23 -> 0.10562745 | G15: ='BALANCE SHEET '!G20/'BALANCE SHEET '!$G$23 -> 0.09667918 | H15: ='BALANCE SHEET '!H20/'BALANCE SHEET '!$H$23 -> 0.074641381 | I15: ='BALANCE SHEET '!I20/'BALANCE SHEET '!$I$23 -> 0.06286917 | J15: ='BALANCE SHEET '!J20/'BALANCE SHEET '!$J$23 -> 0.0924433 | K15: ='BALANCE SHEET '!K20/'BALANCE SHEET '!$K$23 -> 0.059548442
A16: Intangible Assets | B16: ='BALANCE SHEET '!B21/'BALANCE SHEET '!$B$23 -> 0.11662965 | C16: ='BALANCE SHEET '!C21/'BALANCE SHEET '!$C$23 -> 0.1063772 | D16: ='BALANCE SHEET '!D21/'BALANCE SHEET '!$D$23 -> 0.073366528 | E16: ='BALANCE SHEET '!E21/'BALANCE SHEET '!$E$23 -> 0.059603238 | F16: ='BALANCE SHEET '!F21/'BALANCE SHEET '!$F$23 -> 0.049879627 | G16: ='BALANCE SHEET '!G21/'BALANCE SHEET '!$G$23 -> 0.038521513 | H16: ='BALANCE SHEET '!H21/'BALANCE SHEET '!$H$23 -> 0.24070022 | I16: ='BALANCE SHEET '!I21/'BALANCE SHEET '!$I$23 -> 0.15135673 | J16: ='BALANCE SHEET '!J21/'BALANCE SHEET '!$J$23 -> 0.14686028 | K16: ='BALANCE SHEET '!K21/'BALANCE SHEET '!$K$23 -> 0.084317186
A17: Other Assets | B17: ='BALANCE SHEET '!B22/'BALANCE SHEET '!$B$23 -> 0.012622046 | C17: ='BALANCE SHEET '!C22/'BALANCE SHEET '!$C$23 -> 0.0090909091 | D17: ='BALANCE SHEET '!D22/'BALANCE SHEET '!$D$23 -> 0.0063001727 | E17: ='BALANCE SHEET '!E22/'BALANCE SHEET '!$E$23 -> 0.028378258 | F17: ='BALANCE SHEET '!F22/'BALANCE SHEET '!$F$23 -> 0.050255793 | G17: ='BALANCE SHEET '!G22/'BALANCE SHEET '!$G$23 -> 0.042506497 | H17: ='BALANCE SHEET '!H22/'BALANCE SHEET '!$H$23 -> 0.099024001 | I17: ='BALANCE SHEET '!I22/'BALANCE SHEET '!$I$23 -> 0.050874692 | J17: ='BALANCE SHEET '!J22/'BALANCE SHEET '!$J$23 -> 0.028726142 | K17: ='BALANCE SHEET '!K22/'BALANCE SHEET '!$K$23 -> 0.088942308
... A35: Total Liabilities & Equity | B35: ='BALANCE SHEET '!B40/'BALANCE SHEET '!$B$23 -> 1 | C35: ='BALANCE SHEET '!C40/'BALANCE SHEET '!$C$23 -> 1 | D35: ='BALANCE SHEET '!D40/'BALANCE SHEET '!$D$23 -> 1 | E35: ='BALANCE SHEET '!E40/'BALANCE SHEET '!$E$23 -> 1 | F35: ='BALANCE SHEET '!F40/'BALANCE SHEET '!$F$23 -> 1 | G35: ='BALANCE SHEET '!G40/'BALANCE SHEET '!$G$23 -> 1 | H35: ='BALANCE SHEET '!H40/'BALANCE SHEET '!$H$23 -> 1 | I35: ='BALANCE SHEET '!I40/'BALANCE SHEET '!$I$23 -> 1 | J35: ='BALANCE SHEET '!J40/'BALANCE SHEET '!$J$23 -> 1 | K35: ='BALANCE SHEET '!K40/'BALANCE SHEET '!$K$23 -> 1

Sheet FINANCIAL RATIOS
A1: Report Date | B1: 2015 | C1: 2016 | D1: 2017 | E1: 2018 | F1: 2019 | G1: 2020 | H1: 2021 | I1: 2022 | J1: 2023 | K1: 2024
A2: Revenue Growth | B2: ='INCOME STATEMENT'!B13/'INCOME STATEMENT'!B13 -> 1 | C2: =('INCOME STATEMENT'!C13-'INCOME STATEMENT'!B13)/'INCOME STATEMENT'!B13 -> 0.070168217 | D2: =('INCOME STATEMENT'!D13-'INCOME STATEMENT'!C13)/'INCOME STATEMENT'!C13 -> 0.37924152 | E2: =('INCOME STATEMENT'!E13-'INCOME STATEMENT'!D13)/'INCOME STATEMENT'!D13 -> 0.40578871 | F2: =('INCOME STATEMENT'!F13-'INCOME STATEMENT'!E13)/'INCOME STATEMENT'!E13 -> 0.2060943 | G2: =('INCOME STATEMENT'!G13-'INCOME STATEMENT'!F13)/'INCOME STATEMENT'!F13 -> -0.068111984 | H2: =('INCOME STATEMENT'!H13-'INCOME STATEMENT'!G13)/'INCOME STATEMENT'!G13 -> 0.52729438 | I2: =('INCOME STATEMENT'!I13-'INCOME STATEMENT'!H13)/'INCOME STATEMENT'!H13 -> 0.61403298 | J2: =('INCOME STATEMENT'!J13-'INCOME STATEMENT'!I13)/'INCOME STATEMENT'!I13 -> 0.002229323 | K2: =('INCOME STATEMENT'!K13-'INCOME STATEMENT'!J13)/'INCOME STATEMENT'!J13 -> 1.2585453
A3: Net Profit Margin | B3: ='INCOME STATEMENT'!B24/'INCOME STATEMENT'!B13 -> 0.13469744 | C3: ='INCOME STATEMENT'!C24/'INCOME STATEMENT'!C13 -> 0.12255489 | D3: ='INCOME STATEMENT'!D24/'INCOME STATEMENT'!D13 -> 0.24109986 | E3: ='INCOME STATEMENT'!E24/'INCOME STATEMENT'!E13 -> 0.31367099 | F3: ='INCOME STATEMENT'!F24/'INCOME STATEMENT'!F13 -> 0.35344828 | G3: ='INCOME STATEMENT'!G24/'INCOME STATEMENT'!G13 -> 0.25609086 | H3: ='INCOME STATEMENT'!H24/'INCOME STATEMENT'!H13 -> 0.2597901 | I3: ='INCOME STATEMENT'!I24/'INCOME STATEMENT'!I13 -> 0.3623393 | ... K3: ='INCOME STATEMENT'!K24/'INCOME STATEMENT'!K13 -> 0.48849348
A4: Gross Profit Margin | B4: ='INCOME STATEMENT'!B15/'INCOME STATEMENT'!B13 -> 0.555265 | C4: ='INCOME STATEMENT'!C15/'INCOME STATEMENT'!C13 -> 0.56107784 | D4: ='INCOME STATEMENT'!D15/'INCOME STATEMENT'!D13 -> 0.58798842 | E4: ='INCOME STATEMENT'!E15/'INCOME STATEMENT'!E13 -> 0.59934116 | F4: ='INCOME STATEMENT'!F15/'INCOME STATEMENT'!F13 -> 0.61206897 | G4: ='INCOME STATEMENT'!G15/'INCOME STATEMENT'!G13 -> 0.61989375 | H4: ='INCOME STATEMENT'!H15/'INCOME STATEMENT'!H13 -> 0.62344828 | I4: ='INCOME STATEMENT'!I15/'INCOME STATEMENT'!I13 -> 0.64929033 | ... K4: ='INCOME STATEMENT'!K15/'INCOME STATEMENT'!K13 -> 0.72717573
A5: Operating Income | B5: ='INCOME STATEMENT'!B19/'INCOME STATEMENT'!B13 -> 0.16212493 | C5: ='INCOME STATEMENT'!C19/'INCOME STATEMENT'!C13 -> 0.1491018 | D5: ='INCOME STATEMENT'!D19/'INCOME STATEMENT'!D13 -> 0.27988423 | E5: ='INCOME STATEMENT'!E19/'INCOME STATEMENT'!E13 -> 0.3304509 | F5: ='INCOME STATEMENT'!F19/'INCOME STATEMENT'!F13 -> 0.32468419 | G5: ='INCOME STATEMENT'!G19/'INCOME STATEMENT'!G13 -> 0.26067045 | H5: ='INCOME STATEMENT'!H19/'INCOME STATEMENT'!H13 -> 0.27178411 | I5: ='INCOME STATEMENT'!I19/'INCOME STATEMENT'!I13 -> 0.37307721 | ... K5: ='INCOME STATEMENT'!K19/'INCOME STATEMENT'!K13 -> 0.54121664
A6: Return On Assets | B6: ='INCOME STATEMENT'!B24/'BALANCE SHEET '!B23 -> 0.08756489 | C6: ='INCOME STATEMENT'!C24/'BALANCE SHEET '!C23 -> 0.083310719 | D6: ='INCOME STATEMENT'!D24/'BALANCE SHEET '!D23 -> 0.16929174 | E6: ='INCOME STATEMENT'!E24/'BALANCE SHEET '!E23 -> 0.27106129 | F6: ='INCOME STATEMENT'!F24/'BALANCE SHEET '!F23 -> 0.31154078 | G6: ='INCOME STATEMENT'!G24/'BALANCE SHEET '!G23 -> 0.16147849 | H6: ='INCOME STATEMENT'!H24/'BALANCE SHEET '!H23 -> 0.15046369 | I6: ='INCOME STATEMENT'!I24/'BALANCE SHEET '!I23 -> 0.2206984 | ... K6: ='INCOME STATEMENT'!K24/'BALANCE SHEET '!K23 -> 0.45277507
A7: Return on equity | B7: ='INCOME STATEMENT'!B24/'BALANCE SHEET '!B39 -> 0.14273191 | C7: ='INCOME STATEMENT'!C24/'BALANCE SHEET '!C39 -> 0.13476734 | D7: ='INCOME STATEMENT'!D24/'BALANCE SHEET '!D39 -> 0.28758847 | E7: ='INCOME STATEMENT'!E24/'BALANCE SHEET '!E39 -> 0.40784366 | F7: ='INCOME STATEMENT'!F24/'BALANCE SHEET '!F39 -> 0.44326697 | G7: ='INCOME STATEMENT'!G24/'BALANCE SHEET '!G39 -> 0.22910521 | H7: ='INCOME STATEMENT'!H24/'BALANCE SHEET '!H39 -> 0.25643758 | I7: ='INCOME STATEMENT'!I24/'BALANCE SHEET '!I39 -> 0.36645123 | ... K7: ='INCOME STATEMENT'!K24/'BALANCE SHEET '!K39 -> 0.6924473
A8: Liquidity Ratio
A9: Current Ratio | B9: ='BALANCE SHEET '!B17/'BALANCE SHEET '!B29 -> 6.3762341 | C9: ='BALANCE SHEET '!C17/'BALANCE SHEET '!C29 -> 2.5746491 | D9: ='BALANCE SHEET '!D17/'BALANCE SHEET '!D29 -> 4.7740492 | E9: ='BALANCE SHEET '!E17/'BALANCE SHEET '!E29 -> 8.0268864 | F9: ='BALANCE SHEET '!F17/'BALANCE SHEET '!F29 -> 7.9435666 | G9: ='BALANCE SHEET '!G17/'BALANCE SHEET '!G29 -> 7.6737668 | H9: ='BALANCE SHEET '!H17/'BALANCE SHEET '!H29 -> 4.0904459 | I9: ='BALANCE SHEET '!I17/'BALANCE SHEET '!I29 -> 6.6502884 | ... K9: ='BALANCE SHEET '!K17/'BALANCE SHEET '!K29 -> 4.1712915
A10: Quick Ratios | B10: =('BALANCE SHEET '!B11+'BALANCE SHEET '!B12+'BALANCE SHEET '!B14)/'BALANCE SHEET '!B29 -> 5.6883988 | C10: =('BALANCE SHEET '!C11+'BALANCE SHEET '!C12+'BALANCE SHEET '!C14)/'BALANCE SHEET '!C29 -> 2.3572948 | D10: =('BALANCE SHEET '!D11+'BALANCE SHEET '!D12+'BALANCE SHEET '!D14)/'BALANCE SHEET '!D29 -> 4.2639821 | E10: =('BALANCE SHEET '!E11+'BALANCE SHEET '!E12+'BALANCE SHEET '!E14)/'BALANCE SHEET '!E29 -> 7.2619254 | F10: =('BALANCE SHEET '!F11+'BALANCE SHEET '!F12+'BALANCE SHEET '!F14)/'BALANCE SHEET '!F29 -> 6.6561324 | G10: =('BALANCE SHEET '!G11+'BALANCE SHEET '!G12+'BALANCE SHEET '!G14)/'BALANCE SHEET '!G29 -> 7.0369955 | H10: =('BALANCE SHEET '!H11+'BALANCE SHEET '!H12+'BALANCE SHEET '!H14)/'BALANCE SHEET '!H29 -> 3.5643312 | I10: =('BALANCE SHEET '!I11+'BALANCE SHEET '!I12+'BALANCE SHEET '!I14)/'BALANCE SHEET '!I29 -> 5.9649366 | ... K10: =('BALANCE SHEET '!K11+'BALANCE SHEET '!K12+'BALANCE SHEET '!K14)/'BALANCE SHEET '!K29 -> 3.3847239
A11: Cash Ratio | B11: ='BALANCE SHEET '!B11/'BALANCE SHEET '!B33 -> 0.17843519 | C11: ='BALANCE SHEET '!C11/'BALANCE SHEET '!C33 -> 0.21179815 | D11: ='BALANCE SHEET '!D11/'BALANCE SHEET '!D33 -> 0.43626482 | E11: ='BALANCE SHEET '!E11/'BALANCE SHEET '!E33 -> 1.0615385 | F11: ='BALANCE SHEET '!F11/'BALANCE SHEET '!F33 -> 0.19797468 | G11: ='BALANCE SHEET '!G11/'BALANCE SHEET '!G33 -> 2.1318724 | H11: ='BALANCE SHEET '!H11/'BALANCE SHEET '!H33 -> 0.071188435 | I11: ='BALANCE SHEET '!I11/'BALANCE SHEET '!I33 -> 0.11322902 | ... K11: ='BALANCE SHEET '!K11/'BALANCE SHEET '!K33 -> 0.32
A12: Leverage Ratio
A13: Debt to Equity Ratio | B13: ='BALANCE SHEET '!B33/'BALANCE SHEET '!B39 -> 0.63001298 | C13: ='BALANCE SHEET '!C33/'BALANCE SHEET '!C39 -> 0.61764706 | D13: ='BALANCE SHEET '!D33/'BALANCE SHEET '!D39 -> 0.69877438 | E13: ='BALANCE SHEET '!E33/'BALANCE SHEET '!E39 -> 0.50461786 | F13: ='BALANCE SHEET '!F33/'BALANCE SHEET '!F39 -> 0.42282167 | G13: ='BALANCE SHEET '!G33/'BALANCE SHEET '!G39 -> 0.41879712 | H13: ='BALANCE SHEET '!H33/'BALANCE SHEET '!H39 -> 0.7043154 | I13: ='BALANCE SHEET '!I33/'BALANCE SHEET '!I39 -> 0.66041635 | ... K13: ='BALANCE SHEET '!K33/'BALANCE SHEET '!K39 -> 0.52934059
A14: Debt Ratio | B14: ='BALANCE SHEET '!B33/'BALANCE SHEET '!B23 -> 0.38650795 | C14: ='BALANCE SHEET '!C33/'BALANCE SHEET '!C23 -> 0.38181818 | D14: ='BALANCE SHEET '!D33/'BALANCE SHEET '!D23 -> 0.41134031 | E14: ='BALANCE SHEET '!E33/'BALANCE SHEET '!E23 -> 0.33537941 | F14: ='BALANCE SHEET '!F33/'BALANCE SHEET '!F23 -> 0.29717123 | G14: ='BALANCE SHEET '!G33/'BALANCE SHEET '!G23 -> 0.29517759 | H14: ='BALANCE SHEET '!H33/'BALANCE SHEET '!H23 -> 0.41325414 | I14: ='BALANCE SHEET '!I33/'BALANCE SHEET '!I23 -> 0.39774142 | ... K14: ='BALANCE SHEET '!K33/'BALANCE SHEET '!K23 -> 0.34612342

Sheet INCOME STATEMENT
A4: Powered by Clearbit
A5: NVIDIA Corp (NMS: NVDA)
A6: Standardized Annual Income Statement | B6: 2015 | C6: 2016 | D6: 2017 | E6: 2018 | F6: 2019 | G6: 2020 | H6: 2021 | I6: 2022 | J6: 2023 | K6: 2024
A7: Report Date | B7: 01/25/2015 | C7: 01/31/2016 | D7: 01/29/2017 | E7: 01/28/2018 | F7: 01/27/2019 | G7: 01/26/2020 | H7: 01/31/2021 | I7: 01/30/2022 | J7: 01/29/2023 | K7: 01/28/2024
A8: Currency | B8: USD | C8: USD | D8: USD | E8: USD | F8: USD | G8: USD | H8: USD | I8: USD | J8: USD | K8: USD
A9: Audit Status | B9: Not Qualified | C9: Not Qualified | D9: Not Qualified | E9: Not Qualified | F9: Not Qualified | G9: Not Qualified | H9: Not Qualified | I9: Not Qualified | J9: Not Qualified | K9: Not Qualified
A10: Consolidated | B10: Yes | C10: Yes | D10: Yes | E10: Yes | F10: Yes | G10: Yes | H10: Yes | I10: Yes | J10: Yes | K10: Yes
A11: Scale | B11: Thousands | C11: Thousands | D11: Thousands | E11: Thousands | F11: Thousands | G11: Thousands | H11: Thousands | I11: Thousands | J11: Thousands | K11: Thousands
A12: Sales Revenue | B12: - | C12: - | D12: - | E12: - | F12: - | G12: - | H12: - | I12: - | J12: - | K12: 60922000
A13: Total Revenue | B13: 4681507 | C13: 5010000 | D13: 6910000 | E13: 9714000 | F13: 11716000 | G13: 10918000 | H13: 16675000 | I13: 26914000 | J13: 26974000 | K13: 60922000
A14: Direct Costs | B14: 2082030 | C14: 2199000 | D14: 2847000 | E14: 3892000 | F14: 4545000 | G14: 4150000 | H14: 6279000 | I14: 9439000 | J14: 11618000 | K14: 16621000
A15: Gross Profit | B15: 2599477 | C15: 2811000 | D15: 4063000 | E15: 5822000 | F15: 7171000 | G15: 6768000 | H15: 10396000 | I15: 17475000 | J15: 15356000 | K15: 44301000
A16: Selling General & Admin | B16: 480763 | C16: 602000 | D16: 663000 | E16: 815000 | F16: 991000 | G16: 1093000 | H16: 1940000 | I16: 2166000 | J16: 2440000 | K16: 2654000
A17: Research & Development | B17: 1359725 | C17: 1331000 | D17: 1463000 | E17: 1797000 | F17: 2376000 | G17: 2829000 | H17: 3924000 | I17: 5268000 | J17: 7339000 | K17: 8675000
A18: Total Indirect Operating Costs | B18: 1840488 | C18: 2064000 | D18: 2129000 | E18: 2612000 | F18: 3367000 | G18: 3922000 | H18: 5864000 | I18: 7434000 | J18: 11132000 | K18: 11329000
A19: Operating Income | B19: 758989 | C19: 747000 | D19: 1934000 | E19: 3210000 | F19: 3804000 | G19: 2846000 | H19: 4532000 | I19: 10041000 | J19: 4224000 | K19: 32972000
A20: Interest Income | B20: -18043 | C20: -8000 | D20: -4000 | E20: 8000 | F20: 78000 | G20: 126000 | H20: -127000 | I20: -207000 | J20: 5000 | K20: 609000
A21: Other Non-Operating Income | B21: 13890 | C21: 4000 | D21: -25000 | E21: -22000 | F21: 14000 | G21: -2000 | H21: 4000 | I21: 107000 | J21: -48000 | K21: 237000
A22: Total Non-Operating Income | B22: -4153 | C22: -4000 | D22: -29000 | E22: -14000 | F22: 92000 | G22: 124000 | H22: -123000 | I22: -100000 | J22: -43000 | K22: 846000
A23: Earnings Before Tax | B23: 754836 | C23: 743000 | D23: 1905000 | E23: 3196000 | F23: 3896000 | G23: 2970000 | H23: 4409000 | I23: 9941000 | J23: 4181000 | K23: 33818000
A24: Net Income | B24: 630587 | C24: 614000 | D24: 1666000 | E24: 3047000 | F24: 4141000 | G24: 2796000 | H24: 4332000 | I24: 9752000 | J24: 4368000 | K24: 29760000
... A32: Shares Outstanding | B32: 21796520 | C32: 21560000 | D32: 23400000 | E32: 24240000 | F32: 24240000 | G32: 24480000 | H32: 24800000 | I32: 25060000 | J32: 24660000 | K32: 24640000

Sheet Income statement c
B2: 2015 | C2: 2016 | D2: 2017 | E2: 2018 | F2: 2019 | G2: 2020 | H2: 2021 | I2: 2022 | J2: 2023 | K2: 2024
A3: Report Date | B3: 01/25/2015 | C3: 01/31/2016 | D3: 01/29/2017 | E3: 01/28/2018 | F3: 01/27/2019 | G3: 01/26/2020 | H3: 01/31/2021 | I3: 01/30/2022 | J3: 01/29/2023 | K3: 01/28/2024
A4: Total Revenue | B4: ='INCOME STATEMENT'!B13/'INCOME STATEMENT'!B$13 -> 1 | C4: ='INCOME STATEMENT'!C13/'INCOME STATEMENT'!C$13 -> 1 | D4: ='INCOME STATEMENT'!D13/'INCOME STATEMENT'!D$13 -> 1 | E4: ='INCOME STATEMENT'!E13/'INCOME STATEMENT'!E$13 -> 1 | F4: ='INCOME STATEMENT'!F13/'INCOME STATEMENT'!F$13 -> 1 | G4: ='INCOME STATEMENT'!G13/'INCOME STATEMENT'!G$13 -> 1 | H4: ='INCOME STATEMENT'!H13/'INCOME STATEMENT'!H$13 -> 1 | I4: ='INCOME STATEMENT'!I13/'INCOME STATEMENT'!I$13 -> 1 | ... K4: ='INCOME STATEMENT'!K13/'INCOME STATEMENT'!K$13 -> 1
A5: Direct Costs | B5: ='INCOME STATEMENT'!B14/'INCOME STATEMENT'!B$13 -> 0.444735 | C5: ='INCOME STATEMENT'!C14/'INCOME STATEMENT'!C$13 -> 0.43892216 | D5: ='INCOME STATEMENT'!D14/'INCOME STATEMENT'!D$13 -> 0.41201158 | E5: ='INCOME STATEMENT'!E14/'INCOME STATEMENT'!E$13 -> 0.40065884 | F5: ='INCOME STATEMENT'!F14/'INCOME STATEMENT'!F$13 -> 0.38793103 | G5: ='INCOME STATEMENT'!G14/'INCOME STATEMENT'!G$13 -> 0.38010625 | H5: ='INCOME STATEMENT'!H14/'INCOME STATEMENT'!H$13 -> 0.37655172 | I5: ='INCOME STATEMENT'!I14/'INCOME STATEMENT'!I$13 -> 0.35070967 | ... K5: ='INCOME STATEMENT'!K14/'INCOME STATEMENT'!K$13 -> 0.27282427
A6: Gross Profit | B6: ='INCOME STATEMENT'!B15/'INCOME STATEMENT'!B$13 -> 0.555265 | C6: ='INCOME STATEMENT'!C15/'INCOME STATEMENT'!C$13 -> 0.56107784 | D6: ='INCOME STATEMENT'!D15/'INCOME STATEMENT'!D$13 -> 0.58798842 | E6: ='INCOME STATEMENT'!E15/'INCOME STATEMENT'!E$13 -> 0.59934116 | F6: ='INCOME STATEMENT'!F15/'INCOME STATEMENT'!F$13 -> 0.61206897 | G6: ='INCOME STATEMENT'!G15/'INCOME STATEMENT'!G$13 -> 0.61989375 | H6: ='INCOME STATEMENT'!H15/'INCOME STATEMENT'!H$13 -> 0.62344828 | I6: ='INCOME STATEMENT'!I15/'INCOME STATEMENT'!I$13 -> 0.64929033 | ... K6: ='INCOME STATEMENT'!K15/'INCOME STATEMENT'!K$13 -> 0.72717573
A7: Selling General & Admin | B7: ='INCOME STATEMENT'!B16/'INCOME STATEMENT'!B$13 -> 0.10269407 | C7: ='INCOME STATEMENT'!C16/'INCOME STATEMENT'!C$13 -> 0.12015968 | D7: ='INCOME STATEMENT'!D16/'INCOME STATEMENT'!D$13 -> 0.095947902 | E7: ='INCOME STATEMENT'!E16/'INCOME STATEMENT'!E$13 -> 0.083899526 | F7: ='INCOME STATEMENT'!F16/'INCOME STATEMENT'!F$13 -> 0.084585183 | G7: ='INCOME STATEMENT'!G16/'INCOME STATEMENT'!G$13 -> 0.10010991 | H7: ='INCOME STATEMENT'!H16/'INCOME STATEMENT'!H$13 -> 0.11634183 | I7: ='INCOME STATEMENT'!I16/'INCOME STATEMENT'!I$13 -> 0.080478561 | ... K7: ='INCOME STATEMENT'!K16/'INCOME STATEMENT'!K$13 -> 0.043563901
A8: Research & Development | B8: ='INCOME STATEMENT'!B17/'INCOME STATEMENT'!B$13 -> 0.290446 | C8: ='INCOME STATEMENT'!C17/'INCOME STATEMENT'!C$13 -> 0.26566866 | D8: ='INCOME STATEMENT'!D17/'INCOME STATEMENT'!D$13 -> 0.21172214 | E8: ='INCOME STATEMENT'!E17/'INCOME STATEMENT'!E$13 -> 0.18499074 | F8: ='INCOME STATEMENT'!F17/'INCOME STATEMENT'!F$13 -> 0.20279959 | G8: ='INCOME STATEMENT'!G17/'INCOME STATEMENT'!G$13 -> 0.25911339 | H8: ='INCOME STATEMENT'!H17/'INCOME STATEMENT'!H$13 -> 0.23532234 | I8: ='INCOME STATEMENT'!I17/'INCOME STATEMENT'!I$13 -> 0.19573456 | ... K8: ='INCOME STATEMENT'!K17/'INCOME STATEMENT'!K$13 -> 0.14239519
A9: Restruct Remediation & Impair | B9: ='INCOME STATEMENT'!#REF!/'INCOME STATEMENT'!B$13 -> #REF! | C9: ='INCOME STATEMENT'!#REF!/'INCOME STATEMENT'!C$13 -> #REF! | D9: ='INCOME STATEMENT'!#REF!/'INCOME STATEMENT'!D$13 -> #REF! | E9: ='INCOME STATEMENT'!#REF!/'INCOME STATEMENT'!E$13 -> #REF! | F9: ='INCOME STATEMENT'!#REF!/'INCOME STATEMENT'!F$13 -> #REF! | G9: ='INCOME STATEMENT'!#REF!/'INCOME STATEMENT'!G$13 -> #REF! | H9: ='INCOME STATEMENT'!#REF!/'INCOME STATEMENT'!H$13 -> #REF! | I9: ='INCOME STATEMENT'!#REF!/'INCOME STATEMENT'!I$13 -> #REF! | ... K9: ='INCOME STATEMENT'!#REF!/'INCOME STATEMENT'!K$13 -> #REF!
A10: Total Indirect Operating Costs | B10: ='INCOME STATEMENT'!B18/'INCOME STATEMENT'!B$13 -> 0.39314007 | C10: ='INCOME STATEMENT'!C18/'INCOME STATEMENT'!C$13 -> 0.41197605 | D10: ='INCOME STATEMENT'!D18/'INCOME STATEMENT'!D$13 -> 0.3081042 | E10: ='INCOME STATEMENT'!E18/'INCOME STATEMENT'!E$13 -> 0.26889026 | F10: ='INCOME STATEMENT'!F18/'INCOME STATEMENT'!F$13 -> 0.28738477 | G10: ='INCOME STATEMENT'!G18/'INCOME STATEMENT'!G$13 -> 0.3592233 | H10: ='INCOME STATEMENT'!H18/'INCOME STATEMENT'!H$13 -> 0.35166417 | I10: ='INCOME STATEMENT'!I18/'INCOME STATEMENT'!I$13 -> 0.27621312 | ... K10: ='INCOME STATEMENT'!K18/'INCOME STATEMENT'!K$13 -> 0.1859591
A11: Operating Income | B11: ='INCOME STATEMENT'!B19/'INCOME STATEMENT'!B$13 -> 0.16212493 | C11: ='INCOME STATEMENT'!C19/'INCOME STATEMENT'!C$13 -> 0.1491018 | D11: ='INCOME STATEMENT'!D19/'INCOME STATEMENT'!D$13 -> 0.27988423 | E11: ='INCOME STATEMENT'!E19/'INCOME STATEMENT'!E$13 -> 0.3304509 | F11: ='INCOME STATEMENT'!F19/'INCOME STATEMENT'!F$13 -> 0.32468419 | G11: ='INCOME STATEMENT'!G19/'INCOME STATEMENT'!G$13 -> 0.26067045 | H11: ='INCOME STATEMENT'!H19/'INCOME STATEMENT'!H$13 -> 0.27178411 | I11: ='INCOME STATEMENT'!I19/'INCOME STATEMENT'!I$13 -> 0.37307721 | ... K11: ='INCOME STATEMENT'!K19/'INCOME STATEMENT'!K$13 -> 0.54121664
A12: Interest Income | B12: ='INCOME STATEMENT'!B20/'INCOME STATEMENT'!B$13 -> -0.0038541008 | C12: ='INCOME STATEMENT'!C20/'INCOME STATEMENT'!C$13 -> -0.0015968064 | D12: ='INCOME STATEMENT'!D20/'INCOME STATEMENT'!D$13 -> -0.0005788712 | E12: ='INCOME STATEMENT'!E20/'INCOME STATEMENT'!E$13 -> 0.00082355363 | F12: ='INCOME STATEMENT'!F20/'INCOME STATEMENT'!F$13 -> 0.0066575623 | G12: ='INCOME STATEMENT'!G20/'INCOME STATEMENT'!G$13 -> 0.011540575 | H12: ='INCOME STATEMENT'!H20/'INCOME STATEMENT'!H$13 -> -0.0076161919 | I12: ='INCOME STATEMENT'!I20/'INCOME STATEMENT'!I$13 -> -0.0076911644 | ... K12: ='INCOME STATEMENT'!K20/'INCOME STATEMENT'!K$13 -> 0.0099963888
A13: Other Non-Operating Income | B13: ='INCOME STATEMENT'!B21/'INCOME STATEMENT'!B$13 -> 0.0029669933 | C13: ='INCOME STATEMENT'!C21/'INCOME STATEMENT'!C$13 -> 0.00079840319 | D13: ='INCOME STATEMENT'!D21/'INCOME STATEMENT'!D$13 -> -0.003617945 | E13: ='INCOME STATEMENT'!E21/'INCOME STATEMENT'!E$13 -> -0.0022647725 | F13: ='INCOME STATEMENT'!F21/'INCOME STATEMENT'!F$13 -> 0.0011949471 | G13: ='INCOME STATEMENT'!G21/'INCOME STATEMENT'!G$13 -> -0.00018318373 | H13: ='INCOME STATEMENT'!H21/'INCOME STATEMENT'!H$13 -> 0.00023988006 | I13: ='INCOME STATEMENT'!I21/'INCOME STATEMENT'!I$13 -> 0.0039756261 | ... K13: ='INCOME STATEMENT'!K21/'INCOME STATEMENT'!K$13 -> 0.0038902203
A14: Total Non-Operating Income | B14: ='INCOME STATEMENT'!B22/'INCOME STATEMENT'!B$13 -> -0.00088710751 | C14: ='INCOME STATEMENT'!C22/'INCOME STATEMENT'!C$13 -> -0.00079840319 | D14: ='INCOME STATEMENT'!D22/'INCOME STATEMENT'!D$13 -> -0.0041968162 | E14: ='INCOME STATEMENT'!E22/'INCOME STATEMENT'!E$13 -> -0.0014412189 | F14: ='INCOME STATEMENT'!F22/'INCOME STATEMENT'!F$13 -> 0.0078525094 | G14: ='INCOME STATEMENT'!G22/'INCOME STATEMENT'!G$13 -> 0.011357391 | H14: ='INCOME STATEMENT'!H22/'INCOME STATEMENT'!H$13 -> -0.0073763118 | I14: ='INCOME STATEMENT'!I22/'INCOME STATEMENT'!I$13 -> -0.0037155384 | ... K14: ='INCOME STATEMENT'!K22/'INCOME STATEMENT'!K$13 -> 0.013886609
A15: Earnings Before Tax | B15: ='INCOME STATEMENT'!B23/'INCOME STATEMENT'!B$13 -> 0.16123782 | C15: ='INCOME STATEMENT'!C23/'INCOME STATEMENT'!C$13 -> 0.14830339 | D15: ='INCOME STATEMENT'!D23/'INCOME STATEMENT'!D$13 -> 0.27568741 | E15: ='INCOME STATEMENT'!E23/'INCOME STATEMENT'!E$13 -> 0.32900968 | F15: ='INCOME STATEMENT'!F23/'INCOME STATEMENT'!F$13 -> 0.3325367 | G15: ='INCOME STATEMENT'!G23/'INCOME STATEMENT'!G$13 -> 0.27202784 | H15: ='INCOME STATEMENT'!H23/'INCOME STATEMENT'!H$13 -> 0.2644078 | I15: ='INCOME STATEMENT'!I23/'INCOME STATEMENT'!I$13 -> 0.36936167 | ... K15: ='INCOME STATEMENT'!K23/'INCOME STATEMENT'!K$13 -> 0.55510325
A16: Net Income | B16: ='INCOME STATEMENT'!B24/'INCOME STATEMENT'!B$13 -> 0.13469744 | C16: ='INCOME STATEMENT'!C24/'INCOME STATEMENT'!C$13 -> 0.12255489 | D16: ='INCOME STATEMENT'!D24/'INCOME STATEMENT'!D$13 -> 0.24109986 | E16: ='INCOME STATEMENT'!E24/'INCOME STATEMENT'!E$13 -> 0.31367099 | F16: ='INCOME STATEMENT'!F24/'INCOME STATEMENT'!F$13 -> 0.35344828 | G16: ='INCOME STATEMENT'!G24/'INCOME STATEMENT'!G$13 -> 0.25609086 | H16: ='INCOME STATEMENT'!H24/'INCOME STATEMENT'!H$13 -> 0.2597901 | I16: ='INCOME STATEMENT'!I24/'INCOME STATEMENT'!I$13 -> 0.3623393 | ... K16: ='INCOME STATEMENT'!K24/'INCOME STATEMENT'!K$13 -> 0.48849348

Sheet CASHFLOW STATEMENT
A4: Powered by Clearbit
A5: NVIDIA Corp (NMS: NVDA)
A6: Standardized Annual Cash Flows | B6: 2015 | C6: 2016 | D6: 2017 | E6: 2018 | F6: 2019 | G6: 2020 | H6: 2021 | I6: 2022 | J6: 2023 | K6: 2024
A7: Report Date | B7: 01/25/2015 | C7: 01/31/2016 | D7: 01/29/2017 | E7: 01/28/2018 | F7: 01/27/2019 | G7: 01/26/2020 | H7: 01/31/2021 | I7: 01/30/2022 | J7: 01/29/2023 | K7: 01/28/2024
A8: Currency | B8: USD | C8: USD | D8: USD | E8: USD | F8: USD | G8: USD | H8: USD | I8: USD | J8: USD | K8: USD
A9: Audit Status | B9: Not Qualified | C9: Not Qualified | D9: Not Qualified | E9: Not Qualified | F9: Not Qualified | G9: Not Qualified | H9: Not Qualified | I9: Not Qualified | J9: Not Qualified | K9: Not Qualified
A10: Consolidated | B10: Yes | C10: Yes | D10: Yes | E10: Yes | F10: Yes | G10: Yes | H10: Yes | I10: Yes | J10: Yes | K10: Yes
A11: Scale | B11: Thousands | C11: Thousands | D11: Thousands | E11: Thousands | F11: Thousands | G11: Thousands | H11: Thousands | I11: Thousands | J11: Thousands | K11: Thousands
A12: Net Income | B12: 630587 | C12: 614000 | D12: 1666000 | E12: 3047000 | F12: 4141000 | G12: 2796000 | H12: 4332000 | I12: 9752000 | J12: 4368000 | K12: 29760000
A13: Adjustments from Inc to Cash | B13: 477596 | C13: 612000 | D13: 685000 | E13: 270000 | F13: 459000 | G13: 1248000 | H13: 2193000 | I13: 2719000 | J13: 3480000 | K13: 2052000
A14: Change in Working Capital | B14: -202527 | C14: -51000 | D14: -679000 | E14: 185000 | F14: -857000 | G14: 717000 | H14: -703000 | I14: -3363000 | J14: -2207000 | K14: -3722000
A15: Cash Flow from Operations | B15: 905656 | C15: 1175000 | D15: 1672000 | E15: 3502000 | F15: 3743000 | G15: 4761000 | H15: 5822000 | I15: 9108000 | J15: 5641000 | K15: 28090000
A16: Purchase of Pty Plant & Equip | B16: -122381 | C16: -86000 | D16: -176000 | E16: -593000 | F16: -600000 | G16: -489000 | H16: -1128000 | I16: -976000 | J16: -1833000 | K16: -1069000
A17: Purchase of Investments | B17: -2861809 | C17: -3477000 | D17: -3134000 | E17: -36000 | F17: -11157000 | G17: -1461000 | H17: -19308000 | I17: -24787000 | J17: -11897000 | K17: -18211000
A18: Disposal of Investments | B18: 2236780 | C18: 3138000 | D18: 2515000 | E18: 1941000 | F18: 7660000 | G18: 8109000 | H18: 9319000 | I18: 16220000 | J18: 21231000 | K18: 9782000
A19: Change in Business Activities | B19: 0 | C19: 0 | D19: 0 | E19: 0 | F19: 0 | G19: 0 | H19: -8524000 | I19: -263000 | J19: -49000 | K19: -83000
A20: Other Investing Cash Flows | B20: 20362 | C20: 25000 | D20: 2000 | E20: -34000 | F20: 0 | G20: -14000 | H20: -34000 | I20: -24000 | J20: -77000 | K20: -985000
A21: Cash Flow from Investing | B21: -727048 | C21: -400000 | D21: -793000 | E21: 1278000 | F21: -4097000 | G21: 6145000 | H21: -19675000 | I21: -9830000 | J21: 7375000 | K21: -10566000
A22: Change in LT Debt | B22: -2917 | C22: -3000 | D22: 1315000 | E22: -812000 | F22: -16000 | G22: 0 | H22: 4968000 | I22: 3977000 | J22: 0 | K22: -1250000
A23: Change in Equity | B23: -813600 | C23: -587000 | D23: -739000 | E23: -909000 | F23: -1442000 | G23: 149000 | H23: 194000 | I23: 281000 | J23: -9684000 | K23: -9130000
... A31: Net Purch of Pty Plant & Equip | B31: -122381 | C31: -86000 | D31: -176000 | E31: -593000 | F31: -600000 | G31: -489000 | H31: -1128000 | I31: -976000 | J31: -1833000 | K31: -1069000

Sheet comparision
B1: NVDA | C1: AMD | D1: INTC | E1: QCOM
B2: NVIDIA Corporation | C2: Advanced Micro Devices, Inc. | D2: Intel Corporation | E2: QUALCOMM Incorporated
A3: Revenue | B3: 113.27B | C3: 24.30B | D3: 54.25B | E3: 38.96B
A4: gross profit | B4: 85.93B | C4: 11.75B | D4: 18.81B | E4: 21.90B
A5: Gross Margin | B5: 0.7586 | C5: 0.4838 | D5: 0.3467 | E5: 0.5621
A6: Profit Margin | B6: 0.5569 | C6: 0.0752 | D6: -0.2942 | E6: 0.2603

Sheet Sheet2
A4: Powered by Clearbit
A5: Advanced Micro Devices Inc (NMS: AMD)
A7: Exchange rate used is that of the Year End reported date
A10: Standardized Annual Balance Sheet
A11: Report Date | B11: 12/30/2023 | C11: 12/31/2022 | D11: 12/25/2021 | E11: 12/26/2020 | F11: 12/28/2019 | G11: 12/29/2018 | H11: 12/30/2017 | I11: 12/31/2016 | J11: 12/26/2015 | K11: 12/27/2014
A12: Currency | B12: USD | C12: USD | D12: USD | E12: USD | F12: USD | G12: USD | H12: USD | I12: USD | J12: USD | K12: USD
A13: Audit Status | B13: Not Qualified | C13: Not Qualified | D13: Not Qualified | E13: Not Qualified | F13: Not Qualified | G13: Not Qualified | H13: Not Qualified | I13: Not Qualified | J13: Not Qualified | K13: Not Qualified
A14: Consolidated | B14: Yes | C14: Yes | D14: Yes | E14: Yes | F14: Yes | G14: Yes | H14: Yes | I14: Yes | J14: Yes | K14: Yes
A15: Scale | B15: Thousands | C15: Thousands | D15: Thousands | E15: Thousands | F15: Thousands | G15: Thousands | H15: Thousands | I15: Thousands | J15: Thousands | K15: Thousands
A16: Cash & Equivalents | B16: 3933000 | C16: 4835000 | D16: 2535000 | E16: 1595000 | F16: 1503000 | G16: 1156000 | H16: 1185000 | I16: 1264000 | J16: 785000 | K16: 1040000
A17: Short Term Investments | B17: 1840000 | C17: 1020000 | D17: 1073000 | E17: 695000 | F17: 0 | G17: 0 | H17: 0 | I17: 0 | J17: 0 | K17: 0
A18: Cash & Equivs & ST Investments | B18: 5773000 | C18: 5855000 | D18: 3608000 | E18: 2290000 | F18: 1503000 | G18: 1156000 | H18: 1185000 | I18: 1264000 | J18: 785000 | K18: 1040000
A19: Receivables (ST) | B19: 5376000 | C19: 4126000 | D19: 2706000 | E19: 2066000 | F19: 1859000 | G19: 1235000 | H19: 400000 | I19: 311000 | J19: 533000 | K19: 818000
A20: Related Parties (ST Asset) | B20: 9000 | C20: 2000 | D20: 2000 | E20: 10000 | F20: 0 | G20: 0 | H20: 0 | I20: 0 | J20: 0 | K20: 0
A21: Inventories | B21: 4351000 | C21: 3771000 | D21: 1955000 | E21: 1399000 | F21: 982000 | G21: 845000 | H21: 739000 | I21: 751000 | J21: 678000 | K21: 685000
A22: Other Current Assets | B22: 1259000 | C22: 1265000 | D22: 312000 | E22: 378000 | F22: 253000 | G22: 247000 | H22: 221000 | I22: 109000 | J22: 248000 | K22: 80000
A23: Total Current Assets | B23: 16768000 | C23: 15019000 | D23: 8583000 | E23: 6143000 | F23: 4597000 | G23: 3540000 | H23: 2622000 | I23: 2530000 | J23: 2320000 | K23: 2736000
A24: Gross Property Plant & Equip | B24: 3376000 | C24: 3020000 | D24: 1836000 | E24: 1553000 | F24: 1268000 | G24: 1055000 | H24: 1001000 | I24: 881000 | J24: 984000 | K24: 1680000
A25: Accumulated Depreciation | B25: 1787000 | C25: 1507000 | D25: 1134000 | E25: 912000 | F25: 768000 | G25: 707000 | H25: 740000 | I25: 717000 | J25: 796000 | K25: 1378000
A26: Net Property Plant & Equip | B26: 1589000 | C26: 1513000 | D26: 702000 | E26: 641000 | F26: 500000 | G26: 348000 | H26: 261000 | I26: 164000 | J26: 188000 | K26: 302000
A27: Long Term Investments | B27: 99000 | C27: 83000 | D27: 69000 | E27: 63000 | F27: 58000 | G27: 58000 | H27: 58000 | I27: 59000 | J27: 0 | K27: 0
... A35: Accrued Expenses | B35: 3082000 | C35: 3077000 | D35: 2424000 | E35: 1796000 | F35: 1084000 | G35: 763000 | H35: 541000 | I35: 391000 | J35: 472000 | K35: 558000
A36: Current Debt | B36: 751000 | C36: 0 | D36: 312000 | E36: 0 | F36: 0 | G36: 136000 | H36: 70000 | I36: - | J36: 230000 | K36: 177000
A37: Other Current Liabilities | B37: 438000 | C37: 336000 | D37: 98000 | E37: 75000 | F37: 74000 | G37: 24000 | H37: 79000 | I37: 132000 | J37: 177000 | K37: 72000
A38: Total Current Liabilities | B38: 6689000 | C38: 6369000 | D38: 4240000 | E38: 2417000 | F38: 2359000 | G38: 1984000 | H38: 1486000 | I38: 1346000 | J38: 1403000 | K38: 1440000
A39: LT Debt & Leases | B39: 1717000 | C39: 2467000 | D39: 1000 | E39: 330000 | F39: 486000 | G39: 1114000 | H39: 1325000 | I39: 1435000 | J39: 2032000 | K39: 2035000
A40: Deferred LT Liabilities | B40: 1202000 | C40: 1934000 | D40: 0 | E40: 0 | F40: 0 | G40: 0 | H40: 0 | I40: 0 | J40: 0 | K40: 0
A41: Other Liabilities | B41: 2385000 | C41: 2060000 | D41: 681000 | E41: 378000 | F41: 356000 | G41: 192000 | H41: 118000 | I41: 124000 | J41: 86000 | K41: 105000
A42: Total Liabilities | B42: 11993000 | C42: 12830000 | D42: 4922000 | E42: 3125000 | F42: 3201000 | G42: 3290000 | H42: 2929000 | I42: 2905000 | J42: 3521000 | K42: 3580000
A43: Common Share Capital | B43: 17000 | C43: 16000 | D43: 12000 | E43: 12000 | F43: 12000 | G43: 10000 | H43: 9000 | I43: 9000 | J43: 8000 | K43: 8000
A44: Additional Paid-In Capital | B44: 59676000 | C44: 58005000 | D44: 11069000 | E44: 10544000 | F44: 9963000 | G44: 8750000 | H44: 8464000 | I44: 8334000 | J44: 7017000 | K44: 6949000
A45: Retained Earnings | B45: 723000 | C45: -131000 | D45: -1451000 | E45: -4605000 | F45: -7095000 | G45: -7436000 | H45: -7760000 | I45: -7803000 | J45: -7306000 | K45: -6646000
A46: Accum Other Comprehensive Income | B46: -10000 | C46: -41000 | D46: -3000 | E46: 17000 | F46: 0 | G46: -8000 | H46: 6000 | I46: -5000 | J46: -8000 | K46: -5000
A47: Treasury Stock | B47: 4514000 | C47: 3099000 | D47: 2130000 | E47: 131000 | F47: 53000 | G47: 50000 | H47: 108000 | I47: 119000 | J47: 123000 | K47: 119000
A48: Total Equity | B48: 55892000 | C48: 54750000 | D48: 7497000 | E48: 5837000 | F48: 2827000 | G48: 1266000 | H48: 611000 | I48: 416000 | J48: -412000 | K48: 187000
A49: Total Liabilities & Equity | B49: 67885000 | C49: 67580000 | D49: 12419000 | E49: 8962000 | F49: 6028000 | G49: 4556000 | H49: 3540000 | I49: 3321000 | J49: 3109000 | K49: 3767000
A51: Standardized Annual Income Statement
A52: Report Date | B52: 12/30/2023 | C52: 12/31/2022 | D52: 12/25/2021 | E52: 12/26/2020 | F52: 12/28/2019 | G52: 12/29/2018 | H52: 12/30/2017 | I52: 12/31/2016 | J52: 12/26/2015 | K52: 12/27/2014
A53: Currency | B53: USD | C53: USD | D53: USD | E53: USD | F53: USD | G53: USD | H53: USD | I53: USD | J53: USD | K53: USD
A54: Audit Status | B54: Not Qualified | C54: Not Qualified | D54: Not Qualified | E54: Not Qualified | F54: Not Qualified | G54: Not Qualified | H54: Not Qualified | I54: Not Qualified | J54: Not Qualified | K54: Not Qualified
...

Sheet Sheet3

Sheet Sheet4
A4: Powered by Clearbit
A5: Qualcomm Inc (NMS: QCOM)
A7: Exchange rate used is that of the Year End reported date
A10: Standardized Annual Balance Sheet
A11: Report Date | B11: 09/29/2024 | C11: 09/24/2023 | D11: 09/25/2022 | E11: 09/26/2021 | F11: 09/27/2020 | G11: 09/29/2019 | H11: 09/30/2018 | I11: 09/24/2017 | J11: 09/25/2016 | K11: 09/27/2015
A12: Currency | B12: USD | C12: USD | D12: USD | E12: USD | F12: USD | G12: USD | H12: USD | I12: USD | J12: USD | K12: USD
A13: Audit Status | B13: Not Qualified | C13: Not Qualified | D13: Not Qualified | E13: Not Qualified | F13: Not Qualified | G13: Not Qualified | H13: Not Qualified | I13: Not Qualified | J13: Not Qualified | K13: Not Qualified
A14: Consolidated | B14: Yes | C14: Yes | D14: Yes | E14: Yes | F14: Yes | G14: Yes | H14: Yes | I14: Yes | J14: Yes | K14: Yes
A15: Scale | B15: Thousands | C15: Thousands | D15: Thousands | E15: Thousands | F15: Thousands | G15: Thousands | H15: Thousands | I15: Thousands | J15: Thousands | K15: Thousands
A16: Cash & Equivalents | B16: 7849000 | C16: 8450000 | D16: 2773000 | E16: 7116000 | F16: 6707000 | G16: 11839000 | H16: 11777000 | I16: 35029000 | J16: 5946000 | K16: 7560000
A17: Short Term Investments | B17: 5451000 | C17: 2874000 | D17: 3609000 | E17: 5298000 | F17: 4507000 | G17: 421000 | H17: 311000 | I17: 2279000 | J17: 12702000 | K17: 9761000
A18: Cash & Equivs & ST Investments | B18: 13300000 | C18: 11324000 | D18: 6382000 | E18: 12414000 | F18: 11214000 | G18: 12260000 | H18: 12088000 | I18: 37308000 | J18: 18648000 | K18: 17321000
A19: Receivables (ST) | B19: 3929000 | C19: 3183000 | D19: 5643000 | E19: 3579000 | F19: 4003000 | G19: 2471000 | H19: 2904000 | I19: 3632000 | J19: 2219000 | K19: 1964000
A20: Inventories | B20: 6423000 | C20: 6422000 | D20: 6341000 | E20: 3228000 | F20: 2598000 | G20: 1400000 | H20: 1693000 | I20: 2035000 | J20: 1556000 | K20: 1492000
A21: Current Tax Assets | B21: 0 | C21: 0 | D21: 0 | E21: 0 | F21: 0 | G21: 0 | H21: 0 | I21: 0 | J21: 0 | K21: 635000
A22: Assets Held for Sale (ST) | B22: 0 | C22: 341000 | D22: 733000 | E22: 0 | F22: 0 | G22: 0 | H22: 0 | I22: 0 | J22: 0 | K22: 0
A23: Other Current Assets | B23: 1579000 | C23: 1194000 | D23: 1625000 | E23: 854000 | F23: 704000 | G23: 634000 | H23: 699000 | I23: 618000 | J23: 558000 | K23: 687000
A24: Total Current Assets | B24: 25231000 | C24: 22464000 | D24: 20724000 | E24: 20075000 | F24: 18519000 | G24: 16765000 | H24: 17384000 | I24: 43593000 | J24: 22981000 | K24: 22099000
A25: Gross Property Plant & Equip | B25: 13541000 | C25: 12710000 | D25: 11770000 | E25: 10454000 | F25: 8845000 | G25: 7648000 | H25: 7461000 | I25: 7419000 | J25: 6040000 | K25: 5894000
A26: Accumulated Depreciation | B26: 8876000 | C26: 7668000 | D26: 6602000 | E26: 5895000 | F26: 5134000 | G26: 4567000 | H26: 4486000 | I26: 4203000 | J26: 3734000 | K26: 3360000
A27: Net Property Plant & Equip | B27: 4665000 | C27: 5042000 | D27: 5168000 | E27: 4559000 | F27: 3711000 | G27: 3081000 | H27: 2975000 | I27: 3216000 | J27: 2306000 | K27: 2534000
... A52: Total Liabilities & Equity | B52: 55154000 | C52: 51040000 | D52: 49014000 | E52: 41240000 | F52: 35594000 | G52: 32957000 | H52: 32686000 | I52: 65486000 | J52: 52359000 | K52: 50796000
A57: Standardized Annual Income Statement
A58: Report Date | B58: 09/29/2024 | C58: 09/24/2023 | D58: 09/25/2022 | E58: 09/26/2021 | F58: 09/27/2020 | G58: 09/29/2019 | H58: 09/30/2018 | I58: 09/24/2017 | J58: 09/25/2016 | K58: 09/27/2015
A59: Currency | B59: USD | C59: USD | D59: USD | E59: USD | F59: USD | G59: USD | H59: USD | I59: USD | J59: USD | K59: USD
A60: Audit Status | B60: Not Qualified | C60: Not Qualified | D60: Not Qualified | E60: Not Qualified | F60: Not Qualified | G60: Not Qualified | H60: Not Qualified | I60: Not Qualified | J60: Not Qualified | K60: Not Qualified
A61: Consolidated | B61: Yes | C61: Yes | D61: Yes | E61: Yes | F61: Yes | G61: Yes | H61: Yes | I61: Yes | J61: Yes | K61: Yes
A62: Scale | B62: Thousands | C62: Thousands | D62: Thousands | E62: Thousands | F62: Thousands | G62: Thousands | H62: Thousands | I62: Thousands | J62: Thousands | K62: Thousands
A63: Sales Revenue | B63: 38962000 | C63: 30028000 | D63: 37171000 | E63: 26741000 | F63: 16298000 | G63: 14611000 | H63: 17400000 | I63: 16647000 | J63: 15467000 | K63: 17079000
A64: Other Revenue | B64: - | C64: 5792000 | D64: 7029000 | E64: 6825000 | F64: 7233000 | G64: 9662000 | H64: 5332000 | I64: 5644000 | J64: 8087000 | K64: 8202000
A65: Total Revenue | B65: 38962000 | C65: 35820000 | D65: 44200000 | E65: 33566000 | F65: 23531000 | G65: 24273000 | H65: 22732000 | I65: 22291000 | J65: 23554000 | K65: 25281000
A66: Direct Costs | B66: 17060000 | C66: 15869000 | D66: 18635000 | E66: 14262000 | F66: 9255000 | G66: 8599000 | H66: 10244000 | I66: 9792000 | J66: 9749000 | K66: 10378000
A67: Gross Profit | B67: 21902000 | C67: 19951000 | D67: 25565000 | E67: 19304000 | F67: 14276000 | G67: 15674000 | H67: 12488000 | I67: 12499000 | J67: 13805000 | K67: 14903000
A68: Selling General & Admin | B68: 2759000 | C68: 2483000 | D68: 2570000 | E68: 2339000 | F68: 2074000 | G68: 2195000 | H68: 2986000 | I68: 2658000 | J68: 2385000 | K68: 2344000
A69: Research & Development | B69: 8893000 | C69: 8818000 | D69: 8194000 | E69: 7176000 | F69: 5975000 | G69: 5398000 | H69: 5625000 | I69: 5485000 | J69: 5151000 | K69: 5490000
A70: Other Operating Expense | B70: 179000 | C70: 862000 | D70: -1059000 | E70: 0 | F70: -28000 | G70: 414000 | H70: 3135000 | I70: 1742000 | J70: -226000 | K70: 1293000
A71: Total Indirect Operating Costs | B71: 11831000 | C71: 12163000 | D71: 9705000 | E71: 9515000 | F71: 8021000 | G71: 8007000 | H71: 11746000 | I71: 9885000 | J71: 7310000 | K71: 9127000
A72: Operating Income | B72: 10071000 | C72: 7788000 | D72: 15860000 | E72: 9789000 | F72: 6255000 | G72: 7667000 | H72: 742000 | I72: 2614000 | J72: 6495000 | K72: 5776000
A73: Interest Income | B73: -22000 | C73: -381000 | D73: -399000 | E73: -476000 | F73: -446000 | G73: -311000 | H73: -143000 | I73: 125000 | J73: 314000 | K73: 423000
A74: Gains on Sale of Assets | B74: 387000 | C74: 82000 | D74: -287000 | E74: 883000 | F74: 314000 | G74: 342000 | H74: 97000 | I74: 562000 | J74: 280000 | K74: 520000
...

Sheet Sheet5
A4: Powered by Clearbit
A5: Qualcomm Inc (NMS: QCOM)
A7: Exchange rate used is that of the Year End reported date
A10: Standardized Annual Income Statement
A11: Report Date | B11: 09/29/2024 | C11: 09/24/2023 | D11: 09/25/2022 | E11: 09/26/2021 | F11: 09/27/2020 | G11: 09/29/2019 | H11: 09/30/2018 | I11: 09/24/2017 | J11: 09/25/2016 | K11: 09/27/2015
A12: Currency | B12: USD | C12: USD | D12: USD | E12: USD | F12: USD | G12: USD | H12: USD | I12: USD | J12: USD | K12: USD
A13: Audit Status | B13: Not Qualified | C13: Not Qualified | D13: Not Qualified | E13: Not Qualified | F13: Not Qualified | G13: Not Qualified | H13: Not Qualified | I13: Not Qualified | J13: Not Qualified | K13: Not Qualified
A14: Consolidated | B14: Yes | C14: Yes | D14: Yes | E14: Yes | F14: Yes | G14: Yes | H14: Yes | I14: Yes | J14: Yes | K14: Yes
A15: Scale | B15: Thousands | C15: Thousands | D15: Thousands | E15: Thousands | F15: Thousands | G15: Thousands | H15: Thousands | I15: Thousands | J15: Thousands | K15: Thousands
A16: Sales Revenue | B16: 38962000 | C16: 30028000 | D16: 37171000 | E16: 26741000 | F16: 16298000 | G16: 14611000 | H16: 17400000 | I16: 16647000 | J16: 15467000 | K16: 17079000
A17: Other Revenue | B17: - | C17: 5792000 | D17: 7029000 | E17: 6825000 | F17: 7233000 | G17: 9662000 | H17: 5332000 | I17: 5644000 | J17: 8087000 | K17: 8202000
A18: Total Revenue | B18: 38962000 | C18: 35820000 | D18: 44200000 | E18: 33566000 | F18: 23531000 | G18: 24273000 | H18: 22732000 | I18: 22291000 | J18: 23554000 | K18: 25281000
A19: Direct Costs | B19: 17060000 | C19: 15869000 | D19: 18635000 | E19: 14262000 | F19: 9255000 | G19: 8599000 | H19: 10244000 | I19: 9792000 | J19: 9749000 | K19: 10378000
A20: Gross Profit | B20: 21902000 | C20: 19951000 | D20: 25565000 | E20: 19304000 | F20: 14276000 | G20: 15674000 | H20: 12488000 | I20: 12499000 | J20: 13805000 | K20: 14903000
A21: Selling General & Admin | B21: 2759000 | C21: 2483000 | D21: 2570000 | E21: 2339000 | F21: 2074000 | G21: 2195000 | H21: 2986000 | I21: 2658000 | J21: 2385000 | K21: 2344000
A22: Research & Development | B22: 8893000 | C22: 8818000 | D22: 8194000 | E22: 7176000 | F22: 5975000 | G22: 5398000 | H22: 5625000 | I22: 5485000 | J22: 5151000 | K22: 5490000
A23: Other Operating Expense | B23: 179000 | C23: 862000 | D23: -1059000 | E23: 0 | F23: -28000 | G23: 414000 | H23: 3135000 | I23: 1742000 | J23: -226000 | K23: 1293000
A24: Total Indirect Operating Costs | B24: 11831000 | C24: 12163000 | D24: 9705000 | E24: 9515000 | F24: 8021000 | G24: 8007000 | H24: 11746000 | I24: 9885000 | J24: 7310000 | K24: 9127000
A25: Operating Income | B25: 10071000 | C25: 7788000 | D25: 15860000 | E25: 9789000 | F25: 6255000 | G25: 7667000 | H25: 742000 | I25: 2614000 | J25: 6495000 | K25: 5776000
A26: Interest Income | B26: -22000 | C26: -381000 | D26: -399000 | E26: -476000 | F26: -446000 | G26: -311000 | H26: -143000 | I26: 125000 | J26: 314000 | K26: 423000
A27: Gains on Sale of Assets | B27: 387000 | C27: 82000 | D27: -287000 | E27: 883000 | F27: 314000 | G27: 342000 | H27: 97000 | I27: 562000 | J27: 280000 | K27: 520000
A28: Foreign Exchange Gains | B28: - | C28: - | D28: 19000 | E28: -32000 | F28: -25000 | G28: 11000 | H28: 37000 | I28: -30000 | J28: - | K28: -
A29: Other Non-Operating Income | B29: -100000 | C29: -46000 | D29: -188000 | E29: 97000 | F29: -358000 | G29: -135000 | H29: -75000 | I29: -177000 | J29: -172000 | K29: -200000
A30: Total Non-Operating Income | B30: 265000 | C30: -345000 | D30: -855000 | E30: 472000 | F30: -515000 | G30: -93000 | H30: -84000 | I30: 480000 | J30: 422000 | K30: 743000
A31: Earnings Before Tax | B31: 10336000 | C31: 7443000 | D31: 15005000 | E31: 10261000 | F31: 5740000 | G31: 7574000 | H31: 658000 | I31: 3094000 | J31: 6917000 | K31: 6519000
A32: Taxation | B32: 226000 | C32: 104000 | D32: 2012000 | E32: 1231000 | F32: 521000 | G32: 3095000 | H32: 5377000 | I32: 555000 | J32: 1131000 | K32: 1219000
A33: Earnings After Tax | B33: 10110000 | C33: - | D33: - | E33: - | F33: - | G33: - | H33: - | I33: - | J33: - | K33: -
A34: Equity Earnings | B34: - | C34: - | D34: -7000 | E34: 13000 | F34: -21000 | G34: -93000 | H34: -145000 | I34: -74000 | J34: -84000 | K34: -32000
A35: Net Income | B35: 10142000 | C35: 7232000 | D35: 12936000 | E35: 9043000 | F35: 5198000 | G35: 4386000 | H35: -4864000 | I35: 2466000 | J35: 5705000 | K35: 5271000
A36: Net Income to Common | B36: 10142000 | C36: 7232000 | D36: 12936000 | E36: 9043000 | F36: 5198000 | G36: 4386000 | H36: -4864000 | I36: 2466000 | J36: 5705000 | K36: 5271000
A37: Average Shares Basic | B37: 1116000 | C37: 1117000 | D37: 1123000 | E37: 1131000 | F37: 1135000 | G37: 1210000 | H37: 1463000 | I37: 1477000 | J37: 1484000 | K37: 1618000
A38: EPS Net Basic | B38: 9.09 | C38: 6.47 | D38: 11.52 | E38: 7.99 | F38: 4.58 | G38: 3.63 | H38: -3.32 | I38: 1.67 | J38: 3.84 | K38: 3.26
A39: EPS Continuing Basic | B39: 9.06 | C39: 6.57 | D39: 11.56 | E39: 7.99 | F39: 4.58 | G39: 3.63 | H39: -3.32 | I39: 1.67 | J39: 3.84 | K39: 3.26
A40: Average Shares Diluted | B40: 1130000 | C40: 1126000 | D40: 1137000 | E40: 1149000 | F40: 1149000 | G40: 1220000 | H40: 1463000 | I40: 1490000 | J40: 1498000 | K40: 1639000
A41: EPS Net Diluted | B41: 8.97 | C41: 6.42 | D41: 11.37 | E41: 7.87 | F41: 4.52 | G41: 3.59 | H41: -3.32 | I41: 1.65 | J41: 3.81 | K41: 3.22
A42: EPS Continuing Diluted | B42: 8.94 | C42: 6.52 | D42: 11.41 | E42: 7.87 | F42: 4.52 | G42: 3.59 | H42: -3.32 | I42: 1.65 | J42: 3.81 | K42: 3.22
A43: Shares Outstanding | B43: 1113000 | C43: 1114000 | D43: 1121000 | E43: 1125000 | F43: 1131000 | G43: 1145000 | H43: 1219000 | I43: 1474000 | J43: 1476000 | K43: 1524000

Sheet Sheet6
A4: Powered by Clearbit
A5: Intel Corp (NMS: INTC)
A7: Exchange rate used is that of the Year End reported date
A10: Standardized Annual Income Statement
A11: Report Date | B11: 12/30/2023 | C11: 12/31/2022 | D11: 12/25/2021 | E11: 12/26/2020 | F11: 12/28/2019 | G11: 12/29/2018 | H11: 12/30/2017 | I11: 12/31/2016 | J11: 12/26/2015 | K11: 12/27/2014
A12: Currency | B12: USD | C12: USD | D12: USD | E12: USD | F12: USD | G12: USD | H12: USD | I12: USD | J12: USD | K12: USD
A13: Audit Status | B13: Not Qualified | C13: Not Qualified | D13: Not Qualified | E13: Not Qualified | F13: Not Qualified | G13: Not Qualified | H13: Not Qualified | I13: Not Qualified | J13: Not Qualified | K13: Not Qualified
A14: Consolidated | B14: Yes | C14: Yes | D14: Yes | E14: Yes | F14: Yes | G14: Yes | H14: Yes | I14: Yes | J14: Yes | K14: Yes
A15: Scale | B15: Millions | C15: Millions | D15: Millions | E15: Millions | F15: Millions | G15: Millions | H15: Millions | I15: Millions | J15: Millions | K15: Millions
A16: Sales Revenue | B16: 54228 | C16: 0 | D16: 0 | E16: 0 | F16: 0 | G16: 0 | H16: 0 | I16: 0 | J16: 0 | K16: 0
A17: Total Revenue | B17: 54228 | C17: 63054 | D17: 79024 | E17: 77867 | F17: 71965 | G17: 70848 | H17: 62761 | I17: 59387 | J17: 55355 | K17: 55870
A18: Direct Costs | B18: 32517 | C18: 36188 | D18: 35209 | E18: 34255 | F18: 29825 | G18: 27111 | H18: 23692 | I18: 23196 | J18: 20676 | K18: 20261
A19: Gross Profit | B19: 21711 | C19: 26866 | D19: 43815 | E19: 43612 | F19: 42140 | G19: 43737 | H19: 39069 | I19: 36191 | J19: 34679 | K19: 35609
A20: Selling General & Admin | B20: 5634 | C20: 7002 | D20: 6543 | E20: 6180 | F20: 6150 | G20: 6750 | H20: 7474 | I20: 8397 | J20: 7930 | K20: 8136
A21: Depreciation & Amortization | B21: 0 | C21: 0 | D21: 0 | E21: 0 | F21: 200 | G21: 200 | H21: 177 | I21: 294 | J21: 265 | K21: 294
A22: Research & Development | B22: 16046 | C22: 17528 | D22: 15190 | E22: 13556 | F22: 13362 | G22: 13543 | H22: 13098 | I22: 12740 | J22: 12128 | K22: 11537
A23: Restruct Remediation & Impair | B23: 267 | C23: 2 | D23: 2626 | E23: 198 | F23: 393 | G23: -72 | H23: 384 | I23: 1886 | J23: 354 | K23: 295
A24: Other Operating Expense | B24: -329 | C24: 0 | D24: 0 | E24: 0 | F24: 0 | G24: 0 | H24: 0 | I24: 0 | J24: 0 | K24: 0
A25: Total Indirect Operating Costs | B25: 21618 | C25: 24532 | D25: 24359 | E25: 19934 | F25: 20105 | G25: 20421 | H25: 21133 | I25: 23317 | J25: 20677 | K25: 20262
A26: Operating Income | B26: 93 | C26: 2334 | D26: 19456 | E26: 23678 | F26: 22035 | G26: 23316 | H26: 17936 | I26: 12874 | J26: 14002 | K26: 15347
A27: Interest Income | B27: 629 | C27: 1166 | D27: -482 | E27: -504 | F27: 484 | G27: 126 | H27: -235 | I27: -444 | J27: -105 | K27: 43
... A32: Taxation | B32: -913 | C32: -249 | D32: 1835 | E32: 4179 | F32: 3010 | G32: 2264 | H32: 10751 | I32: 2620 | J32: 2792 | K32: 4097
A33: Equity Earnings | B33: 59 | C33: - | D33: - | E33: - | F33: - | G33: - | H33: -232 | I33: -38 | J33: -95 | K33: -69
A34: Net Income | B34: 1689 | C34: 8014 | D34: 19868 | E34: 20899 | F34: 21048 | G34: 21053 | H34: 9601 | I34: 10316 | J34: 11420 | K34: 11704
A35: Net Income to Common | B35: 1689 | C35: 8014 | D35: 19868 | E35: 20899 | F35: 21048 | G35: 21053 | H35: 9601 | I35: 10316 | J35: 11420 | K35: 11704
A36: Average Shares Basic | B36: 4190 | C36: 4108 | D36: 4059 | E36: 4199 | F36: 4417 | G36: 4611 | H36: 4701 | I36: 4730 | J36: 4742 | K36: 4901
A37: EPS Net Basic | B37: 0.4 | C37: 1.95 | D37: 4.89 | E37: 4.98 | F37: 4.77 | G37: 4.57 | H37: 2.04 | I37: 2.18 | J37: 2.41 | K37: 2.39
A38: EPS Continuing Basic | B38: 0.4 | C38: 1.95 | D38: 4.89 | E38: 4.98 | F38: 4.77 | G38: 4.57 | H38: 2.04 | I38: 2.18 | J38: 2.41 | K38: 2.39
A39: Average Shares Diluted | B39: 4212 | C39: 4123 | D39: 4090 | E39: 4232 | F39: 4473 | G39: 4701 | H39: 4835 | I39: 4875 | J39: 4894 | K39: 5056
A40: EPS Net Diluted | B40: 0.4 | C40: 1.94 | D40: 4.86 | E40: 4.94 | F40: 4.71 | G40: 4.48 | H40: 1.99 | I40: 2.12 | J40: 2.33 | K40: 2.31
A41: EPS Continuing Diluted | B41: 0.4 | C41: 1.94 | D41: 4.86 | E41: 4.94 | F41: 4.71 | G41: 4.48 | H41: 1.99 | I41: 2.12 | J41: 2.33 | K41: 2.31
A42: Shares Outstanding | B42: 4228 | C42: 4137 | D42: 4070 | E42: 4062 | F42: 4290 | G42: 4516 | H42: 4687 | I42: 4730 | J42: 4725 | K42: 4748

Sheet Sheet7
A1: Year | B1: 2015 | C1: 2016 | D1: 2017 | E1: 2018 | F1: 2019 | G1: 2020 | H1: 2021 | I1: 2022 | J1: 2023
A2: Revenue | B2: 4681507 | C2: 5010000 | D2: 6910000 | E2: 9714000 | F2: 11716000 | G2: 10918000 | H2: 16675000 | I2: 26914000 | J2: 26974000
A3: EBIT | B3: 758989 | C3: 747000 | D3: 1934000 | E3: 3210000 | F3: 3804000 | G3: 2846000 | H3: 4532000 | I3: 10041000 | J3: 4224000
A4: Net Income | B4: 630587 | C4: 614000 | D4: 1666000 | E4: 3047000 | F4: 4141000 | G4: 2796000 | H4: 4332000 | I4: 9752000 | J4: 4368000
A5: CapEx | B5: -122381 | C5: -86000 | D5: -176000 | E5: -593000 | F5: -600000 | G5: -489000 | H5: -1128000 | I5: -976000 | J5: -1833000
A6: Depreciation | B6: 248092 | C6: 226000 | D6: 212000 | E6: 202000 | F6: 262000 | G6: 381000 | H6: 1098000 | I6: 1174000 | J6: 1544000
A7: Change in WC | B7: -202527 | C7: -51000 | D7: -679000 | E7: 185000 | F7: -857000 | G7: 717000 | H7: -703000 | I7: -3363000 | J7: -2207000
A8: Revenue Growth Rate | B8: 1 | C8: 0.070168217 | D8: 0.37924152 | E8: 0.40578871 | F8: 0.2060943 | G8: -0.068111984 | H8: 0.52729438 | I8: 0.61403298 | J8: 0.002229323
A9: EBIT Margin | B9: 0.16212493 | C9: 0.1491018 | D9: 0.27988423 | E9: 0.3304509 | F9: 0.32468419 | G9: 0.26067045 | H9: 0.27178411 | I9: 0.37307721 | J9: 0.15659524
A10: Effective Tax Rate | B10: 0.83082495 | C10: 0.82195448 | D10: 0.86142709 | E10: 0.94922118 | F10: 1.088591 | G10: 0.98243148 | H10: 0.95586937 | I10: 0.97121801 | J10: 1.0340909
